Workbook

Sheet _Modules
A1: Modules Info
A3: Modules
A4: =IFERROR(__xludf.DUMMYFUNCTION("IMPORTRANGE('_Settings'!B3,""Modules!A4:L1000"")"),"Allocation") -> Allocation | B4: =IFERROR(__xludf.DUMMYFUNCTION("""COMPUTED_VALUE"""),"Allocate") -> Allocate | C4: =IFERROR(__xludf.DUMMYFUNCTION("""COMPUTED_VALUE"""),"Undefined") -> Undefined
A5: =IFERROR(__xludf.DUMMYFUNCTION("""COMPUTED_VALUE"""),"Allocation") -> Allocation | B5: =IFERROR(__xludf.DUMMYFUNCTION("""COMPUTED_VALUE"""),"CheckAllocatedGroups") -> CheckAllocatedGroups | C5: =IFERROR(__xludf.DUMMYFUNCTION("""COMPUTED_VALUE"""),"17hQQja2JxgHYc91C7e_NxNoHLA89SiPSSBCEIFHCoTk") -> 17hQQja2JxgHYc91C7e_NxNoHLA89SiPSSBCEIFHCoTk
A6: =IFERROR(__xludf.DUMMYFUNCTION("""COMPUTED_VALUE"""),"Allocation") -> Allocation | B6: =IFERROR(__xludf.DUMMYFUNCTION("""COMPUTED_VALUE"""),"GetDataAllocation") -> GetDataAllocation | C6: =IFERROR(__xludf.DUMMYFUNCTION("""COMPUTED_VALUE"""),"108eHf5dlaU-2uUYuHfGgKKJqgdRILzey4i21uN8VBpc") -> 108eHf5dlaU-2uUYuHfGgKKJqgdRILzey4i21uN8VBpc
A7: =IFERROR(__xludf.DUMMYFUNCTION("""COMPUTED_VALUE"""),"Allocation") -> Allocation | B7: =IFERROR(__xludf.DUMMYFUNCTION("""COMPUTED_VALUE"""),"SelectAllocatedGroup") -> SelectAllocatedGroup | C7: =IFERROR(__xludf.DUMMYFUNCTION("""COMPUTED_VALUE"""),"1xOLrriXpynkiEARWECFOoYcCjgpJ_r_B8l8himR40tc") -> 1xOLrriXpynkiEARWECFOoYcCjgpJ_r_B8l8himR40tc
A8: =IFERROR(__xludf.DUMMYFUNCTION("""COMPUTED_VALUE"""),"Allocation") -> Allocation | B8: =IFERROR(__xludf.DUMMYFUNCTION("""COMPUTED_VALUE"""),"EditTradesAllocated") -> EditTradesAllocated | C8: =IFERROR(__xludf.DUMMYFUNCTION("""COMPUTED_VALUE"""),"1czFgc0rQ9Yr0z5XyYhwS9vTzyyW8C_kbFoZotVQvRGU") -> 1czFgc0rQ9Yr0z5XyYhwS9vTzyyW8C_kbFoZotVQvRGU
A9: =IFERROR(__xludf.DUMMYFUNCTION("""COMPUTED_VALUE"""),"Allocation") -> Allocation | B9: =IFERROR(__xludf.DUMMYFUNCTION("""COMPUTED_VALUE"""),"EditTradesUnallocated") -> EditTradesUnallocated | C9: =IFERROR(__xludf.DUMMYFUNCTION("""COMPUTED_VALUE"""),"1IzyG5_6aGu2OE6b5hRX3Fsz__PyNpFOt5iSq6kKmpgs") -> 1IzyG5_6aGu2OE6b5hRX3Fsz__PyNpFOt5iSq6kKmpgs
A10: =IFERROR(__xludf.DUMMYFUNCTION("""COMPUTED_VALUE"""),"Allocation") -> Allocation | B10: =IFERROR(__xludf.DUMMYFUNCTION("""COMPUTED_VALUE"""),"Reallocate") -> Reallocate | C10: =IFERROR(__xludf.DUMMYFUNCTION("""COMPUTED_VALUE"""),"Undefined") -> Undefined
A11: =IFERROR(__xludf.DUMMYFUNCTION("""COMPUTED_VALUE"""),"Blotter") -> Blotter | B11: =IFERROR(__xludf.DUMMYFUNCTION("""COMPUTED_VALUE"""),"ReplaceFillsOnBlotter") -> ReplaceFillsOnBlotter | C11: =IFERROR(__xludf.DUMMYFUNCTION("""COMPUTED_VALUE"""),"1Diy-Nhw7lqGk8BUcJ7_tudF9wi_ZJxiWQvXjEtj0fbg") -> 1Diy-Nhw7lqGk8BUcJ7_tudF9wi_ZJxiWQvXjEtj0fbg
A12: =IFERROR(__xludf.DUMMYFUNCTION("""COMPUTED_VALUE"""),"a") -> a | B12: =IFERROR(__xludf.DUMMYFUNCTION("""COMPUTED_VALUE"""),"1s") -> 1s | C12: =IFERROR(__xludf.DUMMYFUNCTION("""COMPUTED_VALUE"""),"1enUPqyPREGl3f2eye-2V4zEhW4eTEsQWbHsvbHWKlLQ") -> 1enUPqyPREGl3f2eye-2V4zEhW4eTEsQWbHsvbHWKlLQ
A13: =IFERROR(__xludf.DUMMYFUNCTION("""COMPUTED_VALUE"""),"GeneralLedger") -> GeneralLedger | B13: =IFERROR(__xludf.DUMMYFUNCTION("""COMPUTED_VALUE"""),"GetDataCash") -> GetDataCash | C13: =IFERROR(__xludf.DUMMYFUNCTION("""COMPUTED_VALUE"""),"11pF8hppeASHIBEU4fJBPX4H2s826R1k7KA4JaccEGq0") -> 11pF8hppeASHIBEU4fJBPX4H2s826R1k7KA4JaccEGq0
A14: =IFERROR(__xludf.DUMMYFUNCTION("""COMPUTED_VALUE"""),"GeneralLedger") -> GeneralLedger | B14: =IFERROR(__xludf.DUMMYFUNCTION("""COMPUTED_VALUE"""),"EnterCashDividends") -> EnterCashDividends | C14: =IFERROR(__xludf.DUMMYFUNCTION("""COMPUTED_VALUE"""),"1qI9l0oxajDKeZluTNrlCeeZ28QX8NkbvZl6ujxbGJnI") -> 1qI9l0oxajDKeZluTNrlCeeZ28QX8NkbvZl6ujxbGJnI
A15: =IFERROR(__xludf.DUMMYFUNCTION("""COMPUTED_VALUE"""),"GeneralLedger") -> GeneralLedger | B15: =IFERROR(__xludf.DUMMYFUNCTION("""COMPUTED_VALUE"""),"EnterNonTradingTransaction") -> EnterNonTradingTransaction | C15: =IFERROR(__xludf.DUMMYFUNCTION("""COMPUTED_VALUE"""),"1n0XgxxbStGy3VjvQS309fIpzG_L1vcwVX484ib8d3QU") -> 1n0XgxxbStGy3VjvQS309fIpzG_L1vcwVX484ib8d3QU
A16: =IFERROR(__xludf.DUMMYFUNCTION("""COMPUTED_VALUE"""),"GeneralLedger") -> GeneralLedger | B16: =IFERROR(__xludf.DUMMYFUNCTION("""COMPUTED_VALUE"""),"VerifyCash") -> VerifyCash | C16: =IFERROR(__xludf.DUMMYFUNCTION("""COMPUTED_VALUE"""),"1dm_rO3DsjDpe_rov3TM-pXjFB8WSzw6eN-gEqIFDT2M") -> 1dm_rO3DsjDpe_rov3TM-pXjFB8WSzw6eN-gEqIFDT2M
A17: =IFERROR(__xludf.DUMMYFUNCTION("""COMPUTED_VALUE"""),"GeneralLedger") -> GeneralLedger | B17: =IFERROR(__xludf.DUMMYFUNCTION("""COMPUTED_VALUE"""),"VerifyActivity") -> VerifyActivity | C17: =IFERROR(__xludf.DUMMYFUNCTION("""COMPUTED_VALUE"""),"1n2_KWleIEyqXIdrb2wBU9n9HG3wOCbtLJiXuNliDxbo") -> 1n2_KWleIEyqXIdrb2wBU9n9HG3wOCbtLJiXuNliDxbo
A18: =IFERROR(__xludf.DUMMYFUNCTION("""COMPUTED_VALUE"""),"GeneralLedger") -> GeneralLedger | B18: =IFERROR(__xludf.DUMMYFUNCTION("""COMPUTED_VALUE"""),"VerifyTradingTransaction") -> VerifyTradingTransaction | C18: =IFERROR(__xludf.DUMMYFUNCTION("""COMPUTED_VALUE"""),"1HUrg5HC-uhaySvPqKlbfDJy_tRqbpd3tG5-BRQbvQNE") -> 1HUrg5HC-uhaySvPqKlbfDJy_tRqbpd3tG5-BRQbvQNE
A19: =IFERROR(__xludf.DUMMYFUNCTION("""COMPUTED_VALUE"""),"GeneralLedger") -> GeneralLedger | B19: =IFERROR(__xludf.DUMMYFUNCTION("""COMPUTED_VALUE"""),"VerifyRevaluationData") -> VerifyRevaluationData | C19: =IFERROR(__xludf.DUMMYFUNCTION("""COMPUTED_VALUE"""),"1ogDmXxmcH2S6ctXbFXoGdWmaCJRo_ECxi411UEwWYtk") -> 1ogDmXxmcH2S6ctXbFXoGdWmaCJRo_ECxi411UEwWYtk
A20: =IFERROR(__xludf.DUMMYFUNCTION("""COMPUTED_VALUE"""),"CorporateAction") -> CorporateAction | B20: =IFERROR(__xludf.DUMMYFUNCTION("""COMPUTED_VALUE"""),"CorporateAction") -> CorporateAction | C20: =IFERROR(__xludf.DUMMYFUNCTION("""COMPUTED_VALUE"""),"15KSHSnHyfcV68P-BAz-qSKIAViB6QpZ5pCYmrYItUS4") -> 15KSHSnHyfcV68P-BAz-qSKIAViB6QpZ5pCYmrYItUS4
A21: =IFERROR(__xludf.DUMMYFUNCTION("""COMPUTED_VALUE"""),"CreateTransaction") -> CreateTransaction | B21: =IFERROR(__xludf.DUMMYFUNCTION("""COMPUTED_VALUE"""),"CreateTransaction") -> CreateTransaction | C21: =IFERROR(__xludf.DUMMYFUNCTION("""COMPUTED_VALUE"""),"1JZcaOlNrERZ2pJDJY1f-UuSxW_EJa6FmaMW4Ng69G-Y") -> 1JZcaOlNrERZ2pJDJY1f-UuSxW_EJa6FmaMW4Ng69G-Y
A22: =IFERROR(__xludf.DUMMYFUNCTION("""COMPUTED_VALUE"""),"DailyValuation") -> DailyValuation | B22: =IFERROR(__xludf.DUMMYFUNCTION("""COMPUTED_VALUE"""),"UpdateBeta") -> UpdateBeta | C22: =IFERROR(__xludf.DUMMYFUNCTION("""COMPUTED_VALUE"""),"14bzYQBiZIs2a3lfzwT4TROCDnXpt72UALcJjBTZdEAk") -> 14bzYQBiZIs2a3lfzwT4TROCDnXpt72UALcJjBTZdEAk
A23: =IFERROR(__xludf.DUMMYFUNCTION("""COMPUTED_VALUE"""),"DailyValuation") -> DailyValuation | B23: =IFERROR(__xludf.DUMMYFUNCTION("""COMPUTED_VALUE"""),"UpdateDailyCash") -> UpdateDailyCash | C23: =IFERROR(__xludf.DUMMYFUNCTION("""COMPUTED_VALUE"""),"1qlSfNvUHenegqRyv9ZFeKA5gN-iwbykaaRHcYfx0vR8") -> 1qlSfNvUHenegqRyv9ZFeKA5gN-iwbykaaRHcYfx0vR8
A24: =IFERROR(__xludf.DUMMYFUNCTION("""COMPUTED_VALUE"""),"DailyValuation") -> DailyValuation | B24: =IFERROR(__xludf.DUMMYFUNCTION("""COMPUTED_VALUE"""),"UpdateMultipleDailyCash") -> UpdateMultipleDailyCash | C24: =IFERROR(__xludf.DUMMYFUNCTION("""COMPUTED_VALUE"""),"1f9Url4H77DADigFnhRCLdDJPePHaUcYK-sGJAcDVqAc") -> 1f9Url4H77DADigFnhRCLdDJPePHaUcYK-sGJAcDVqAc
A25: =IFERROR(__xludf.DUMMYFUNCTION("""COMPUTED_VALUE"""),"DailyValuation") -> DailyValuation | B25: =IFERROR(__xludf.DUMMYFUNCTION("""COMPUTED_VALUE"""),"UpdateForexConversion") -> UpdateForexConversion | C25: =IFERROR(__xludf.DUMMYFUNCTION("""COMPUTED_VALUE"""),"1ovsWSW4IX_ESJf6L_l_o3LFV2g37EWvXALJwiSoMOOk") -> 1ovsWSW4IX_ESJf6L_l_o3LFV2g37EWvXALJwiSoMOOk
A26: =IFERROR(__xludf.DUMMYFUNCTION("""COMPUTED_VALUE"""),"DailyValuation") -> DailyValuation | B26: =IFERROR(__xludf.DUMMYFUNCTION("""COMPUTED_VALUE"""),"UpdateMarkPrice") -> UpdateMarkPrice | C26: =IFERROR(__xludf.DUMMYFUNCTION("""COMPUTED_VALUE"""),"16KBVroR_j9VfEeynsJjMmeERh-LHCXp_Q3zfX2ptUbk") -> 16KBVroR_j9VfEeynsJjMmeERh-LHCXp_Q3zfX2ptUbk
A27: =IFERROR(__xludf.DUMMYFUNCTION("""COMPUTED_VALUE"""),"Import") -> Import | B27: =IFERROR(__xludf.DUMMYFUNCTION("""COMPUTED_VALUE"""),"Import") -> Import | C27: =IFERROR(__xludf.DUMMYFUNCTION("""COMPUTED_VALUE"""),"1_vNaQNw1K3VUjBqTVyF_y9hpe8G2ewy1wQSeMFKnIsw") -> 1_vNaQNw1K3VUjBqTVyF_y9hpe8G2ewy1wQSeMFKnIsw
A28: =IFERROR(__xludf.DUMMYFUNCTION("""COMPUTED_VALUE"""),"PortfolioManagement") -> PortfolioManagement | B28: =IFERROR(__xludf.DUMMYFUNCTION("""COMPUTED_VALUE"""),"CheckDashboardPM") -> CheckDashboardPM | C28: =IFERROR(__xludf.DUMMYFUNCTION("""COMPUTED_VALUE"""),"1XML_rKDwoATUqQEdSmAgWZeBq0nRAO-QFlPnVgX1Uac") -> 1XML_rKDwoATUqQEdSmAgWZeBq0nRAO-QFlPnVgX1Uac
A29: =IFERROR(__xludf.DUMMYFUNCTION("""COMPUTED_VALUE"""),"PortfolioManagement") -> PortfolioManagement | B29: =IFERROR(__xludf.DUMMYFUNCTION("""COMPUTED_VALUE"""),"CheckPortfolioManagement") -> CheckPortfolioManagement | C29: =IFERROR(__xludf.DUMMYFUNCTION("""COMPUTED_VALUE"""),"10mJBbfEKw8miuRHDwCV7_-8V_E3ZX1n6jlsC5kfflVY") -> 10mJBbfEKw8miuRHDwCV7_-8V_E3ZX1n6jlsC5kfflVY
A30: =IFERROR(__xludf.DUMMYFUNCTION("""COMPUTED_VALUE"""),"PortfolioManagement") -> PortfolioManagement | B30: =IFERROR(__xludf.DUMMYFUNCTION("""COMPUTED_VALUE"""),"CheckPMLiveFeed") -> CheckPMLiveFeed | C30: =IFERROR(__xludf.DUMMYFUNCTION("""COMPUTED_VALUE"""),"1Q4XgYTYb3ng95eo0AHEW34QHB-UqihXSsfRcQQpkVXw") -> 1Q4XgYTYb3ng95eo0AHEW34QHB-UqihXSsfRcQQpkVXw
A31: =IFERROR(__xludf.DUMMYFUNCTION("""COMPUTED_VALUE"""),"PricingInput") -> PricingInput | B31: =IFERROR(__xludf.DUMMYFUNCTION("""COMPUTED_VALUE"""),"PricingInput") -> PricingInput | C31: =IFERROR(__xludf.DUMMYFUNCTION("""COMPUTED_VALUE"""),"1oej4n4PC8RE49pB4-TiWxTqbDPyninh9e03DcCsTU80") -> 1oej4n4PC8RE49pB4-TiWxTqbDPyninh9e03DcCsTU80
A32: =IFERROR(__xludf.DUMMYFUNCTION("""COMPUTED_VALUE"""),"PricingInput") -> PricingInput | B32: =IFERROR(__xludf.DUMMYFUNCTION("""COMPUTED_VALUE"""),"UpdateSharesOutstanding") -> UpdateSharesOutstanding | C32: =IFERROR(__xludf.DUMMYFUNCTION("""COMPUTED_VALUE"""),"1crnQkc3JZblrRatY8QxWLuk7JnchsXg0e_CyrN38bbE") -> 1crnQkc3JZblrRatY8QxWLuk7JnchsXg0e_CyrN38bbE
A33: =IFERROR(__xludf.DUMMYFUNCTION("""COMPUTED_VALUE"""),"SymbolLookup") -> SymbolLookup | B33: =IFERROR(__xludf.DUMMYFUNCTION("""COMPUTED_VALUE"""),"VerifySymbolLookUp") -> VerifySymbolLookUp | C33: =IFERROR(__xludf.DUMMYFUNCTION("""COMPUTED_VALUE"""),"1YWFFwFn67kSD8UqbzR_g6NbGZ9pjemCMVA9QmSA4_S8") -> 1YWFFwFn67kSD8UqbzR_g6NbGZ9pjemCMVA9QmSA4_S8
A34: =IFERROR(__xludf.DUMMYFUNCTION("""COMPUTED_VALUE"""),"SymbolLookup") -> SymbolLookup | B34: =IFERROR(__xludf.DUMMYFUNCTION("""COMPUTED_VALUE"""),"SymbolLookupFromTT") -> SymbolLookupFromTT | C34: =IFERROR(__xludf.DUMMYFUNCTION("""COMPUTED_VALUE"""),"1gDvMDcnV_Cq-gd3uSiTszH4Q8IYBAMQu9lTMq8Rpy3o") -> 1gDvMDcnV_Cq-gd3uSiTszH4Q8IYBAMQu9lTMq8Rpy3o
A35: =IFERROR(__xludf.DUMMYFUNCTION("""COMPUTED_VALUE"""),"SymbolLookup") -> SymbolLookup | B35: =IFERROR(__xludf.DUMMYFUNCTION("""COMPUTED_VALUE"""),"UpdateUDA") -> UpdateUDA | C35: =IFERROR(__xludf.DUMMYFUNCTION("""COMPUTED_VALUE"""),"1dhqVPgdlk0qqXkJ78cDzBf_Mq3MegKBc6RXPw3xiPrw") -> 1dhqVPgdlk0qqXkJ78cDzBf_Mq3MegKBc6RXPw3xiPrw
A36: =IFERROR(__xludf.DUMMYFUNCTION("""COMPUTED_VALUE"""),"SymbolLookup") -> SymbolLookup | B36: =IFERROR(__xludf.DUMMYFUNCTION("""COMPUTED_VALUE"""),"GetSymbol") -> GetSymbol | C36: =IFERROR(__xludf.DUMMYFUNCTION("""COMPUTED_VALUE"""),"173hAXGieMVvXY5pe0UbKu68RfryU3RaXKikGhyg-rOo") -> 173hAXGieMVvXY5pe0UbKu68RfryU3RaXKikGhyg-rOo
A37: =IFERROR(__xludf.DUMMYFUNCTION("""COMPUTED_VALUE"""),"SymbolLookup") -> SymbolLookup | B37: =IFERROR(__xludf.DUMMYFUNCTION("""COMPUTED_VALUE"""),"GetDataSymbolLookup") -> GetDataSymbolLookup | C37: =IFERROR(__xludf.DUMMYFUNCTION("""COMPUTED_VALUE"""),"1NAyBh7MvMUe-ymIgaMjhvCcTdXRrdfoOqa5k2oEkEtY") -> 1NAyBh7MvMUe-ymIgaMjhvCcTdXRrdfoOqa5k2oEkEtY
A38: =IFERROR(__xludf.DUMMYFUNCTION("""COMPUTED_VALUE"""),"SymbolLookup") -> SymbolLookup | B38: =IFERROR(__xludf.DUMMYFUNCTION("""COMPUTED_VALUE"""),"DeleteValidateSymbol") -> DeleteValidateSymbol | C38: =IFERROR(__xludf.DUMMYFUNCTION("""COMPUTED_VALUE"""),"1WIb_XXxmZPR_GUhoObQfZ6l1pKvOl5CWOE5mnz2ftU0") -> 1WIb_XXxmZPR_GUhoObQfZ6l1pKvOl5CWOE5mnz2ftU0
A39: =IFERROR(__xludf.DUMMYFUNCTION("""COMPUTED_VALUE"""),"ThirdParty") -> ThirdParty | B39: =IFERROR(__xludf.DUMMYFUNCTION("""COMPUTED_VALUE"""),"GenerateThirdParty") -> GenerateThirdParty | C39: =IFERROR(__xludf.DUMMYFUNCTION("""COMPUTED_VALUE"""),"1MME0WB8RmCV2QKgHuWbTvubmaZmPuF0knOKGp2GUg7o") -> 1MME0WB8RmCV2QKgHuWbTvubmaZmPuF0knOKGp2GUg7o
A40: =IFERROR(__xludf.DUMMYFUNCTION("""COMPUTED_VALUE"""),"ThirdParty") -> ThirdParty | B40: =IFERROR(__xludf.DUMMYFUNCTION("""COMPUTED_VALUE"""),"SendThirdParty") -> SendThirdParty | C40: =IFERROR(__xludf.DUMMYFUNCTION("""COMPUTED_VALUE"""),"1Rq8zeuYkGxaBxmemqN7Z1OVWnaheHVEDxVozT52myRI") -> 1Rq8zeuYkGxaBxmemqN7Z1OVWnaheHVEDxVozT52myRI
A41: =IFERROR(__xludf.DUMMYFUNCTION("""COMPUTED_VALUE"""),"ThirdParty") -> ThirdParty | B41: =IFERROR(__xludf.DUMMYFUNCTION("""COMPUTED_VALUE"""),"ViewThirdParty") -> ViewThirdParty | C41: =IFERROR(__xludf.DUMMYFUNCTION("""COMPUTED_VALUE"""),"1UalkAEsbJcZQAzEnT3T29et4u4PKQ3n66SBTt1HPqVc") -> 1UalkAEsbJcZQAzEnT3T29et4u4PKQ3n66SBTt1HPqVc
...

Sheet _Settings
A1: Settings
A3: Module Step Setting File | B3: 1FzWTLghJOFjrGmCEN5rFkuzctvHiAo4TNjRi7fOzwlg
A4: Master Data Settings File | B4: 1ET_FzujYIJWcp6rHUh1D2C4DN1gw_3KHpK7g1_mrw08

Sheet _MasterData
A1: Master Data Info
A3: Module | B3: Step | C3: Master Data Sheet
A4: =IFERROR(__xludf.DUMMYFUNCTION("IMPORTRANGE('_Settings'!B4,""Master Data!A4:L1000"")"),"#REF!") -> #REF!

Sheet CustomOrderTT
B1: Data
J2: =VLOOKUP($E$3,'_MasterData'!B4:D1000,3,FALSE) -> #N/A
B3: Module | C3: TradingTicket | D3: Step | E3: CreateDoneAwayOrder | F3: Data Format | G3: Input Format
B4: =IFERROR(__xludf.DUMMYFUNCTION("IF(C3="""","""",Transpose(IMPORTRANGE('_Settings'!$B$3,C3&""!A4:A1000"")))"),"OpenTTFromPST") -> OpenTTFromPST | C4: =IFERROR(__xludf.DUMMYFUNCTION("""COMPUTED_VALUE"""),"EnterDetailsOnTT") -> EnterDetailsOnTT | D4: =IFERROR(__xludf.DUMMYFUNCTION("""COMPUTED_VALUE"""),"ValidateSymbolTT") -> ValidateSymbolTT | E4: =IFERROR(__xludf.DUMMYFUNCTION("""COMPUTED_VALUE"""),"VerifyDataTT") -> VerifyDataTT | F4: =IFERROR(__xludf.DUMMYFUNCTION("""COMPUTED_VALUE"""),"SetUIPreferencesTT") -> SetUIPreferencesTT | G4: =IFERROR(__xludf.DUMMYFUNCTION("""COMPUTED_VALUE"""),"SetBrokerWisePreferencesTT") -> SetBrokerWisePreferencesTT | H4: =IFERROR(__xludf.DUMMYFUNCTION("""COMPUTED_VALUE"""),"VerifyComplianceOrder") -> VerifyComplianceOrder | I4: =IFERROR(__xludf.DUMMYFUNCTION("""COMPUTED_VALUE"""),"TradeNewSub") -> TradeNewSub | J4: =IFERROR(__xludf.DUMMYFUNCTION("""COMPUTED_VALUE"""),"CreateStageOrder") -> CreateStageOrder | K4: =IFERROR(__xludf.DUMMYFUNCTION("""COMPUTED_VALUE"""),"CreateReplaceOrder") -> CreateReplaceOrder | L4: =IFERROR(__xludf.DUMMYFUNCTION("""COMPUTED_VALUE"""),"SetGeneralPreference") -> SetGeneralPreference | M4: =IFERROR(__xludf.DUMMYFUNCTION("""COMPUTED_VALUE"""),"CreateNewSubOrder") -> CreateNewSubOrder | N4: =IFERROR(__xludf.DUMMYFUNCTION("""COMPUTED_VALUE"""),"TradeBloomberg") -> TradeBloomberg | O4: =IFERROR(__xludf.DUMMYFUNCTION("""COMPUTED_VALUE"""),"ClickSymbolLookup") -> ClickSymbolLookup | P4: =IFERROR(__xludf.DUMMYFUNCTION("""COMPUTED_VALUE"""),"VerifyTT") -> VerifyTT | Q4: =IFERROR(__xludf.DUMMYFUNCTION("""COMPUTED_VALUE"""),"CreateLiveOrder") -> CreateLiveOrder | R4: =IFERROR(__xludf.DUMMYFUNCTION("""COMPUTED_VALUE"""),"UpdateMasterFundOnTT") -> UpdateMasterFundOnTT | S4: =IFERROR(__xludf.DUMMYFUNCTION("""COMPUTED_VALUE"""),"SetTTCompliancePreference") -> SetTTCompliancePreference | T4: =IFERROR(__xludf.DUMMYFUNCTION("""COMPUTED_VALUE"""),"ImportSymbol") -> ImportSymbol | U4: =IFERROR(__xludf.DUMMYFUNCTION("""COMPUTED_VALUE"""),"ExportSymbolFromRAList") -> ExportSymbolFromRAList | V4: =IFERROR(__xludf.DUMMYFUNCTION("""COMPUTED_VALUE"""),"CheckPendingNewOrderAlert") -> CheckPendingNewOrderAlert | W4: =IFERROR(__xludf.DUMMYFUNCTION("""COMPUTED_VALUE"""),"AddSymbolOnRAList") -> AddSymbolOnRAList | X4: =IFERROR(__xludf.DUMMYFUNCTION("""COMPUTED_VALUE"""),"DeleteSymbolListFromRA") -> DeleteSymbolListFromRA | Y4: =IFERROR(__xludf.DUMMYFUNCTION("""COMPUTED_VALUE"""),"RemoveSymbolFromRAList") -> RemoveSymbolFromRAList | Z4: =IFERROR(__xludf.DUMMYFUNCTION("""COMPUTED_VALUE"""),"ToggleBlombergOnRA") -> ToggleBlombergOnRA | AA4: =IFERROR(__xludf.DUMMYFUNCTION("""COMPUTED_VALUE"""),"CreateDoneAwayOrder") -> CreateDoneAwayOrder | AB4: =IFERROR(__xludf.DUMMYFUNCTION("""COMPUTED_VALUE"""),"CreateComplianceOrder") -> CreateComplianceOrder | AC4: =IFERROR(__xludf.DUMMYFUNCTION("""COMPUTED_VALUE"""),"AddOptionTrade") -> AddOptionTrade | AD4: =IFERROR(__xludf.DUMMYFUNCTION("""COMPUTED_VALUE"""),"SendLiveBloomberg") -> SendLiveBloomberg | AE4: =IFERROR(__xludf.DUMMYFUNCTION("""COMPUTED_VALUE"""),"ViewAllocation") -> ViewAllocation | AF4: =IFERROR(__xludf.DUMMYFUNCTION("""COMPUTED_VALUE"""),"CreateReplaceLiveOrder") -> CreateReplaceLiveOrder | AG4: =IFERROR(__xludf.DUMMYFUNCTION("""COMPUTED_VALUE"""),"CreateNewSubLiveOrder") -> CreateNewSubLiveOrder | AH4: =IFERROR(__xludf.DUMMYFUNCTION("""COMPUTED_VALUE"""),"VerifyBasketExport") -> VerifyBasketExport | AI4: =IFERROR(__xludf.DUMMYFUNCTION("""COMPUTED_VALUE"""),"VerifyCustomAllocationonTT") -> VerifyCustomAllocationonTT | AJ4: =IFERROR(__xludf.DUMMYFUNCTION("""COMPUTED_VALUE"""),"CustomOrderTT") -> CustomOrderTT | AK4: =IFERROR(__xludf.DUMMYFUNCTION("""COMPUTED_VALUE"""),"CheckStepSheet") -> CheckStepSheet | AL4: =IFERROR(__xludf.DUMMYFUNCTION("""COMPUTED_VALUE"""),"OptionTradingThroughSecurity") -> OptionTradingThroughSecurity | AM4: =IFERROR(__xludf.DUMMYFUNCTION("""COMPUTED_VALUE"""),"CreateTradeWithAlgoBroker") -> CreateTradeWithAlgoBroker | AN4: =IFERROR(__xludf.DUMMYFUNCTION("""COMPUTED_VALUE"""),"VerifyOrderSide") -> VerifyOrderSide | AO4: =IFERROR(__xludf.DUMMYFUNCTION("""COMPUTED_VALUE"""),"CreateOrEditSymbolTT") -> CreateOrEditSymbolTT | AP4: =IFERROR(__xludf.DUMMYFUNCTION("""COMPUTED_VALUE"""),"VerifyTTNavLockPopup") -> VerifyTTNavLockPopup | AQ4: =IFERROR(__xludf.DUMMYFUNCTION("""COMPUTED_VALUE"""),"VerifyCustomAllocationSecondUI") -> VerifyCustomAllocationSecondUI | AR4: =IFERROR(__xludf.DUMMYFUNCTION("""COMPUTED_VALUE"""),"ShortLocateFromTT") -> ShortLocateFromTT | AS4: =IFERROR(__xludf.DUMMYFUNCTION("""COMPUTED_VALUE"""),"ShortLocateFromTT") -> ShortLocateFromTT | AT4: =IFERROR(__xludf.DUMMYFUNCTION("""COMPUTED_VALUE"""),"ShortLocateFromTT") -> ShortLocateFromTT | AU4: =IFERROR(__xludf.DUMMYFUNCTION("""COMPUTED_VALUE"""),"VerifyShortLocateWindowOnTT") -> VerifyShortLocateWindowOnTT | AV4: =IFERROR(__xludf.DUMMYFUNCTION("""COMPUTED_VALUE"""),"AlgoUIOperations") -> AlgoUIOperations | AW4: =IFERROR(__xludf.DUMMYFUNCTION("""COMPUTED_VALUE"""),"UpdateShortLocateFromTT") -> UpdateShortLocateFromTT | AX4: =IFERROR(__xludf.DUMMYFUNCTION("""COMPUTED_VALUE"""),"ResetTT") -> ResetTT | AY4: =IFERROR(__xludf.DUMMYFUNCTION("""COMPUTED_VALUE"""),"MergeTT") -> MergeTT | AZ4: =IFERROR(__xludf.DUMMYFUNCTION("""COMPUTED_VALUE"""),"ResizeEnsureTT") -> ResizeEnsureTT | BA4: =IFERROR(__xludf.DUMMYFUNCTION("""COMPUTED_VALUE"""),"VerifyExecutionType") -> VerifyExecutionType | BB4: =IFERROR(__xludf.DUMMYFUNCTION("""COMPUTED_VALUE"""),"VerifyPopupAlignment") -> VerifyPopupAlignment | BC4: =IFERROR(__xludf.DUMMYFUNCTION("""COMPUTED_VALUE"""),"SelectET") -> SelectET | BD4: =IFERROR(__xludf.DUMMYFUNCTION("""COMPUTED_VALUE"""),"SymbolSuggestionVerify") -> SymbolSuggestionVerify
B5: Symbol | C5: Quantity | D5: Price | E5: Order type button | F5: SharesOutstandingPopUp | G5: TT_Open | H5: SharesOutstandingPopUpQty | I5: AllocationMethod | J5: Order Side | K5: DB_Check | L5: CommissionBasis | M5: CommissionRate | N5: SoftBasis | O5: SoftRate | P5: Account | Q5: Account % | R5: VerifySuggestions | S5: SymbolToPickFromSuggesstions | T5: TypedSymbolAvailableOnSuggestion | U5: TIF | V5: Order Type | W5: Stop | X5: Limit | Y5: Expiration Date | Z5: Trade Date | AA5: Broker | AB5: Padlock Visiblity | AC5: Padlock Unlock | AD5: Venue | AE5: Fx Rate | AF5: Fx Operator | AG5: PendingApprovalPopUp | AH5: TradeBy | AI5: BookAsSwap | AJ5: RoundLot | AK5: Increment | AL5: Decrement
B6: AAPL | C6: 100 | D6: 20 | E6: CreateOrder
B7: KO | C7: 100 | D7: 20 | E7: CreateOrder

Sheet TradeNewSubOrder
B1: Data
J2: =VLOOKUP($E$3,'_MasterData'!B4:D1000,3,FALSE) -> #N/A
B3: Module | C3: Blotter | D3: Step | F3: Data Format | G3: Input Format
B4: =IFERROR(__xludf.DUMMYFUNCTION("IF(C3="""","""",Transpose(IMPORTRANGE('_Settings'!$B$3,C3&""!A4:A1000"")))"),"#REF!") -> #REF! | C4: EnterDetailsOnTT
B5: Transaction Time | C5: Algo | D5: Avg Fill Price (Base) | E5: Bloomberg Symbol | F5: Limit Price | G5: Working Qty | H5: Venue | I5: User | J5: Underlying Symbol | K5: Underlying Country | L5: Trader | M5: Trade Attribute 6 | N5: Trade Attribute 5 | O5: Trade Attribute 4 | P5: Trade Attribute 3 | Q5: Trade Attribute 1 | R5: Trade Attribute 2 | S5: Strike Price | T5: Stop Price | U5: Settlement Currency | V5: Put/Call | W5: Process Date | X5: Peg | Y5: ParentClOrderID | Z5: OrderID | AA5: Master Fund | AB5: Last Shares | AC5: Internal Comments | AD5: FX Rate | AE5: Imported File Name | AF5: FX Conversion Operator | AG5: Day Average Price | AH5: Asset Class | AI5: Symbol | AJ5: Side | AK5: Status | AL5: Target Qty | AM5: Total Executed Qty | AN5: % Executed | AO5: Day Executed Qty | AP5: Uncommitted Qty | AQ5: Last Fill Price (Local) | AR5: Avg Fill Price (Local) | AS5: Broker | AT5: Account | AU5: Order Type | AV5: Principal Amount (Local) | AW5: Principal Amount (Base) | AX5: Allocation Scheme Name | AY5: Status (With Rollover) | AZ5: Start of Day Qty | BA5: Leaves
AI6: AAPl | AJ6: Buy | AL6: 100

Sheet CreateComplianceOrder
B1: Data
J2: =VLOOKUP($E$3,'_MasterData'!B4:D1000,3,FALSE) -> #N/A
B3: Module | C3: TradingTicket | D3: Step | E3: CreateComplianceOrder | F3: Data Format | G3: Input Format
B4: =IFERROR(__xludf.DUMMYFUNCTION("IF(C3="""","""",Transpose(IMPORTRANGE('_Settings'!$B$3,C3&""!A4:A1000"")))"),"OpenTTFromPST") -> OpenTTFromPST | C4: =IFERROR(__xludf.DUMMYFUNCTION("""COMPUTED_VALUE"""),"EnterDetailsOnTT") -> EnterDetailsOnTT | D4: =IFERROR(__xludf.DUMMYFUNCTION("""COMPUTED_VALUE"""),"ValidateSymbolTT") -> ValidateSymbolTT | E4: =IFERROR(__xludf.DUMMYFUNCTION("""COMPUTED_VALUE"""),"VerifyDataTT") -> VerifyDataTT | F4: =IFERROR(__xludf.DUMMYFUNCTION("""COMPUTED_VALUE"""),"SetUIPreferencesTT") -> SetUIPreferencesTT | G4: =IFERROR(__xludf.DUMMYFUNCTION("""COMPUTED_VALUE"""),"SetBrokerWisePreferencesTT") -> SetBrokerWisePreferencesTT | H4: =IFERROR(__xludf.DUMMYFUNCTION("""COMPUTED_VALUE"""),"VerifyComplianceOrder") -> VerifyComplianceOrder | I4: =IFERROR(__xludf.DUMMYFUNCTION("""COMPUTED_VALUE"""),"TradeNewSub") -> TradeNewSub | J4: =IFERROR(__xludf.DUMMYFUNCTION("""COMPUTED_VALUE"""),"CreateStageOrder") -> CreateStageOrder | K4: =IFERROR(__xludf.DUMMYFUNCTION("""COMPUTED_VALUE"""),"CreateReplaceOrder") -> CreateReplaceOrder | L4: =IFERROR(__xludf.DUMMYFUNCTION("""COMPUTED_VALUE"""),"SetGeneralPreference") -> SetGeneralPreference | M4: =IFERROR(__xludf.DUMMYFUNCTION("""COMPUTED_VALUE"""),"CreateNewSubOrder") -> CreateNewSubOrder | N4: =IFERROR(__xludf.DUMMYFUNCTION("""COMPUTED_VALUE"""),"TradeBloomberg") -> TradeBloomberg | O4: =IFERROR(__xludf.DUMMYFUNCTION("""COMPUTED_VALUE"""),"ClickSymbolLookup") -> ClickSymbolLookup | P4: =IFERROR(__xludf.DUMMYFUNCTION("""COMPUTED_VALUE"""),"VerifyTT") -> VerifyTT | Q4: =IFERROR(__xludf.DUMMYFUNCTION("""COMPUTED_VALUE"""),"CreateLiveOrder") -> CreateLiveOrder | R4: =IFERROR(__xludf.DUMMYFUNCTION("""COMPUTED_VALUE"""),"UpdateMasterFundOnTT") -> UpdateMasterFundOnTT | S4: =IFERROR(__xludf.DUMMYFUNCTION("""COMPUTED_VALUE"""),"SetTTCompliancePreference") -> SetTTCompliancePreference | T4: =IFERROR(__xludf.DUMMYFUNCTION("""COMPUTED_VALUE"""),"ImportSymbol") -> ImportSymbol | U4: =IFERROR(__xludf.DUMMYFUNCTION("""COMPUTED_VALUE"""),"ExportSymbolFromRAList") -> ExportSymbolFromRAList | V4: =IFERROR(__xludf.DUMMYFUNCTION("""COMPUTED_VALUE"""),"CheckPendingNewOrderAlert") -> CheckPendingNewOrderAlert | W4: =IFERROR(__xludf.DUMMYFUNCTION("""COMPUTED_VALUE"""),"AddSymbolOnRAList") -> AddSymbolOnRAList | X4: =IFERROR(__xludf.DUMMYFUNCTION("""COMPUTED_VALUE"""),"DeleteSymbolListFromRA") -> DeleteSymbolListFromRA | Y4: =IFERROR(__xludf.DUMMYFUNCTION("""COMPUTED_VALUE"""),"RemoveSymbolFromRAList") -> RemoveSymbolFromRAList | Z4: =IFERROR(__xludf.DUMMYFUNCTION("""COMPUTED_VALUE"""),"ToggleBlombergOnRA") -> ToggleBlombergOnRA | AA4: =IFERROR(__xludf.DUMMYFUNCTION("""COMPUTED_VALUE"""),"CreateDoneAwayOrder") -> CreateDoneAwayOrder | AB4: =IFERROR(__xludf.DUMMYFUNCTION("""COMPUTED_VALUE"""),"CreateComplianceOrder") -> CreateComplianceOrder | AC4: =IFERROR(__xludf.DUMMYFUNCTION("""COMPUTED_VALUE"""),"AddOptionTrade") -> AddOptionTrade | AD4: =IFERROR(__xludf.DUMMYFUNCTION("""COMPUTED_VALUE"""),"SendLiveBloomberg") -> SendLiveBloomberg | AE4: =IFERROR(__xludf.DUMMYFUNCTION("""COMPUTED_VALUE"""),"ViewAllocation") -> ViewAllocation | AF4: =IFERROR(__xludf.DUMMYFUNCTION("""COMPUTED_VALUE"""),"CreateReplaceLiveOrder") -> CreateReplaceLiveOrder | AG4: =IFERROR(__xludf.DUMMYFUNCTION("""COMPUTED_VALUE"""),"CreateNewSubLiveOrder") -> CreateNewSubLiveOrder | AH4: =IFERROR(__xludf.DUMMYFUNCTION("""COMPUTED_VALUE"""),"VerifyBasketExport") -> VerifyBasketExport | AI4: =IFERROR(__xludf.DUMMYFUNCTION("""COMPUTED_VALUE"""),"VerifyCustomAllocationonTT") -> VerifyCustomAllocationonTT | AJ4: =IFERROR(__xludf.DUMMYFUNCTION("""COMPUTED_VALUE"""),"CustomOrderTT") -> CustomOrderTT | AK4: =IFERROR(__xludf.DUMMYFUNCTION("""COMPUTED_VALUE"""),"CheckStepSheet") -> CheckStepSheet | AL4: =IFERROR(__xludf.DUMMYFUNCTION("""COMPUTED_VALUE"""),"OptionTradingThroughSecurity") -> OptionTradingThroughSecurity | AM4: =IFERROR(__xludf.DUMMYFUNCTION("""COMPUTED_VALUE"""),"CreateTradeWithAlgoBroker") -> CreateTradeWithAlgoBroker | AN4: =IFERROR(__xludf.DUMMYFUNCTION("""COMPUTED_VALUE"""),"VerifyOrderSide") -> VerifyOrderSide | AO4: =IFERROR(__xludf.DUMMYFUNCTION("""COMPUTED_VALUE"""),"CreateOrEditSymbolTT") -> CreateOrEditSymbolTT | AP4: =IFERROR(__xludf.DUMMYFUNCTION("""COMPUTED_VALUE"""),"VerifyTTNavLockPopup") -> VerifyTTNavLockPopup | AQ4: =IFERROR(__xludf.DUMMYFUNCTION("""COMPUTED_VALUE"""),"VerifyCustomAllocationSecondUI") -> VerifyCustomAllocationSecondUI | AR4: =IFERROR(__xludf.DUMMYFUNCTION("""COMPUTED_VALUE"""),"ShortLocateFromTT") -> ShortLocateFromTT | AS4: =IFERROR(__xludf.DUMMYFUNCTION("""COMPUTED_VALUE"""),"ShortLocateFromTT") -> ShortLocateFromTT | AT4: =IFERROR(__xludf.DUMMYFUNCTION("""COMPUTED_VALUE"""),"ShortLocateFromTT") -> ShortLocateFromTT | AU4: =IFERROR(__xludf.DUMMYFUNCTION("""COMPUTED_VALUE"""),"VerifyShortLocateWindowOnTT") -> VerifyShortLocateWindowOnTT | AV4: =IFERROR(__xludf.DUMMYFUNCTION("""COMPUTED_VALUE"""),"AlgoUIOperations") -> AlgoUIOperations | AW4: =IFERROR(__xludf.DUMMYFUNCTION("""COMPUTED_VALUE"""),"UpdateShortLocateFromTT") -> UpdateShortLocateFromTT | AX4: =IFERROR(__xludf.DUMMYFUNCTION("""COMPUTED_VALUE"""),"ResetTT") -> ResetTT | AY4: =IFERROR(__xludf.DUMMYFUNCTION("""COMPUTED_VALUE"""),"MergeTT") -> MergeTT | AZ4: =IFERROR(__xludf.DUMMYFUNCTION("""COMPUTED_VALUE"""),"ResizeEnsureTT") -> ResizeEnsureTT | BA4: =IFERROR(__xludf.DUMMYFUNCTION("""COMPUTED_VALUE"""),"VerifyExecutionType") -> VerifyExecutionType | BB4: =IFERROR(__xludf.DUMMYFUNCTION("""COMPUTED_VALUE"""),"VerifyPopupAlignment") -> VerifyPopupAlignment | BC4: =IFERROR(__xludf.DUMMYFUNCTION("""COMPUTED_VALUE"""),"SelectET") -> SelectET | BD4: =IFERROR(__xludf.DUMMYFUNCTION("""COMPUTED_VALUE"""),"SymbolSuggestionVerify") -> SymbolSuggestionVerify
A5: =IFERROR(__xludf.DUMMYFUNCTION("TRANSPOSE(IMPORTRANGE(VLOOKUP($E$3,IMPORTRANGE('_Settings'!$B$3,$C$3&""!A4:B1000""),2,FALSE),$G$3&""!A4:A1000""))"),"") | B5: =IFERROR(__xludf.DUMMYFUNCTION("""COMPUTED_VALUE"""),"Symbol") -> Symbol | C5: =IFERROR(__xludf.DUMMYFUNCTION("""COMPUTED_VALUE"""),"Order Side") -> Order Side | D5: =IFERROR(__xludf.DUMMYFUNCTION("""COMPUTED_VALUE"""),"Quantity") -> Quantity | E5: =IFERROR(__xludf.DUMMYFUNCTION("""COMPUTED_VALUE"""),"TargetQuantityIn") -> TargetQuantityIn | F5: =IFERROR(__xludf.DUMMYFUNCTION("""COMPUTED_VALUE"""),"AllocationMethod") -> AllocationMethod | G5: =IFERROR(__xludf.DUMMYFUNCTION("""COMPUTED_VALUE"""),"Broker") -> Broker | H5: =IFERROR(__xludf.DUMMYFUNCTION("""COMPUTED_VALUE"""),"TIF") -> TIF | I5: =IFERROR(__xludf.DUMMYFUNCTION("""COMPUTED_VALUE"""),"Order Type") -> Order Type | J5: =IFERROR(__xludf.DUMMYFUNCTION("""COMPUTED_VALUE"""),"Price") -> Price | K5: =IFERROR(__xludf.DUMMYFUNCTION("""COMPUTED_VALUE"""),"Stop") -> Stop | L5: =IFERROR(__xludf.DUMMYFUNCTION("""COMPUTED_VALUE"""),"Limit") -> Limit | M5: =IFERROR(__xludf.DUMMYFUNCTION("""COMPUTED_VALUE"""),"Strategy") -> Strategy | N5: =IFERROR(__xludf.DUMMYFUNCTION("""COMPUTED_VALUE"""),"Trade Date") -> Trade Date | O5: =IFERROR(__xludf.DUMMYFUNCTION("""COMPUTED_VALUE"""),"FxRate") -> FxRate | P5: =IFERROR(__xludf.DUMMYFUNCTION("""COMPUTED_VALUE"""),"Notes") -> Notes | Q5: =IFERROR(__xludf.DUMMYFUNCTION("""COMPUTED_VALUE"""),"Broker Notes") -> Broker Notes | R5: =IFERROR(__xludf.DUMMYFUNCTION("""COMPUTED_VALUE"""),"CommissionBasis") -> CommissionBasis | S5: =IFERROR(__xludf.DUMMYFUNCTION("""COMPUTED_VALUE"""),"CommissionRate") -> CommissionRate | T5: =IFERROR(__xludf.DUMMYFUNCTION("""COMPUTED_VALUE"""),"SoftBasis") -> SoftBasis | U5: =IFERROR(__xludf.DUMMYFUNCTION("""COMPUTED_VALUE"""),"SoftRate") -> SoftRate | V5: =IFERROR(__xludf.DUMMYFUNCTION("""COMPUTED_VALUE"""),"TradeAttribute1") -> TradeAttribute1 | W5: =IFERROR(__xludf.DUMMYFUNCTION("""COMPUTED_VALUE"""),"TradeAttribute2") -> TradeAttribute2 | X5: =IFERROR(__xludf.DUMMYFUNCTION("""COMPUTED_VALUE"""),"TradeAttribute3") -> TradeAttribute3 | Y5: =IFERROR(__xludf.DUMMYFUNCTION("""COMPUTED_VALUE"""),"TradeAttribute4") -> TradeAttribute4 | Z5: =IFERROR(__xludf.DUMMYFUNCTION("""COMPUTED_VALUE"""),"TradeAttribute5") -> TradeAttribute5 | AA5: =IFERROR(__xludf.DUMMYFUNCTION("""COMPUTED_VALUE"""),"TradeAttribute6") -> TradeAttribute6 | AB5: =IFERROR(__xludf.DUMMYFUNCTION("""COMPUTED_VALUE"""),"Venue") -> Venue | AC5: =IFERROR(__xludf.DUMMYFUNCTION("""COMPUTED_VALUE"""),"ExecutionInstructions") -> ExecutionInstructions | AD5: =IFERROR(__xludf.DUMMYFUNCTION("""COMPUTED_VALUE"""),"HandlingInstructions") -> HandlingInstructions | AE5: =IFERROR(__xludf.DUMMYFUNCTION("""COMPUTED_VALUE"""),"Trader") -> Trader | AF5: =IFERROR(__xludf.DUMMYFUNCTION("""COMPUTED_VALUE"""),"SettlementCurrency") -> SettlementCurrency | AG5: =IFERROR(__xludf.DUMMYFUNCTION("""COMPUTED_VALUE"""),"SettlementFXRate") -> SettlementFXRate | AH5: =IFERROR(__xludf.DUMMYFUNCTION("""COMPUTED_VALUE"""),"SettlementAmount") -> SettlementAmount | AI5: =IFERROR(__xludf.DUMMYFUNCTION("""COMPUTED_VALUE"""),"SettlementFXOperator") -> SettlementFXOperator | AJ5: =IFERROR(__xludf.DUMMYFUNCTION("""COMPUTED_VALUE"""),"SettleByBroker") -> SettleByBroker | AK5: =IFERROR(__xludf.DUMMYFUNCTION("""COMPUTED_VALUE"""),"Account") -> Account | AL5: =IFERROR(__xludf.DUMMYFUNCTION("""COMPUTED_VALUE"""),"Account %") -> Account % | AM5: =IFERROR(__xludf.DUMMYFUNCTION("""COMPUTED_VALUE"""),"Deal In") -> Deal In | AN5: =IFERROR(__xludf.DUMMYFUNCTION("""COMPUTED_VALUE"""),"ChkBoxBookAsSwap") -> ChkBoxBookAsSwap | AO5: =IFERROR(__xludf.DUMMYFUNCTION("""COMPUTED_VALUE"""),"PopUpQuantity") -> PopUpQuantity | AP5: =IFERROR(__xludf.DUMMYFUNCTION("""COMPUTED_VALUE"""),"ShortLocate") -> ShortLocate | AQ5: =IFERROR(__xludf.DUMMYFUNCTION("""COMPUTED_VALUE"""),"AllowTrade") -> AllowTrade | AR5: =IFERROR(__xludf.DUMMYFUNCTION("""COMPUTED_VALUE"""),"SharesOutstandingPopUpQty") -> SharesOutstandingPopUpQty | AS5: =IFERROR(__xludf.DUMMYFUNCTION("""COMPUTED_VALUE"""),"SharesOutstandingPopUp") -> SharesOutstandingPopUp | AT5: =IFERROR(__xludf.DUMMYFUNCTION("""COMPUTED_VALUE"""),"ResAllowedListPopUp") -> ResAllowedListPopUp | AU5: =IFERROR(__xludf.DUMMYFUNCTION("""COMPUTED_VALUE"""),"Rate(%)") -> Rate(%) | AV5: =IFERROR(__xludf.DUMMYFUNCTION("""COMPUTED_VALUE"""),"Interest Rate") -> Interest Rate | AW5: =IFERROR(__xludf.DUMMYFUNCTION("""COMPUTED_VALUE"""),"SelectAlgoStrategy") -> SelectAlgoStrategy | AX5: =IFERROR(__xludf.DUMMYFUNCTION("""COMPUTED_VALUE"""),"Button") -> Button | AY5: =IFERROR(__xludf.DUMMYFUNCTION("""COMPUTED_VALUE"""),"EditOrder") -> EditOrder
B6: AAPL | C6: Buy | D6: 100 | J6: 10 | AX6: DoneAway

Sheet OpenModuleFromDock
B1: Data
J2: =VLOOKUP($E$3,'_MasterData'!B4:D1000,3,FALSE) -> #N/A
B3: Module | C3: OpenFin | D3: Step | E3: OpenModuleFromDock | F3: Data Format | G3: Input Format
B4: =IFERROR(__xludf.DUMMYFUNCTION("IF(C3="""","""",Transpose(IMPORTRANGE('_Settings'!$B$3,C3&""!A4:A1000"")))"),"CheckOpenFinWindowName") -> CheckOpenFinWindowName | C4: =IFERROR(__xludf.DUMMYFUNCTION("""COMPUTED_VALUE"""),"OpenWindowFromSearch") -> OpenWindowFromSearch | D4: =IFERROR(__xludf.DUMMYFUNCTION("""COMPUTED_VALUE"""),"VerifyColour") -> VerifyColour | E4: =IFERROR(__xludf.DUMMYFUNCTION("""COMPUTED_VALUE"""),"OpenReleaseClient") -> OpenReleaseClient | F4: =IFERROR(__xludf.DUMMYFUNCTION("""COMPUTED_VALUE"""),"ActionOnPageFromSearch") -> ActionOnPageFromSearch | G4: =IFERROR(__xludf.DUMMYFUNCTION("""COMPUTED_VALUE"""),"SavePageView") -> SavePageView | H4: =IFERROR(__xludf.DUMMYFUNCTION("""COMPUTED_VALUE"""),"ChangeThemeOnModule") -> ChangeThemeOnModule | I4: =IFERROR(__xludf.DUMMYFUNCTION("""COMPUTED_VALUE"""),"CloseService") -> CloseService | J4: =IFERROR(__xludf.DUMMYFUNCTION("""COMPUTED_VALUE"""),"LogOutSamsara") -> LogOutSamsara | K4: =IFERROR(__xludf.DUMMYFUNCTION("""COMPUTED_VALUE"""),"ResizeEnsure") -> ResizeEnsure | L4: =IFERROR(__xludf.DUMMYFUNCTION("""COMPUTED_VALUE"""),"VerifyNotification") -> VerifyNotification | M4: =IFERROR(__xludf.DUMMYFUNCTION("""COMPUTED_VALUE"""),"LockUnlockModule") -> LockUnlockModule | N4: =IFERROR(__xludf.DUMMYFUNCTION("""COMPUTED_VALUE"""),"OpenModuleFromDock") -> OpenModuleFromDock
A5: =IFERROR(__xludf.DUMMYFUNCTION("TRANSPOSE(IMPORTRANGE(VLOOKUP($E$3,IMPORTRANGE('_Settings'!$B$3,$C$3&""!A4:B1000""),2,FALSE),$G$3&""!A4:A1000""))"),"") | B5: =IFERROR(__xludf.DUMMYFUNCTION("""COMPUTED_VALUE"""),"OpenWindow") -> OpenWindow
B6: Trading Ticket

Sheet CheckOpenFinWindowName
B1: Data
J2: =VLOOKUP($E$3,'_MasterData'!B4:D1000,3,FALSE) -> #N/A
B3: Module | C3: OpenFin | D3: Step | E3: CheckOpenFinWindowName | F3: Data Format | G3: Input Format
B4: =IFERROR(__xludf.DUMMYFUNCTION("IF(C3="""","""",Transpose(IMPORTRANGE('_Settings'!$B$3,C3&""!A4:A1000"")))"),"CheckOpenFinWindowName") -> CheckOpenFinWindowName | C4: =IFERROR(__xludf.DUMMYFUNCTION("""COMPUTED_VALUE"""),"OpenWindowFromSearch") -> OpenWindowFromSearch | D4: =IFERROR(__xludf.DUMMYFUNCTION("""COMPUTED_VALUE"""),"VerifyColour") -> VerifyColour | E4: =IFERROR(__xludf.DUMMYFUNCTION("""COMPUTED_VALUE"""),"OpenReleaseClient") -> OpenReleaseClient | F4: =IFERROR(__xludf.DUMMYFUNCTION("""COMPUTED_VALUE"""),"ActionOnPageFromSearch") -> ActionOnPageFromSearch | G4: =IFERROR(__xludf.DUMMYFUNCTION("""COMPUTED_VALUE"""),"SavePageView") -> SavePageView | H4: =IFERROR(__xludf.DUMMYFUNCTION("""COMPUTED_VALUE"""),"ChangeThemeOnModule") -> ChangeThemeOnModule | I4: =IFERROR(__xludf.DUMMYFUNCTION("""COMPUTED_VALUE"""),"CloseService") -> CloseService | J4: =IFERROR(__xludf.DUMMYFUNCTION("""COMPUTED_VALUE"""),"LogOutSamsara") -> LogOutSamsara | K4: =IFERROR(__xludf.DUMMYFUNCTION("""COMPUTED_VALUE"""),"ResizeEnsure") -> ResizeEnsure | L4: =IFERROR(__xludf.DUMMYFUNCTION("""COMPUTED_VALUE"""),"VerifyNotification") -> VerifyNotification | M4: =IFERROR(__xludf.DUMMYFUNCTION("""COMPUTED_VALUE"""),"LockUnlockModule") -> LockUnlockModule | N4: =IFERROR(__xludf.DUMMYFUNCTION("""COMPUTED_VALUE"""),"OpenModuleFromDock") -> OpenModuleFromDock
A5: =IFERROR(__xludf.DUMMYFUNCTION("TRANSPOSE(IMPORTRANGE(VLOOKUP($E$3,IMPORTRANGE('_Settings'!$B$3,$C$3&""!A4:B1000""),2,FALSE),$G$3&""!A4:A1000""))"),"") | B5: =IFERROR(__xludf.DUMMYFUNCTION("""COMPUTED_VALUE"""),"WindowName") -> WindowName | C5: =IFERROR(__xludf.DUMMYFUNCTION("""COMPUTED_VALUE"""),"WindowPresentOrNot") -> WindowPresentOrNot
B6: Pre-Trade Compliance Results | C6: TRUE
B7: Trading Ticket | C7: FALSE

Sheet VerifyComplianceOrder
B1: Data
J2: =VLOOKUP($E$3,'_MasterData'!B4:D1000,3,FALSE) -> #N/A
B3: Module | C3: TradingTicket | D3: Step | E3: VerifyComplianceOrder | F3: Data Format | G3: Input Format
B4: =IFERROR(__xludf.DUMMYFUNCTION("IF(C3="""","""",Transpose(IMPORTRANGE('_Settings'!$B$3,C3&""!A4:A1000"")))"),"OpenTTFromPST") -> OpenTTFromPST | C4: =IFERROR(__xludf.DUMMYFUNCTION("""COMPUTED_VALUE"""),"EnterDetailsOnTT") -> EnterDetailsOnTT | D4: =IFERROR(__xludf.DUMMYFUNCTION("""COMPUTED_VALUE"""),"ValidateSymbolTT") -> ValidateSymbolTT | E4: =IFERROR(__xludf.DUMMYFUNCTION("""COMPUTED_VALUE"""),"VerifyDataTT") -> VerifyDataTT | F4: =IFERROR(__xludf.DUMMYFUNCTION("""COMPUTED_VALUE"""),"SetUIPreferencesTT") -> SetUIPreferencesTT | G4: =IFERROR(__xludf.DUMMYFUNCTION("""COMPUTED_VALUE"""),"SetBrokerWisePreferencesTT") -> SetBrokerWisePreferencesTT | H4: =IFERROR(__xludf.DUMMYFUNCTION("""COMPUTED_VALUE"""),"VerifyComplianceOrder") -> VerifyComplianceOrder | I4: =IFERROR(__xludf.DUMMYFUNCTION("""COMPUTED_VALUE"""),"TradeNewSub") -> TradeNewSub | J4: =IFERROR(__xludf.DUMMYFUNCTION("""COMPUTED_VALUE"""),"CreateStageOrder") -> CreateStageOrder | K4: =IFERROR(__xludf.DUMMYFUNCTION("""COMPUTED_VALUE"""),"CreateReplaceOrder") -> CreateReplaceOrder | L4: =IFERROR(__xludf.DUMMYFUNCTION("""COMPUTED_VALUE"""),"SetGeneralPreference") -> SetGeneralPreference | M4: =IFERROR(__xludf.DUMMYFUNCTION("""COMPUTED_VALUE"""),"CreateNewSubOrder") -> CreateNewSubOrder | N4: =IFERROR(__xludf.DUMMYFUNCTION("""COMPUTED_VALUE"""),"TradeBloomberg") -> TradeBloomberg | O4: =IFERROR(__xludf.DUMMYFUNCTION("""COMPUTED_VALUE"""),"ClickSymbolLookup") -> ClickSymbolLookup | P4: =IFERROR(__xludf.DUMMYFUNCTION("""COMPUTED_VALUE"""),"VerifyTT") -> VerifyTT | Q4: =IFERROR(__xludf.DUMMYFUNCTION("""COMPUTED_VALUE"""),"CreateLiveOrder") -> CreateLiveOrder | R4: =IFERROR(__xludf.DUMMYFUNCTION("""COMPUTED_VALUE"""),"UpdateMasterFundOnTT") -> UpdateMasterFundOnTT | S4: =IFERROR(__xludf.DUMMYFUNCTION("""COMPUTED_VALUE"""),"SetTTCompliancePreference") -> SetTTCompliancePreference | T4: =IFERROR(__xludf.DUMMYFUNCTION("""COMPUTED_VALUE"""),"ImportSymbol") -> ImportSymbol | U4: =IFERROR(__xludf.DUMMYFUNCTION("""COMPUTED_VALUE"""),"ExportSymbolFromRAList") -> ExportSymbolFromRAList | V4: =IFERROR(__xludf.DUMMYFUNCTION("""COMPUTED_VALUE"""),"CheckPendingNewOrderAlert") -> CheckPendingNewOrderAlert | W4: =IFERROR(__xludf.DUMMYFUNCTION("""COMPUTED_VALUE"""),"AddSymbolOnRAList") -> AddSymbolOnRAList | X4: =IFERROR(__xludf.DUMMYFUNCTION("""COMPUTED_VALUE"""),"DeleteSymbolListFromRA") -> DeleteSymbolListFromRA | Y4: =IFERROR(__xludf.DUMMYFUNCTION("""COMPUTED_VALUE"""),"RemoveSymbolFromRAList") -> RemoveSymbolFromRAList | Z4: =IFERROR(__xludf.DUMMYFUNCTION("""COMPUTED_VALUE"""),"ToggleBlombergOnRA") -> ToggleBlombergOnRA | AA4: =IFERROR(__xludf.DUMMYFUNCTION("""COMPUTED_VALUE"""),"CreateDoneAwayOrder") -> CreateDoneAwayOrder | AB4: =IFERROR(__xludf.DUMMYFUNCTION("""COMPUTED_VALUE"""),"CreateComplianceOrder") -> CreateComplianceOrder | AC4: =IFERROR(__xludf.DUMMYFUNCTION("""COMPUTED_VALUE"""),"AddOptionTrade") -> AddOptionTrade | AD4: =IFERROR(__xludf.DUMMYFUNCTION("""COMPUTED_VALUE"""),"SendLiveBloomberg") -> SendLiveBloomberg | AE4: =IFERROR(__xludf.DUMMYFUNCTION("""COMPUTED_VALUE"""),"ViewAllocation") -> ViewAllocation | AF4: =IFERROR(__xludf.DUMMYFUNCTION("""COMPUTED_VALUE"""),"CreateReplaceLiveOrder") -> CreateReplaceLiveOrder | AG4: =IFERROR(__xludf.DUMMYFUNCTION("""COMPUTED_VALUE"""),"CreateNewSubLiveOrder") -> CreateNewSubLiveOrder | AH4: =IFERROR(__xludf.DUMMYFUNCTION("""COMPUTED_VALUE"""),"VerifyBasketExport") -> VerifyBasketExport | AI4: =IFERROR(__xludf.DUMMYFUNCTION("""COMPUTED_VALUE"""),"VerifyCustomAllocationonTT") -> VerifyCustomAllocationonTT | AJ4: =IFERROR(__xludf.DUMMYFUNCTION("""COMPUTED_VALUE"""),"CustomOrderTT") -> CustomOrderTT | AK4: =IFERROR(__xludf.DUMMYFUNCTION("""COMPUTED_VALUE"""),"CheckStepSheet") -> CheckStepSheet | AL4: =IFERROR(__xludf.DUMMYFUNCTION("""COMPUTED_VALUE"""),"OptionTradingThroughSecurity") -> OptionTradingThroughSecurity | AM4: =IFERROR(__xludf.DUMMYFUNCTION("""COMPUTED_VALUE"""),"CreateTradeWithAlgoBroker") -> CreateTradeWithAlgoBroker | AN4: =IFERROR(__xludf.DUMMYFUNCTION("""COMPUTED_VALUE"""),"VerifyOrderSide") -> VerifyOrderSide | AO4: =IFERROR(__xludf.DUMMYFUNCTION("""COMPUTED_VALUE"""),"CreateOrEditSymbolTT") -> CreateOrEditSymbolTT | AP4: =IFERROR(__xludf.DUMMYFUNCTION("""COMPUTED_VALUE"""),"VerifyTTNavLockPopup") -> VerifyTTNavLockPopup | AQ4: =IFERROR(__xludf.DUMMYFUNCTION("""COMPUTED_VALUE"""),"VerifyCustomAllocationSecondUI") -> VerifyCustomAllocationSecondUI | AR4: =IFERROR(__xludf.DUMMYFUNCTION("""COMPUTED_VALUE"""),"ShortLocateFromTT") -> ShortLocateFromTT | AS4: =IFERROR(__xludf.DUMMYFUNCTION("""COMPUTED_VALUE"""),"ShortLocateFromTT") -> ShortLocateFromTT | AT4: =IFERROR(__xludf.DUMMYFUNCTION("""COMPUTED_VALUE"""),"ShortLocateFromTT") -> ShortLocateFromTT | AU4: =IFERROR(__xludf.DUMMYFUNCTION("""COMPUTED_VALUE"""),"VerifyShortLocateWindowOnTT") -> VerifyShortLocateWindowOnTT | AV4: =IFERROR(__xludf.DUMMYFUNCTION("""COMPUTED_VALUE"""),"AlgoUIOperations") -> AlgoUIOperations | AW4: =IFERROR(__xludf.DUMMYFUNCTION("""COMPUTED_VALUE"""),"UpdateShortLocateFromTT") -> UpdateShortLocateFromTT | AX4: =IFERROR(__xludf.DUMMYFUNCTION("""COMPUTED_VALUE"""),"ResetTT") -> ResetTT | AY4: =IFERROR(__xludf.DUMMYFUNCTION("""COMPUTED_VALUE"""),"MergeTT") -> MergeTT | AZ4: =IFERROR(__xludf.DUMMYFUNCTION("""COMPUTED_VALUE"""),"ResizeEnsureTT") -> ResizeEnsureTT | BA4: =IFERROR(__xludf.DUMMYFUNCTION("""COMPUTED_VALUE"""),"VerifyExecutionType") -> VerifyExecutionType | BB4: =IFERROR(__xludf.DUMMYFUNCTION("""COMPUTED_VALUE"""),"VerifyPopupAlignment") -> VerifyPopupAlignment | BC4: =IFERROR(__xludf.DUMMYFUNCTION("""COMPUTED_VALUE"""),"SelectET") -> SelectET | BD4: =IFERROR(__xludf.DUMMYFUNCTION("""COMPUTED_VALUE"""),"SymbolSuggestionVerify") -> SymbolSuggestionVerify
A5: =IFERROR(__xludf.DUMMYFUNCTION("TRANSPOSE(IMPORTRANGE(VLOOKUP($E$3,IMPORTRANGE('_Settings'!$B$3,$C$3&""!A4:B1000""),2,FALSE),$G$3&""!A4:A1000""))"),"") | B5: =IFERROR(__xludf.DUMMYFUNCTION("""COMPUTED_VALUE"""),"Alert Type") -> Alert Type | C5: =IFERROR(__xludf.DUMMYFUNCTION("""COMPUTED_VALUE"""),"Rule Name") -> Rule Name | D5: =IFERROR(__xludf.DUMMYFUNCTION("""COMPUTED_VALUE"""),"Description of Rule") -> Description of Rule | E5: =IFERROR(__xludf.DUMMYFUNCTION("""COMPUTED_VALUE"""),"Dimensions") -> Dimensions | F5: =IFERROR(__xludf.DUMMYFUNCTION("""COMPUTED_VALUE"""),"Threshold") -> Threshold | G5: =IFERROR(__xludf.DUMMYFUNCTION("""COMPUTED_VALUE"""),"Actual Result") -> Actual Result | H5: =IFERROR(__xludf.DUMMYFUNCTION("""COMPUTED_VALUE"""),"Comments") -> Comments | I5: =IFERROR(__xludf.DUMMYFUNCTION("""COMPUTED_VALUE"""),"User Notes") -> User Notes | J5: =IFERROR(__xludf.DUMMYFUNCTION("""COMPUTED_VALUE"""),"Write UserNote") -> Write UserNote | K5: =IFERROR(__xludf.DUMMYFUNCTION("""COMPUTED_VALUE"""),"AllowTrade") -> AllowTrade | L5: =IFERROR(__xludf.DUMMYFUNCTION("""COMPUTED_VALUE"""),"ClickonMultiple") -> ClickonMultiple | M5: =IFERROR(__xludf.DUMMYFUNCTION("""COMPUTED_VALUE"""),"Trade") -> Trade | N5: =IFERROR(__xludf.DUMMYFUNCTION("""COMPUTED_VALUE"""),"PendingApprovalPopUp") -> PendingApprovalPopUp | O5: =IFERROR(__xludf.DUMMYFUNCTION("""COMPUTED_VALUE"""),"VerifyExportState") -> VerifyExportState
B6: Soft | K6: Yes | M6: DoneAway

Sheet LockUnlockModule
B1: Data
J2: =VLOOKUP($E$3,'_MasterData'!B4:D1000,3,FALSE) -> #N/A
B3: Module | C3: OpenFin | D3: Step | E3: LockUnlockModule | F3: Data Format | G3: Input Format
B4: =IFERROR(__xludf.DUMMYFUNCTION("IF(C3="""","""",Transpose(IMPORTRANGE('_Settings'!$B$3,C3&""!A4:A1000"")))"),"CheckOpenFinWindowName") -> CheckOpenFinWindowName | C4: =IFERROR(__xludf.DUMMYFUNCTION("""COMPUTED_VALUE"""),"OpenWindowFromSearch") -> OpenWindowFromSearch | D4: =IFERROR(__xludf.DUMMYFUNCTION("""COMPUTED_VALUE"""),"VerifyColour") -> VerifyColour | E4: =IFERROR(__xludf.DUMMYFUNCTION("""COMPUTED_VALUE"""),"OpenReleaseClient") -> OpenReleaseClient | F4: =IFERROR(__xludf.DUMMYFUNCTION("""COMPUTED_VALUE"""),"ActionOnPageFromSearch") -> ActionOnPageFromSearch | G4: =IFERROR(__xludf.DUMMYFUNCTION("""COMPUTED_VALUE"""),"SavePageView") -> SavePageView | H4: =IFERROR(__xludf.DUMMYFUNCTION("""COMPUTED_VALUE"""),"ChangeThemeOnModule") -> ChangeThemeOnModule | I4: =IFERROR(__xludf.DUMMYFUNCTION("""COMPUTED_VALUE"""),"CloseService") -> CloseService | J4: =IFERROR(__xludf.DUMMYFUNCTION("""COMPUTED_VALUE"""),"LogOutSamsara") -> LogOutSamsara | K4: =IFERROR(__xludf.DUMMYFUNCTION("""COMPUTED_VALUE"""),"ResizeEnsure") -> ResizeEnsure | L4: =IFERROR(__xludf.DUMMYFUNCTION("""COMPUTED_VALUE"""),"VerifyNotification") -> VerifyNotification | M4: =IFERROR(__xludf.DUMMYFUNCTION("""COMPUTED_VALUE"""),"LockUnlockModule") -> LockUnlockModule | N4: =IFERROR(__xludf.DUMMYFUNCTION("""COMPUTED_VALUE"""),"OpenModuleFromDock") -> OpenModuleFromDock
A5: =IFERROR(__xludf.DUMMYFUNCTION("TRANSPOSE(IMPORTRANGE(VLOOKUP($E$3,IMPORTRANGE('_Settings'!$B$3,$C$3&""!A4:B1000""),2,FALSE),$G$3&""!A4:A1000""))"),"") | B5: =IFERROR(__xludf.DUMMYFUNCTION("""COMPUTED_VALUE"""),"OpenWindow") -> OpenWindow
B6: Trading Ticket

Sheet TradeNewSubOrder1
B1: Data
J2: =VLOOKUP($E$3,'_MasterData'!B4:D1000,3,FALSE) -> #N/A
B3: Module | C3: TradingTicket | D3: Step | E3: CreateDoneAwayOrder | F3: Data Format | G3: Input Format
B4: =IFERROR(__xludf.DUMMYFUNCTION("IF(C3="""","""",Transpose(IMPORTRANGE('_Settings'!$B$3,C3&""!A4:A1000"")))"),"OpenTTFromPST") -> OpenTTFromPST | C4: =IFERROR(__xludf.DUMMYFUNCTION("""COMPUTED_VALUE"""),"EnterDetailsOnTT") -> EnterDetailsOnTT | D4: =IFERROR(__xludf.DUMMYFUNCTION("""COMPUTED_VALUE"""),"ValidateSymbolTT") -> ValidateSymbolTT | E4: =IFERROR(__xludf.DUMMYFUNCTION("""COMPUTED_VALUE"""),"VerifyDataTT") -> VerifyDataTT | F4: =IFERROR(__xludf.DUMMYFUNCTION("""COMPUTED_VALUE"""),"SetUIPreferencesTT") -> SetUIPreferencesTT | G4: =IFERROR(__xludf.DUMMYFUNCTION("""COMPUTED_VALUE"""),"SetBrokerWisePreferencesTT") -> SetBrokerWisePreferencesTT | H4: =IFERROR(__xludf.DUMMYFUNCTION("""COMPUTED_VALUE"""),"VerifyComplianceOrder") -> VerifyComplianceOrder | I4: =IFERROR(__xludf.DUMMYFUNCTION("""COMPUTED_VALUE"""),"TradeNewSub") -> TradeNewSub | J4: =IFERROR(__xludf.DUMMYFUNCTION("""COMPUTED_VALUE"""),"CreateStageOrder") -> CreateStageOrder | K4: =IFERROR(__xludf.DUMMYFUNCTION("""COMPUTED_VALUE"""),"CreateReplaceOrder") -> CreateReplaceOrder | L4: =IFERROR(__xludf.DUMMYFUNCTION("""COMPUTED_VALUE"""),"SetGeneralPreference") -> SetGeneralPreference | M4: =IFERROR(__xludf.DUMMYFUNCTION("""COMPUTED_VALUE"""),"CreateNewSubOrder") -> CreateNewSubOrder | N4: =IFERROR(__xludf.DUMMYFUNCTION("""COMPUTED_VALUE"""),"TradeBloomberg") -> TradeBloomberg | O4: =IFERROR(__xludf.DUMMYFUNCTION("""COMPUTED_VALUE"""),"ClickSymbolLookup") -> ClickSymbolLookup | P4: =IFERROR(__xludf.DUMMYFUNCTION("""COMPUTED_VALUE"""),"VerifyTT") -> VerifyTT | Q4: =IFERROR(__xludf.DUMMYFUNCTION("""COMPUTED_VALUE"""),"CreateLiveOrder") -> CreateLiveOrder | R4: =IFERROR(__xludf.DUMMYFUNCTION("""COMPUTED_VALUE"""),"UpdateMasterFundOnTT") -> UpdateMasterFundOnTT | S4: =IFERROR(__xludf.DUMMYFUNCTION("""COMPUTED_VALUE"""),"SetTTCompliancePreference") -> SetTTCompliancePreference | T4: =IFERROR(__xludf.DUMMYFUNCTION("""COMPUTED_VALUE"""),"ImportSymbol") -> ImportSymbol | U4: =IFERROR(__xludf.DUMMYFUNCTION("""COMPUTED_VALUE"""),"ExportSymbolFromRAList") -> ExportSymbolFromRAList | V4: =IFERROR(__xludf.DUMMYFUNCTION("""COMPUTED_VALUE"""),"CheckPendingNewOrderAlert") -> CheckPendingNewOrderAlert | W4: =IFERROR(__xludf.DUMMYFUNCTION("""COMPUTED_VALUE"""),"AddSymbolOnRAList") -> AddSymbolOnRAList | X4: =IFERROR(__xludf.DUMMYFUNCTION("""COMPUTED_VALUE"""),"DeleteSymbolListFromRA") -> DeleteSymbolListFromRA | Y4: =IFERROR(__xludf.DUMMYFUNCTION("""COMPUTED_VALUE"""),"RemoveSymbolFromRAList") -> RemoveSymbolFromRAList | Z4: =IFERROR(__xludf.DUMMYFUNCTION("""COMPUTED_VALUE"""),"ToggleBlombergOnRA") -> ToggleBlombergOnRA | AA4: =IFERROR(__xludf.DUMMYFUNCTION("""COMPUTED_VALUE"""),"CreateDoneAwayOrder") -> CreateDoneAwayOrder | AB4: =IFERROR(__xludf.DUMMYFUNCTION("""COMPUTED_VALUE"""),"CreateComplianceOrder") -> CreateComplianceOrder | AC4: =IFERROR(__xludf.DUMMYFUNCTION("""COMPUTED_VALUE"""),"AddOptionTrade") -> AddOptionTrade | AD4: =IFERROR(__xludf.DUMMYFUNCTION("""COMPUTED_VALUE"""),"SendLiveBloomberg") -> SendLiveBloomberg | AE4: =IFERROR(__xludf.DUMMYFUNCTION("""COMPUTED_VALUE"""),"ViewAllocation") -> ViewAllocation | AF4: =IFERROR(__xludf.DUMMYFUNCTION("""COMPUTED_VALUE"""),"CreateReplaceLiveOrder") -> CreateReplaceLiveOrder | AG4: =IFERROR(__xludf.DUMMYFUNCTION("""COMPUTED_VALUE"""),"CreateNewSubLiveOrder") -> CreateNewSubLiveOrder | AH4: =IFERROR(__xludf.DUMMYFUNCTION("""COMPUTED_VALUE"""),"VerifyBasketExport") -> VerifyBasketExport | AI4: =IFERROR(__xludf.DUMMYFUNCTION("""COMPUTED_VALUE"""),"VerifyCustomAllocationonTT") -> VerifyCustomAllocationonTT | AJ4: =IFERROR(__xludf.DUMMYFUNCTION("""COMPUTED_VALUE"""),"CustomOrderTT") -> CustomOrderTT | AK4: =IFERROR(__xludf.DUMMYFUNCTION("""COMPUTED_VALUE"""),"CheckStepSheet") -> CheckStepSheet | AL4: =IFERROR(__xludf.DUMMYFUNCTION("""COMPUTED_VALUE"""),"OptionTradingThroughSecurity") -> OptionTradingThroughSecurity | AM4: =IFERROR(__xludf.DUMMYFUNCTION("""COMPUTED_VALUE"""),"CreateTradeWithAlgoBroker") -> CreateTradeWithAlgoBroker | AN4: =IFERROR(__xludf.DUMMYFUNCTION("""COMPUTED_VALUE"""),"VerifyOrderSide") -> VerifyOrderSide | AO4: =IFERROR(__xludf.DUMMYFUNCTION("""COMPUTED_VALUE"""),"CreateOrEditSymbolTT") -> CreateOrEditSymbolTT | AP4: =IFERROR(__xludf.DUMMYFUNCTION("""COMPUTED_VALUE"""),"VerifyTTNavLockPopup") -> VerifyTTNavLockPopup | AQ4: =IFERROR(__xludf.DUMMYFUNCTION("""COMPUTED_VALUE"""),"VerifyCustomAllocationSecondUI") -> VerifyCustomAllocationSecondUI | AR4: =IFERROR(__xludf.DUMMYFUNCTION("""COMPUTED_VALUE"""),"ShortLocateFromTT") -> ShortLocateFromTT | AS4: =IFERROR(__xludf.DUMMYFUNCTION("""COMPUTED_VALUE"""),"ShortLocateFromTT") -> ShortLocateFromTT | AT4: =IFERROR(__xludf.DUMMYFUNCTION("""COMPUTED_VALUE"""),"ShortLocateFromTT") -> ShortLocateFromTT | AU4: =IFERROR(__xludf.DUMMYFUNCTION("""COMPUTED_VALUE"""),"VerifyShortLocateWindowOnTT") -> VerifyShortLocateWindowOnTT | AV4: =IFERROR(__xludf.DUMMYFUNCTION("""COMPUTED_VALUE"""),"AlgoUIOperations") -> AlgoUIOperations | AW4: =IFERROR(__xludf.DUMMYFUNCTION("""COMPUTED_VALUE"""),"UpdateShortLocateFromTT") -> UpdateShortLocateFromTT | AX4: =IFERROR(__xludf.DUMMYFUNCTION("""COMPUTED_VALUE"""),"ResetTT") -> ResetTT | AY4: =IFERROR(__xludf.DUMMYFUNCTION("""COMPUTED_VALUE"""),"MergeTT") -> MergeTT | AZ4: =IFERROR(__xludf.DUMMYFUNCTION("""COMPUTED_VALUE"""),"ResizeEnsureTT") -> ResizeEnsureTT | BA4: =IFERROR(__xludf.DUMMYFUNCTION("""COMPUTED_VALUE"""),"VerifyExecutionType") -> VerifyExecutionType | BB4: =IFERROR(__xludf.DUMMYFUNCTION("""COMPUTED_VALUE"""),"VerifyPopupAlignment") -> VerifyPopupAlignment | BC4: =IFERROR(__xludf.DUMMYFUNCTION("""COMPUTED_VALUE"""),"SelectET") -> SelectET | BD4: =IFERROR(__xludf.DUMMYFUNCTION("""COMPUTED_VALUE"""),"SymbolSuggestionVerify") -> SymbolSuggestionVerify
B5: Transaction Time | C5: Algo | D5: Avg Fill Price (Base) | E5: Bloomberg Symbol | F5: Limit Price | G5: Working Qty | H5: Venue | I5: User | J5: Underlying Symbol | K5: Underlying Country | L5: Trader | M5: Trade Attribute 6 | N5: Trade Attribute 5 | O5: Trade Attribute 4 | P5: Trade Attribute 3 | Q5: Trade Attribute 1 | R5: Trade Attribute 2 | S5: Strike Price | T5: Stop Price | U5: Settlement Currency | V5: Put/Call | W5: Process Date | X5: Peg | Y5: ParentClOrderID | Z5: OrderID | AA5: Master Fund | AB5: Last Shares | AC5: Internal Comments | AD5: FX Rate | AE5: Imported File Name | AF5: FX Conversion Operator | AG5: Day Average Price | AH5: Asset Class | AI5: Symbol | AJ5: Side | AK5: Status | AL5: Target Qty | AM5: Total Executed Qty | AN5: % Executed | AO5: Day Executed Qty | AP5: Uncommitted Qty | AQ5: Last Fill Price (Local) | AR5: Avg Fill Price (Local) | AS5: Broker | AT5: Account | AU5: Order Type | AV5: Principal Amount (Local) | AW5: Principal Amount (Base) | AX5: Allocation Scheme Name | AY5: Status (With Rollover) | AZ5: Start of Day Qty | BA5: Leaves
AI6: KO | AJ6: Buy | AL6: 100

Sheet CheckOpenFinWindowName1
B1: Data
J2: =VLOOKUP($E$3,'_MasterData'!B4:D1000,3,FALSE) -> #N/A
B3: Module | C3: OpenFin | D3: Step | E3: CheckOpenFinWindowName | F3: Data Format | G3: Input Format
B4: =IFERROR(__xludf.DUMMYFUNCTION("IF(C3="""","""",Transpose(IMPORTRANGE('_Settings'!$B$3,C3&""!A4:A1000"")))"),"CheckOpenFinWindowName") -> CheckOpenFinWindowName | C4: =IFERROR(__xludf.DUMMYFUNCTION("""COMPUTED_VALUE"""),"OpenWindowFromSearch") -> OpenWindowFromSearch | D4: =IFERROR(__xludf.DUMMYFUNCTION("""COMPUTED_VALUE"""),"VerifyColour") -> VerifyColour | E4: =IFERROR(__xludf.DUMMYFUNCTION("""COMPUTED_VALUE"""),"OpenReleaseClient") -> OpenReleaseClient | F4: =IFERROR(__xludf.DUMMYFUNCTION("""COMPUTED_VALUE"""),"ActionOnPageFromSearch") -> ActionOnPageFromSearch | G4: =IFERROR(__xludf.DUMMYFUNCTION("""COMPUTED_VALUE"""),"SavePageView") -> SavePageView | H4: =IFERROR(__xludf.DUMMYFUNCTION("""COMPUTED_VALUE"""),"ChangeThemeOnModule") -> ChangeThemeOnModule | I4: =IFERROR(__xludf.DUMMYFUNCTION("""COMPUTED_VALUE"""),"CloseService") -> CloseService | J4: =IFERROR(__xludf.DUMMYFUNCTION("""COMPUTED_VALUE"""),"LogOutSamsara") -> LogOutSamsara | K4: =IFERROR(__xludf.DUMMYFUNCTION("""COMPUTED_VALUE"""),"ResizeEnsure") -> ResizeEnsure | L4: =IFERROR(__xludf.DUMMYFUNCTION("""COMPUTED_VALUE"""),"VerifyNotification") -> VerifyNotification | M4: =IFERROR(__xludf.DUMMYFUNCTION("""COMPUTED_VALUE"""),"LockUnlockModule") -> LockUnlockModule | N4: =IFERROR(__xludf.DUMMYFUNCTION("""COMPUTED_VALUE"""),"OpenModuleFromDock") -> OpenModuleFromDock
A5: =IFERROR(__xludf.DUMMYFUNCTION("TRANSPOSE(IMPORTRANGE(VLOOKUP($E$3,IMPORTRANGE('_Settings'!$B$3,$C$3&""!A4:B1000""),2,FALSE),$G$3&""!A4:A1000""))"),"") | B5: =IFERROR(__xludf.DUMMYFUNCTION("""COMPUTED_VALUE"""),"WindowName") -> WindowName | C5: =IFERROR(__xludf.DUMMYFUNCTION("""COMPUTED_VALUE"""),"WindowPresentOrNot") -> WindowPresentOrNot
B6: KO - Trading Ticket | C6: FALSE
