Workbook

Sheet _Modules
A1: Modules Info
A3: Modules
A4: =IFERROR(__xludf.DUMMYFUNCTION("IMPORTRANGE('_Settings'!B3,""Modules!A4:L1000"")"),"Allocation") -> Allocation | B4: Allocate | C4: undefined
A5: Allocation | B5: CheckAllocatedGroups | C5: 1L-ZLJ-WUi30_f-lOlKY8keIuba5MrxrSFg61cuw6a1Q
A6: Allocation | B6: Unallocate | C6: 1EwSV_9D5NTEl2PEpL_Jt7zJTHUPrALTb8OtSzPCvCyw
A7: Allocation | B7: GetDataAllocation | C7: 1DppyOA5Ydn7_wREefqS5OXdf-FB0aeezazxO7l_KkPI
A8: Allocation | B8: SelectAllocatedGroup | C8: 1EwSV_9D5NTEl2PEpL_Jt7zJTHUPrALTb8OtSzPCvCyw
A9: Allocation | B9: EditTradesAllocated | C9: 1mZVDHa5HAPBlU7A7Qt_dcTY5NCi1wrh46jO_Kvm6p0Y
A10: Allocation | B10: EditTradesUnallocated | C10: 11fJBWY-Z4X4pAJ10BZMvanCBUxCez87FACI3SN4oHhc
A11: Allocation | B11: Reallocate | C11: undefined
A12: Blotter | B12: ReplaceFillsOnBlotter | C12: undefined
A13: Blotter | B13: CheckBlotter | C13: 1gCNoZk41UU6qYClK-xpR_ek0RFJSoyNo2GYPM85gGKU
A14: GeneralLedger | B14: GetDataCash | C14: 1mrbqxvNyXyDjk1XgAgEZXuSeTqc593taxDqDOV7hZqA
A15: GeneralLedger | B15: EnterCashDividends | C15: 1OE2eAPH4pnVoDKHq07XJnAWdqq3B53-Vz_fU3XSLsOo
A16: GeneralLedger | B16: EnterNonTradingTransaction | C16: 1zgBoPmpmJ5_Bxh0JLfP4NSXfDAdqPOOnRDY40vNAJdc
... A136: Blotter | B136: TransferToUserOrder | C136: 14InZb8SNY40mEv1SSHdXyYM9uUfHH_RYVe5I_ZduiAM
A137: Allocation | B137: CloseCalculatedPreferences
A138: TradingTicket | B138: CreateReplaceOrder | C138: 1jFE79xo0b9W0HJJs-HmlLF7udJScoHnuVUGcEZPDmp8
A139: Blotter | B139: EditOrder | C139: 1MBNM6rxMapSxXXYy6UK5cB5Mm-bkVGjo0iNbHGdxDDw
A140: Blotter | B140: SelectTradeSubOrderBlotter | C140: 1LbV8pvlircDAqSgbL-BKgTJwzz_cmXCqxEiU57Ci5OE
A141: Blotter | B141: VerifyOrder | C141: 1oOS0wr4TlVQYMcyMgjNQGBvRlWWWkCgPKAmDiNwd424
A142: Blotter | B142: VerifySubOrder | C142: 18m2emPTSMX9x8ImL8xIvTxR6WyzF9mZts5Ff0iPAYuI
A143: Blotter | B143: RemoveSelectedOrders | C143: 1EJ9TjV53fXZzJ7A6K1DLboXLoaSZfSenii_KPeOnMzw
A144: Blotter | B144: CancelAllSelectedSubs | C144: 1Lyvk7bRx3dI9U21dqLgGQ4ReyVk7Fg6WkayG_WSvsOM
A145: Blotter | B145: MultiTradingTicket | C145: 1bPHEr59kxpPk3j6GmaEhDvltCPQMggoHcEF4O23XEqQ
A146: Blotter | B146: AuditTrailOrderBlotter | C146: 1mluc81dVHErhRCeaKr2aujEkMGGfYOQ79O6PxhmTgiw
A147: Blotter | B147: TradeNewSubOrder | C147: 10pwxvaFTBXtbFBhsCB8qR8twnbPWxCipQKY6AQxOZ-s
A148: Blotter | B148: RemoveStageOrder | C148: 1L-cgfoBNr1Merxa4xauhs8VQmicSxJIxJ1S-26aapDM
A149: TradingTicket | B149: SetGeneralPreference | C149: 1tiKvuYV-RSxi_jQ9OrEjHDaRE48gx-1VUrfbcDRzBqI
... A164: Allocation | B164: ImportCalculatedPreferencesTool | C164: 1Pz-_3uwP9cgwTQ2fq8xKkNw2j2tG4dto0mMIdpoyzyE
A165: GeneralLedger | B165: RunRevaluation
A166: GeneralLedger | B166: CalculateDayEndCash
A167: Allocation | B167: ExportAllCalculatedPreferTool | C167: 1lPDSQfgavG8kFJMCSrGhdzO3KiscTppqCoKt6N6dQeU
A168: Allocation | B168: OpenAuditTrailAllocatedGroup | C168: 1SPOgNGUarAvXiMCTVmaSYuGWIMk0j_jJaNaY5VkX9Hw
A169: Allocation | B169: OpenSymbolLookupUnallocateGroup | C169: 1DKcxcD1U6XoEecNXYKf6mmAIOPrXKRk0zUHXHNuzyCw
A170: Allocation | B170: OpenSymbolLookupAllocatedGroup | C170: 1MNcP6XIG9bpEL3NbBBg7G2BVvTczbcpB5E-n4znXVQ8
A171: Allocation | B171: DeleteFixedPreference | C171: 1xCPCtn2rJZWfCaJ3xJk34V9VIGqbQqnumhF_D1nCrJQ
A172: Blotter | B172: TransferToUserSubOrder | C172: 1FjfJ7iSl3gpA2-NLJT143BORY3lF-ucwyKVsOAdxbZI
A173: Blotter | B173: DetailsForAlgoTradeOrder | C173: 1n-asacXwX-M_P6fakIZxYHvBw3nr6vN53glg_OJimsk
A174: Blotter | B174: AddFillsSubOrder | C174: 1_nYfAYJO3sygqeqe0ZD6JSxzyp8hWAfm7M7p2pcs78A
...

Sheet _Settings
A1: Settings
A3: Module Step Setting File | B3: 1jzmqcGUKrtaw2eG0h9EmAVqiksOTc5tCg2fjw0rnduM
A4: Master Data Settings File | B4: 1EGvQ4gQZof5ChEr7TLuvC_9b1eGAQgRVRtrGCIOSzkc

Sheet _MasterData
A1: Master Data Info
A3: Module | B3: Step | C3: Master Data Sheet
A4: =IFERROR(__xludf.DUMMYFUNCTION("IMPORTRANGE('_Settings'!B4,""Master Data!A4:L1000"")"),"#REF!") -> #REF!

Sheet CreateDoneAwayOrder
B1: Data
J2: =VLOOKUP($E$3,_MasterData!B4:D1000,3,FALSE) -> #N/A
B3: Module | C3: TradingTicket | D3: Step | E3: CreateDoneAwayOrder | F3: Data Format | G3: Input Format
B4: =IFERROR(__xludf.DUMMYFUNCTION("IF(C3="""","""",Transpose(IMPORTRANGE('_Settings'!$B$3,C3&""!A4:A1000"")))"),"OpenTTFromPST") -> OpenTTFromPST | C4: EnterDetailsOnTT | D4: ValidateSymbolTT | E4: VerifyDataTT | F4: SetUIPreferencesTT | G4: SetBrokerWisePreferencesTT | H4: TradeNewSub | I4: SetBrokerWisePreferencesTT | J4: TradeNewSub | K4: CreateStageOrder | L4: CreateReplaceOrder | M4: SetGeneralPreference | N4: CreateDoneAwayOrder | O4: ClickSymbolLookup | P4: TradeBloomberg | Q4: CreateNewSubOrder
A5: =IFERROR(__xludf.DUMMYFUNCTION("TRANSPOSE(IMPORTRANGE(VLOOKUP($E$3,IMPORTRANGE('_Settings'!$B$3,$C$3&""!A4:B1000""),2,FALSE),$G$3&""!A4:A1000""))"),"") | B5: Symbol | C5: Order Side | D5: Quantity | E5: TargetQuantityIn | F5: AllocationMethod | G5: Broker | H5: TIF | I5: Order Type | J5: Price | K5: Stop | L5: Limit | M5: Strategy | N5: Trade Date | O5: FxRate | P5: Notes | Q5: Broker Notes | R5: CommissionBasis | S5: CommissionRate | T5: SoftBasis | U5: SoftRate | V5: TradeAttribute1 | W5: TradeAttribute2 | X5: TradeAttribute3 | Y5: TradeAttribute4 | Z5: TradeAttribute5 | AA5: TradeAttribute6 | AB5: Venue | AC5: ExecutionInstructions | AD5: HandlingInstructions | AE5: Trader | AF5: SettlementCurrency | AG5: SettlementFXRate | AH5: SettlementAmount | AI5: SettlementFXOperator | AJ5: SettleByBroker | AK5: Account | AL5: Account % | AM5: Deal In
B6: MSFT | C6: Buy | D6: 400 | E6: 400 | J6: 1 | AK6: Allocation1,Allocation2,Allocation3 | AL6: 25,25,50
B7: AAPL | C7: Buy | D7: 400 | E7: 400 | J7: 1 | AK7: Allocation1,Allocation2 | AL7: 25,75
B8: INFY | C8: Buy | D8: 400 | E8: 400 | F8: OFFSHORE | J8: 1
B9: MSFT | C9: Buy | D9: 100 | E9: 100 | F9: Unallocated | J9: 1
B10: AAPL | C10: Sell | D10: 600 | E10: 600 | F10: Unallocated | J10: 1
B11: INFY | C11: Sell | D11: 400 | E11: 400 | F11: Unallocated | J11: 1
B12: TESS | C12: Sell short | D12: 100 | E12: 100 | F12: Unallocated | J12: 1

Sheet GetDailyCash
B1: Data
J2: =VLOOKUP($E$3,_MasterData!B4:D1000,3,FALSE) -> #N/A
B3: Module | C3: DailyValuation | D3: Step | E3: GetDailyCash | F3: Data Format | G3: Input Format
B4: =IFERROR(__xludf.DUMMYFUNCTION("IF(C3="""","""",Transpose(IMPORTRANGE('_Settings'!$B$3,C3&""!A4:A1000"")))"),"UpdateBeta") -> UpdateBeta | C4: UpdateDailyCash | D4: UpdateForexConversion | E4: UpdateMarkPrice | F4: CleanUp | G4: GetMarkPriceData | H4: UpdateForwardPoints | I4: GetForwardPoints | J4: UpdateForwardPoints | K4: GetForexConversion | L4: DeleteNAV | M4: GetDailyCash | N4: GetDailyOutstandings | O4: GetDailyVolatility | P4: GetDailyDividendYield | Q4: GetDailyBeta | R4: GetDailyTradingVolume | S4: GetDailyDelta | T4: UpdateDailyVolatility | U4: UpdateDividendYield | V4: UpdateTradingVolume | W4: UpdateDailyDelta | X4: UpdateDailyOutstandings | Y4: UpdateBeta | Z4: UpdateNAV | AA4: UpdateDailyCash | AB4: UpdateDailyCreditLimt | AC4: RemoveDailyCreditLimit | AD4: RemoveDailyCash | AE4: RemoveNAV | BL4: UpdateNAV | BM4: UpdateDailyCash | BN4: UpdateDailyCreditLimt | BO4: RemoveDailyCreditLimit | BP4: RemoveDailyCash | BQ4: RemoveNAV
A5: =IFERROR(__xludf.DUMMYFUNCTION("TRANSPOSE(IMPORTRANGE(VLOOKUP($E$3,IMPORTRANGE('_Settings'!$B$3,$C$3&""!A4:B1000""),2,FALSE),$G$3&""!A4:A1000""))"),"") | B5: Select Date | C5: Copy From
B6: =TODAY()-1 -> 43641 | C6: =TODAY() -> 43642

Sheet UpdateDailyCash
B1: Data
J2: =VLOOKUP($E$3,_MasterData!B4:D1000,3,FALSE) -> #N/A
B3: Module | C3: DailyValuation | D3: Step | E3: UpdateDailyCash | F3: Data Format | G3: Input Format
B4: =IFERROR(__xludf.DUMMYFUNCTION("IF(C3="""","""",Transpose(IMPORTRANGE('_Settings'!$B$3,C3&""!A4:A1000"")))"),"UpdateBeta") -> UpdateBeta | C4: UpdateDailyCash | D4: UpdateForexConversion | E4: UpdateMarkPrice | F4: CleanUp | G4: GetMarkPriceData | H4: UpdateForwardPoints | I4: GetForwardPoints | J4: UpdateForwardPoints | K4: GetForexConversion | L4: DeleteNAV | M4: GetDailyCash | N4: GetDailyOutstandings | O4: GetDailyVolatility | P4: GetDailyDividendYield | Q4: GetDailyBeta | R4: GetDailyTradingVolume | S4: GetDailyDelta | T4: UpdateDailyVolatility | U4: UpdateDividendYield | V4: UpdateTradingVolume | W4: UpdateDailyDelta | X4: UpdateDailyOutstandings | Y4: UpdateBeta | Z4: UpdateNAV | AA4: UpdateDailyCash | AB4: UpdateDailyCreditLimt | AC4: RemoveDailyCreditLimit | AD4: RemoveDailyCash | AE4: RemoveNAV | BL4: UpdateNAV | BM4: UpdateDailyCash | BN4: UpdateDailyCreditLimt | BO4: RemoveDailyCreditLimit | BP4: RemoveDailyCash | BQ4: RemoveNAV
A5: =IFERROR(__xludf.DUMMYFUNCTION("TRANSPOSE(IMPORTRANGE(VLOOKUP($E$3,IMPORTRANGE('_Settings'!$B$3,$C$3&""!A4:B1000""),2,FALSE),$G$3&""!A4:A1000""))"),"") | B5: Account | C5: Local Currency | D5: Cash Value Local
B6: Allocation1 | C6: USD | D6: 71218
B7: Allocation2 | C7: USD | D7: 14894
B8: Allocation3 | C8: USD | D8: 35679

Sheet PricingInput
B1: Data
J2: =VLOOKUP($E$3,_MasterData!B4:D1000,3,FALSE) -> #N/A
B3: Module | C3: PricingInput | D3: Step | E3: PricingInput | F3: Data Format | G3: Input Format
B4: =IFERROR(__xludf.DUMMYFUNCTION("IF(C3="""","""",Transpose(IMPORTRANGE('_Settings'!$B$3,C3&""!A4:A1000"")))"),"PricingInput") -> PricingInput | C4: UpdateSharesOutstanding | D4: EODTPreferences | E4: LiveData
A5: =IFERROR(__xludf.DUMMYFUNCTION("TRANSPOSE(IMPORTRANGE(VLOOKUP($E$3,IMPORTRANGE('_Settings'!$B$3,$C$3&""!A4:B1000""),2,FALSE),$G$3&""!A4:A1000""))"),"") | B5: Symbol | C5: User Px | D5: Asset Class | E5: Volatility(%) | F5: Historical Volatility | G5: User Volatility | H5: Interest Rate | I5: User Interest Rate | J5: Dividend Yield | K5: User Dividend Yield | L5: Actual Delta | M5: User Delta | N5: Selected Px | O5: Forward Points | P5: Shares Outstanding | Q5: User Shares Outstanding | R5: LastPriceUsed | S5: VolatilityUsed | T5: IntRateUsed
B6: MSFT | C6: 5 | Q6: 1000
B7: AAPL | C7: 5 | Q7: 1000
B8: TESS | C8: 5 | Q8: 1000
B9: INFY | C9: 5 | Q9: 1000

Sheet TradePTT
B1: Data
J2: =VLOOKUP($E$3,_MasterData!B4:D1000,3,FALSE) -> #N/A
B3: Module | C3: PTT | D3: Step | E3: TradePTT | F3: Data Format | G3: Input Format
B4: =IFERROR(__xludf.DUMMYFUNCTION("IF(C3="""","""",Transpose(IMPORTRANGE('_Settings'!$B$3,C3&""!A4:A1000"")))"),"SetAccountFactor") -> SetAccountFactor | C4: EditMultiTT | D4: SelectMultiTT | E4: OpenMultiTTFromPTT | F4: VerifyPTT | G4: TradePTT | H4: CreateOrderPTT | I4: StageOrderUsingPTT | J4: TradeUsingPTT | K4: CalculatePTT
A5: =IFERROR(__xludf.DUMMYFUNCTION("TRANSPOSE(IMPORTRANGE(VLOOKUP($E$3,IMPORTRANGE('_Settings'!$B$3,$C$3&""!A4:B1000""),2,FALSE),$G$3&""!A4:A1000""))"),"") | B5: Ticker | C5: Add/Set | D5: Type | E5: Target | F5: Price | G5: Combined Account Total | H5: MasterFund/Account | I5: Accounts
B6: HITT | D6: Percentage | E6: 5 | F6: 1 | G6: No | H6: Account | I6: Allocation1,Allocation2,Allocation3

Sheet CreateDoneAwayOrderPTT
B1: Data
J2: =VLOOKUP($E$3,_MasterData!B4:D1000,3,FALSE) -> #N/A
B3: Module | C3: TradingTicket | D3: Step | E3: CreateDoneAwayOrder | F3: Data Format | G3: Input Format
B4: =IFERROR(__xludf.DUMMYFUNCTION("IF(C3="""","""",Transpose(IMPORTRANGE('_Settings'!$B$3,C3&""!A4:A1000"")))"),"OpenTTFromPST") -> OpenTTFromPST | C4: EnterDetailsOnTT | D4: ValidateSymbolTT | E4: VerifyDataTT | F4: SetUIPreferencesTT | G4: SetBrokerWisePreferencesTT | H4: TradeNewSub | I4: SetBrokerWisePreferencesTT | J4: TradeNewSub | K4: CreateStageOrder | L4: CreateReplaceOrder | M4: SetGeneralPreference | N4: CreateDoneAwayOrder | O4: ClickSymbolLookup | P4: TradeBloomberg | Q4: CreateNewSubOrder
A5: =IFERROR(__xludf.DUMMYFUNCTION("TRANSPOSE(IMPORTRANGE(VLOOKUP($E$3,IMPORTRANGE('_Settings'!$B$3,$C$3&""!A4:B1000""),2,FALSE),$G$3&""!A4:A1000""))"),"") | B5: Symbol | C5: Order Side | D5: Quantity | E5: TargetQuantityIn | F5: AllocationMethod | G5: Broker | H5: TIF | I5: Order Type | J5: Price | K5: Stop | L5: Limit | M5: Strategy | N5: Trade Date | O5: FxRate | P5: Notes | Q5: Broker Notes | R5: CommissionBasis | S5: CommissionRate | T5: SoftBasis | U5: SoftRate | V5: TradeAttribute1 | W5: TradeAttribute2 | X5: TradeAttribute3 | Y5: TradeAttribute4 | Z5: TradeAttribute5 | AA5: TradeAttribute6 | AB5: Venue | AC5: ExecutionInstructions | AD5: HandlingInstructions | AE5: Trader | AF5: SettlementCurrency | AG5: SettlementFXRate | AH5: SettlementAmount | AI5: SettlementFXOperator | AJ5: SettleByBroker | AK5: Account | AL5: Account % | AM5: Deal In
B6: HITT | D6: 500 | E6: 500 | J6: 1

Sheet Unallocate
B1: Data
J2: =VLOOKUP($E$3,_MasterData!B4:D1000,3,FALSE) -> #N/A
B3: Module | C3: Allocation | D3: Step | E3: Unallocate | F3: Data Format | G3: Input Format
B4: =IFERROR(__xludf.DUMMYFUNCTION("IF(C3="""","""",Transpose(IMPORTRANGE('_Settings'!$B$3,C3&""!A4:A1000"")))"),"Allocate") -> Allocate | C4: Reallocate | D4: CleanUp | E4: SaveCalculatedPreferences | F4: CloseCalculatedPreferences | G4: CloseAllocation | H4: SaveCloseMFPreference | I4: ModifyMFPrefGeneralRuleValues | J4: ClearPrefetchFilters | K4: ExpandCollapseAllUnallocated | L4: ExpandCollapseAllAllocated | M4: SaveAllocation | N4: CheckAllocatedGroups | O4: GetDataAllocation | P4: SelectAllocatedGroup | Q4: EditTradesAllocated | R4: EditTradesUnallocated | S4: EditUnallocatedGroupSidePanel | T4: TradeAttributeBulkChange | U4: ApplyBulkUpdateOnGroups | V4: ApplyPrefetchFilters | W4: GeneralPreferencesDefaultRule | X4: GeneralPrefCompanyUserWise | Y4: RenameTradeAttributes | Z4: SetGroupingRules | AA4: SetMasterFundRatio | AB4: CheckFixedPreference | AC4: GetFixedPreference | AD4: BulkChangeCalculatedPreferences | AE4: AddCalculatedPreferences | AF4: DeleteCalculatedPreferences | AG4: RenameCalculatedPreferences | AH4: CopyCalculatedPreferences | AI4: RunAutoGroup | AJ4: BookOrUpdateSwap | AK4: RunProrata | AL4: SetDefaultRuleCalculatedPref | AM4: SetAccountValueCalculatedPref | AN4: TradeAttributeBulkChangeGroups | AO4: TradeAttributeBulkChangeTaxlots | AP4: AddCalculatedPreferenceToolbar | AQ4: SetStrategyValueCalculatedPref | AR4: ApplyBulkUpdateOnTaxlots | AS4: CommissionBulkChangeOnGroups | AT4: CommissionBulkChangeOnTaxlots | AU4: SelectUnallocatedGroup | AV4: EnterAccountValuesToAllocate | AW4: EnterAllocatePreference | AX4: UnallocateWithOutSave | AY4: GenerateCashTransaction | AZ4: EnterStrategyValuesToAllocate | BA4: CopyCalculatedPreferenceToolbar | BB4: SetGeneralRuleCalculatedPref | BC4: ExportAllCalculatedPreferences | BD4: SetMFPrefFundDefaultRule | BE4: SetMFPreferencesDefaultRule | BF4: SetMFPrefFundDistribution | BG4: SetMFPrefGeneralRule | BH4: SetMFPrefStrategyValues | BI4: SetMFPrefAccountValues | BJ4: RenameMFPreferences | BK4: ExportCalculatedPreference | BL4: DeleteMFPreferenceToolbar | BM4: DeleteMFPreferences | BN4: AddMFPreferenceToolbar | BO4: AddMFPreferences | BP4: ModifyGRPreferenceValues | BQ4: ImportCalculatedPreferences | BR4: OpenAuditTrailUnallocatedGroup | BS4: DeleteCalculatedPreferencesTool | BT4: ImportCalculatedPreferencesTool | BU4: ExportAllCalculatedPreferTool | BV4: OpenAuditTrailAllocatedGroup | BW4: OpenSymbolLookupUnallocateGroup | BX4: OpenSymbolLookupAllocatedGroup | BY4: DeleteFixedPreference | BZ4: UpdateGRDefaultRule | CA4: UpdateGeneralRulePref | CB4: EditAllocatedGroupSidePanel | CC4: UpdateGRStrategyValue | CD4: UpdateGRAccountValue | CE4: CheckUnallocatedGroups | CF4: SetGeneralPreferences | CG4: UngroupTrades | CH4: GroupTrades | CI4: DeleteGroup | CJ4: Unallocate | CK4: UpdateGeneralRulePref | CL4: CloseOrder | CM4: CheckUnallocatedGroups | CN4: EditAllocatedGroupSidePanel | CO4: DeleteFixedPreference | CP4: ExportCalculatedPreference
A5: =IFERROR(__xludf.DUMMYFUNCTION("TRANSPOSE(IMPORTRANGE(VLOOKUP($E$3,IMPORTRANGE('_Settings'!$B$3,$C$3&""!A4:B1000""),2,FALSE),$G$3&""!A4:A1000""))"),"") | B5: Symbol | C5: Quantity | D5: Trade Date | E5: Account Name | F5: Side | G5: Group Status | H5: Avg Price(Base) | I5: Execution Time | J5: Trade Attribute 1 | K5: Avg Price(Local) | L5: Trade Attribute 2 | M5: Accrued Interest | N5: Commission | O5: Soft Commission | P5: Broker | Q5: Transaction Type | R5: AUEC Fee1 | S5: AUEC Fee2 | T5: Clearing Broker Fee | U5: Other Broker Fees | V5: OCC Fee | W5: SEC Fee | X5: ORF Fee | Y5: IsPreAllocated | Z5: Stamp Duty | AA5: IsManual Group | AB5: Tax On Commissions | AC5: IsAnotherTaxlotAttributesUpdated | AD5: ISNDF | AE5: Transaction Levy | AF5: Description | AG5: GroupID | AH5: Internal Comments | AI5: M2MProfitLoss | AJ5: FX Rate | AK5: FX Conversion Operator | AL5: Trade Attribute 3 | AM5: Trade Attribute 4 | AN5: Trade Attribute 5 | AO5: Trade Attribute 6 | AP5: Put Or Call | AQ5: Allocated Qty | AR5: Total Commission And Fee | AS5: Executed Qty | AT5: Net Amount( Local) | AU5: Net Amount( Base) | AV5: UnAllocatedQty | AW5: Option Premium Adjustment | AX5: Principal Amount( Local) | AY5: Principal Amount( Base) | AZ5: Settlement Currency | BA5: User | BB5: Asset Category | BC5: Change Type | BD5: Strategy Name | BE5: Prana Msg Type | BF5: Total Commission | BG5: Commission Per Share | BH5: Soft Commission Per Share | BI5: Total Commission Per Share | BJ5: Closing Status | BK5: Closing Method | BL5: Allocation Scheme Name | BM5: Change Comment | BN5: Order Type | BO5: Underlying | BP5: Exchange | BQ5: Currency | BR5: AUECID | BS5: Trading Account | BT5: Venue | BU5: Cum Qty For Sub Order | BV5: Contract Multiplier | BW5: Company | BX5: Nirvana Process Date | BY5: Process Date | BZ5: Original Purchase Date | CA5: Closing Date | CB5: Settlement Date | CC5: Expiration Date | CD5: Underlying Symbol | CE5: Accrual Basis | CF5: Bond Type | CG5: Coupon Rate | CH5: Delta | CI5: Bloomberg | CJ5: Sedol Symbol | CK5: Cusip Symbol | CL5: ISIN | CM5: OSISSymbol | CN5: IDCOSymbol | CO5: Underlying Delta | CP5: Proxy Symbol | CQ5: Transaction Source | CR5: Import File Name
B6: HITT | C6: 500 | F6: Buy | H6: 1

Sheet SelectUnallocatedGroup
B1: Data
J2: =VLOOKUP($E$3,_MasterData!B4:D1000,3,FALSE) -> #N/A
B3: Module | C3: Allocation | D3: Step | E3: SelectUnallocatedGroup | F3: Data Format | G3: Input Format
B4: =IFERROR(__xludf.DUMMYFUNCTION("IF(C3="""","""",Transpose(IMPORTRANGE('_Settings'!$B$3,C3&""!A4:A1000"")))"),"Allocate") -> Allocate | C4: Reallocate | D4: CleanUp | E4: SaveCalculatedPreferences | F4: CloseCalculatedPreferences | G4: CloseAllocation | H4: SaveCloseMFPreference | I4: ModifyMFPrefGeneralRuleValues | J4: ClearPrefetchFilters | K4: ExpandCollapseAllUnallocated | L4: ExpandCollapseAllAllocated | M4: SaveAllocation | N4: CheckAllocatedGroups | O4: GetDataAllocation | P4: SelectAllocatedGroup | Q4: EditTradesAllocated | R4: EditTradesUnallocated | S4: EditUnallocatedGroupSidePanel | T4: TradeAttributeBulkChange | U4: ApplyBulkUpdateOnGroups | V4: ApplyPrefetchFilters | W4: GeneralPreferencesDefaultRule | X4: GeneralPrefCompanyUserWise | Y4: RenameTradeAttributes | Z4: SetGroupingRules | AA4: SetMasterFundRatio | AB4: CheckFixedPreference | AC4: GetFixedPreference | AD4: BulkChangeCalculatedPreferences | AE4: AddCalculatedPreferences | AF4: DeleteCalculatedPreferences | AG4: RenameCalculatedPreferences | AH4: CopyCalculatedPreferences | AI4: RunAutoGroup | AJ4: BookOrUpdateSwap | AK4: RunProrata | AL4: SetDefaultRuleCalculatedPref | AM4: SetAccountValueCalculatedPref | AN4: TradeAttributeBulkChangeGroups | AO4: TradeAttributeBulkChangeTaxlots | AP4: AddCalculatedPreferenceToolbar | AQ4: SetStrategyValueCalculatedPref | AR4: ApplyBulkUpdateOnTaxlots | AS4: CommissionBulkChangeOnGroups | AT4: CommissionBulkChangeOnTaxlots | AU4: SelectUnallocatedGroup | AV4: EnterAccountValuesToAllocate | AW4: EnterAllocatePreference | AX4: UnallocateWithOutSave | AY4: GenerateCashTransaction | AZ4: EnterStrategyValuesToAllocate | BA4: CopyCalculatedPreferenceToolbar | BB4: SetGeneralRuleCalculatedPref | BC4: ExportAllCalculatedPreferences | BD4: SetMFPrefFundDefaultRule | BE4: SetMFPreferencesDefaultRule | BF4: SetMFPrefFundDistribution | BG4: SetMFPrefGeneralRule | BH4: SetMFPrefStrategyValues | BI4: SetMFPrefAccountValues | BJ4: RenameMFPreferences | BK4: ExportCalculatedPreference | BL4: DeleteMFPreferenceToolbar | BM4: DeleteMFPreferences | BN4: AddMFPreferenceToolbar | BO4: AddMFPreferences | BP4: ModifyGRPreferenceValues | BQ4: ImportCalculatedPreferences | BR4: OpenAuditTrailUnallocatedGroup | BS4: DeleteCalculatedPreferencesTool | BT4: ImportCalculatedPreferencesTool | BU4: ExportAllCalculatedPreferTool | BV4: OpenAuditTrailAllocatedGroup | BW4: OpenSymbolLookupUnallocateGroup | BX4: OpenSymbolLookupAllocatedGroup | BY4: DeleteFixedPreference | BZ4: UpdateGRDefaultRule | CA4: UpdateGeneralRulePref | CB4: EditAllocatedGroupSidePanel | CC4: UpdateGRStrategyValue | CD4: UpdateGRAccountValue | CE4: CheckUnallocatedGroups | CF4: SetGeneralPreferences | CG4: UngroupTrades | CH4: GroupTrades | CI4: DeleteGroup | CJ4: Unallocate | CK4: UpdateGeneralRulePref | CL4: CloseOrder | CM4: CheckUnallocatedGroups | CN4: EditAllocatedGroupSidePanel | CO4: DeleteFixedPreference | CP4: ExportCalculatedPreference
A5: =IFERROR(__xludf.DUMMYFUNCTION("TRANSPOSE(IMPORTRANGE(VLOOKUP($E$3,IMPORTRANGE('_Settings'!$B$3,$C$3&""!A4:B1000""),2,FALSE),$G$3&""!A4:A1000""))"),"") | B5: Symbol | C5: Side | D5: Quantity | E5: Executed Qty | F5: Trade Date | G5: Net Amount( Local) | H5: Net Amount( Base) | I5: Principal Amount( Local) | J5: Transaction Type | K5: Principal Amount( Base) | L5: Execution Time | M5: Trading Account | N5: Avg Price(Local) | O5: Avg Price(Base) | P5: Broker | Q5: FX Rate | R5: Venue | S5: FX Conversion Operator | T5: User | U5: Asset Category | V5: Settlement Currency | W5: Commission Per Share | X5: Soft Commission Per Share | Y5: Total Commission Per Share | Z5: Change Type | AA5: Trade Attribute 1 | AB5: Trade Attribute 2 | AC5: Trade Attribute 3 | AD5: Trade Attribute 4 | AE5: Trade Attribute 5 | AF5: Trade Attribute 6 | AG5: IsPreAllocated | AH5: IsManual Group | AI5: IsAnotherTaxlotAttributesUpdated | AJ5: ISNDF | AK5: M2MProfitLoss | AL5: Put Or Call | AM5: GroupID | AN5: UnAllocatedQty | AO5: Allocated Qty | AP5: Commission | AQ5: Soft Commission | AR5: Other Broker Fees | AS5: Clearing Broker Fee | AT5: Total Commission And Fee | AU5: Transaction Levy | AV5: Stamp Duty | AW5: AUEC Fee1 | AX5: Tax On Commissions | AY5: AUEC Fee2 | AZ5: SEC Fee | BA5: OCC Fee | BB5: ORF Fee | BC5: Option Premium Adjustment | BD5: Prana Msg Type | BE5: Total Commission | BF5: Closing Status | BG5: Closing Method | BH5: Group Status | BI5: Allocation Scheme Name | BJ5: Change Comment | BK5: Order Type | BL5: Underlying | BM5: Exchange | BN5: Currency | BO5: AUECID | BP5: Cum Qty For Sub Order | BQ5: Contract Multiplier | BR5: Company | BS5: Nirvana Process Date | BT5: Process Date | BU5: Original Purchase Date | BV5: Closing Date | BW5: Settlement Date | BX5: Expiration Date | BY5: Description | BZ5: Underlying Symbol | CA5: Accrued Interest | CB5: Accrual Basis | CC5: Bond Type | CD5: Coupon Rate | CE5: Delta | CF5: Bloomberg | CG5: Sedol Symbol | CH5: Cusip Symbol | CI5: ISIN | CJ5: OSISSymbol | CK5: IDCOSymbol | CL5: Underlying Delta | CM5: Internal Comments | CN5: Proxy Symbol | CO5: Transaction Source | CP5: Import File Name
B6: MSFT | C6: Buy | D6: 100 | E6: 100 | O6: 1
B7: AAPL | C7: Sell | D7: 600 | E7: 600 | O7: 1
B8: INFY | C8: Sell | D8: 400 | E8: 400 | O8: 1
B9: TESS | C9: Sell short | D9: 100 | E9: 100 | O9: 1
B10: HITT | C10: Buy | D10: 500 | E10: 500 | O10: 1

Sheet EnterAllocatePreference
B1: Data
J2: =VLOOKUP($E$3,_MasterData!B4:D1000,3,FALSE) -> #N/A
B3: Module | C3: Allocation | D3: Step | E3: EnterAllocatePreference | F3: Data Format | G3: Input Format
B4: =IFERROR(__xludf.DUMMYFUNCTION("IF(C3="""","""",Transpose(IMPORTRANGE('_Settings'!$B$3,C3&""!A4:A1000"")))"),"Allocate") -> Allocate | C4: Reallocate | D4: CleanUp | E4: SaveCalculatedPreferences | F4: CloseCalculatedPreferences | G4: CloseAllocation | H4: SaveCloseMFPreference | I4: ModifyMFPrefGeneralRuleValues | J4: ClearPrefetchFilters | K4: ExpandCollapseAllUnallocated | L4: ExpandCollapseAllAllocated | M4: SaveAllocation | N4: CheckAllocatedGroups | O4: GetDataAllocation | P4: SelectAllocatedGroup | Q4: EditTradesAllocated | R4: EditTradesUnallocated | S4: EditUnallocatedGroupSidePanel | T4: TradeAttributeBulkChange | U4: ApplyBulkUpdateOnGroups | V4: ApplyPrefetchFilters | W4: GeneralPreferencesDefaultRule | X4: GeneralPrefCompanyUserWise | Y4: RenameTradeAttributes | Z4: SetGroupingRules | AA4: SetMasterFundRatio | AB4: CheckFixedPreference | AC4: GetFixedPreference | AD4: BulkChangeCalculatedPreferences | AE4: AddCalculatedPreferences | AF4: DeleteCalculatedPreferences | AG4: RenameCalculatedPreferences | AH4: CopyCalculatedPreferences | AI4: RunAutoGroup | AJ4: BookOrUpdateSwap | AK4: RunProrata | AL4: SetDefaultRuleCalculatedPref | AM4: SetAccountValueCalculatedPref | AN4: TradeAttributeBulkChangeGroups | AO4: TradeAttributeBulkChangeTaxlots | AP4: AddCalculatedPreferenceToolbar | AQ4: SetStrategyValueCalculatedPref | AR4: ApplyBulkUpdateOnTaxlots | AS4: CommissionBulkChangeOnGroups | AT4: CommissionBulkChangeOnTaxlots | AU4: SelectUnallocatedGroup | AV4: EnterAccountValuesToAllocate | AW4: EnterAllocatePreference | AX4: UnallocateWithOutSave | AY4: GenerateCashTransaction | AZ4: EnterStrategyValuesToAllocate | BA4: CopyCalculatedPreferenceToolbar | BB4: SetGeneralRuleCalculatedPref | BC4: ExportAllCalculatedPreferences | BD4: SetMFPrefFundDefaultRule | BE4: SetMFPreferencesDefaultRule | BF4: SetMFPrefFundDistribution | BG4: SetMFPrefGeneralRule | BH4: SetMFPrefStrategyValues | BI4: SetMFPrefAccountValues | BJ4: RenameMFPreferences | BK4: ExportCalculatedPreference | BL4: DeleteMFPreferenceToolbar | BM4: DeleteMFPreferences | BN4: AddMFPreferenceToolbar | BO4: AddMFPreferences | BP4: ModifyGRPreferenceValues | BQ4: ImportCalculatedPreferences | BR4: OpenAuditTrailUnallocatedGroup | BS4: DeleteCalculatedPreferencesTool | BT4: ImportCalculatedPreferencesTool | BU4: ExportAllCalculatedPreferTool | BV4: OpenAuditTrailAllocatedGroup | BW4: OpenSymbolLookupUnallocateGroup | BX4: OpenSymbolLookupAllocatedGroup | BY4: DeleteFixedPreference | BZ4: UpdateGRDefaultRule | CA4: UpdateGeneralRulePref | CB4: EditAllocatedGroupSidePanel | CC4: UpdateGRStrategyValue | CD4: UpdateGRAccountValue | CE4: CheckUnallocatedGroups | CF4: SetGeneralPreferences | CG4: UngroupTrades | CH4: GroupTrades | CI4: DeleteGroup | CJ4: Unallocate | CK4: UpdateGeneralRulePref | CL4: CloseOrder | CM4: CheckUnallocatedGroups | CN4: EditAllocatedGroupSidePanel | CO4: DeleteFixedPreference | CP4: ExportCalculatedPreference
A5: =IFERROR(__xludf.DUMMYFUNCTION("TRANSPOSE(IMPORTRANGE(VLOOKUP($E$3,IMPORTRANGE('_Settings'!$B$3,$C$3&""!A4:B1000""),2,FALSE),$G$3&""!A4:A1000""))"),"") | B5: PreferenceType | C5: PreferenceName | D5: PTTPrefNeeded | E5: IsForceAllocation | F5: AllocationMethod | G5: RemainderAllocationTo | H5: Target%AsOf | I5: AccountsForProrata | J5: DateUptoDays | K5: MatchClosingTransactions
B6: Calculated | D6: TRUE | H6: Pro-rata (NAV) | I6: Allocation1,Allocation2,Allocation3 | K6: FALSE

Sheet CheckAllocatedGroups
B1: Data
J2: =VLOOKUP($E$3,_MasterData!B4:D1000,3,FALSE) -> #N/A
B3: Module | C3: Allocation | D3: Step | E3: CheckAllocatedGroups | F3: Data Format | G3: Input Format
B4: =IFERROR(__xludf.DUMMYFUNCTION("IF(C3="""","""",Transpose(IMPORTRANGE('_Settings'!$B$3,C3&""!A4:A1000"")))"),"Allocate") -> Allocate | C4: Reallocate | D4: CleanUp | E4: SaveCalculatedPreferences | F4: CloseCalculatedPreferences | G4: CloseAllocation | H4: SaveCloseMFPreference | I4: ModifyMFPrefGeneralRuleValues | J4: ClearPrefetchFilters | K4: ExpandCollapseAllUnallocated | L4: ExpandCollapseAllAllocated | M4: SaveAllocation | N4: CheckAllocatedGroups | O4: GetDataAllocation | P4: SelectAllocatedGroup | Q4: EditTradesAllocated | R4: EditTradesUnallocated | S4: EditUnallocatedGroupSidePanel | T4: TradeAttributeBulkChange | U4: ApplyBulkUpdateOnGroups | V4: ApplyPrefetchFilters | W4: GeneralPreferencesDefaultRule | X4: GeneralPrefCompanyUserWise | Y4: RenameTradeAttributes | Z4: SetGroupingRules | AA4: SetMasterFundRatio | AB4: CheckFixedPreference | AC4: GetFixedPreference | AD4: BulkChangeCalculatedPreferences | AE4: AddCalculatedPreferences | AF4: DeleteCalculatedPreferences | AG4: RenameCalculatedPreferences | AH4: CopyCalculatedPreferences | AI4: RunAutoGroup | AJ4: BookOrUpdateSwap | AK4: RunProrata | AL4: SetDefaultRuleCalculatedPref | AM4: SetAccountValueCalculatedPref | AN4: TradeAttributeBulkChangeGroups | AO4: TradeAttributeBulkChangeTaxlots | AP4: AddCalculatedPreferenceToolbar | AQ4: SetStrategyValueCalculatedPref | AR4: ApplyBulkUpdateOnTaxlots | AS4: CommissionBulkChangeOnGroups | AT4: CommissionBulkChangeOnTaxlots | AU4: SelectUnallocatedGroup | AV4: EnterAccountValuesToAllocate | AW4: EnterAllocatePreference | AX4: UnallocateWithOutSave | AY4: GenerateCashTransaction | AZ4: EnterStrategyValuesToAllocate | BA4: CopyCalculatedPreferenceToolbar | BB4: SetGeneralRuleCalculatedPref | BC4: ExportAllCalculatedPreferences | BD4: SetMFPrefFundDefaultRule | BE4: SetMFPreferencesDefaultRule | BF4: SetMFPrefFundDistribution | BG4: SetMFPrefGeneralRule | BH4: SetMFPrefStrategyValues | BI4: SetMFPrefAccountValues | BJ4: RenameMFPreferences | BK4: ExportCalculatedPreference | BL4: DeleteMFPreferenceToolbar | BM4: DeleteMFPreferences | BN4: AddMFPreferenceToolbar | BO4: AddMFPreferences | BP4: ModifyGRPreferenceValues | BQ4: ImportCalculatedPreferences | BR4: OpenAuditTrailUnallocatedGroup | BS4: DeleteCalculatedPreferencesTool | BT4: ImportCalculatedPreferencesTool | BU4: ExportAllCalculatedPreferTool | BV4: OpenAuditTrailAllocatedGroup | BW4: OpenSymbolLookupUnallocateGroup | BX4: OpenSymbolLookupAllocatedGroup | BY4: DeleteFixedPreference | BZ4: UpdateGRDefaultRule | CA4: UpdateGeneralRulePref | CB4: EditAllocatedGroupSidePanel | CC4: UpdateGRStrategyValue | CD4: UpdateGRAccountValue | CE4: CheckUnallocatedGroups | CF4: SetGeneralPreferences | CG4: UngroupTrades | CH4: GroupTrades | CI4: DeleteGroup | CJ4: Unallocate | CK4: UpdateGeneralRulePref | CL4: CloseOrder | CM4: CheckUnallocatedGroups | CN4: EditAllocatedGroupSidePanel | CO4: DeleteFixedPreference | CP4: ExportCalculatedPreference
A5: =IFERROR(__xludf.DUMMYFUNCTION("TRANSPOSE(IMPORTRANGE(VLOOKUP($E$3,IMPORTRANGE('_Settings'!$B$3,$C$3&""!A4:B1000""),2,FALSE),$G$3&""!A4:A1000""))"),"") | B5: Account Name | C5: Accrual Basis | D5: Accrued Interest | E5: Allocated Qty | F5: Allocation Scheme Name | G5: Asset Category | H5: AUEC Fee1 | I5: AUEC Fee2 | J5: AUECID | K5: Avg Price(Base) | L5: Avg Price(Local) | M5: Bloomberg | N5: Bond Type | O5: Broker | P5: Change Comment | Q5: Change Type | R5: Clearing Broker Fee | S5: Closing Status | T5: Commission | U5: Commission Per Share | V5: Company | W5: Contract Multiplier | X5: Coupon Rate | Y5: Cum Qty For Sub Order | Z5: Currency | AA5: Cusip Symbol | AB5: Delta | AC5: Description | AD5: Exchange | AE5: Executed Qty | AF5: Exceution Time | AG5: Expiration Date | AH5: FX Conversion Operator | AI5: FX Rate | AJ5: Group Status | AK5: IDCOSymbol | AL5: Import File Name | AM5: Internal Comments | AN5: IsAnotherTaxlotAttributesUpdated | AO5: ISIN | AP5: IsManualGroup | AQ5: ISNDF | AR5: IsPreAllocated | AS5: M2MProfitLoss | AT5: Net Amount( Base) | AU5: Net Amount( Local) | AV5: Nirvana Process Date | AW5: OCC Fee | AX5: Option Premium Adjustment | AY5: Order Type | AZ5: ORF Fee | BA5: Original Purchase Date | BB5: OSISSymbol | BC5: Other Broker Fees | BD5: Prana Msg Type | BE5: Principal Amount( Base) | BF5: Principal Amount( Local) | BG5: Process Date | BH5: Proxy Symbol | BI5: Put Or Call | BJ5: Quantity | BK5: SEC Fee | BL5: Sedol Symbol | BM5: Settlement Currency | BN5: Settlement Date | BO5: Side | BP5: Soft Commission | BQ5: Soft Commission Per Share | BR5: Stamp Duty | BS5: Strategy Name | BT5: Symbol | BU5: Tax On Commissions | BV5: Total Commission | BW5: Total Commission And Fee | BX5: Total Commission Per Share | BY5: Trade Attribute 1 | BZ5: Trade Attribute 2 | CA5: Trade Attribute 3 | CB5: Trade Attribute 4 | CC5: Trade Attribute 5 | CD5: Trade Attribute 6 | CE5: Trade Date | CF5: Trading Account | CG5: Transaction Levy | CH5: Transaction Source | CI5: Transaction Type | CJ5: UnAllocatedQty | CK5: Underlying | CL5: Underlying Delta | CM5: Underlying Symbol | CN5: User | CO5: Venue | CP5: Closing Method | CQ5: Closing Date | CR5: GroupID
K6: 1 | L6: 1 | BJ6: 100 | BO6: Buy | BT6: MSFT
K7: 1 | L7: 1 | BJ7: 500 | BO7: Buy | BT7: HITT
K8: 1 | L8: 1 | BJ8: 100 | BO8: Sell short | BT8: TESS

Sheet CheckUnallocatedGroups
B1: Data
J2: =VLOOKUP($E$3,_MasterData!B4:D1000,3,FALSE) -> #N/A
B3: Module | C3: Allocation | D3: Step | E3: CheckUnallocatedGroups | F3: Data Format | G3: Input Format
B4: =IFERROR(__xludf.DUMMYFUNCTION("IF(C3="""","""",Transpose(IMPORTRANGE('_Settings'!$B$3,C3&""!A4:A1000"")))"),"Allocate") -> Allocate | C4: Reallocate | D4: CleanUp | E4: SaveCalculatedPreferences | F4: CloseCalculatedPreferences | G4: CloseAllocation | H4: SaveCloseMFPreference | I4: ModifyMFPrefGeneralRuleValues | J4: ClearPrefetchFilters | K4: ExpandCollapseAllUnallocated | L4: ExpandCollapseAllAllocated | M4: SaveAllocation | N4: CheckAllocatedGroups | O4: GetDataAllocation | P4: SelectAllocatedGroup | Q4: EditTradesAllocated | R4: EditTradesUnallocated | S4: EditUnallocatedGroupSidePanel | T4: TradeAttributeBulkChange | U4: ApplyBulkUpdateOnGroups | V4: ApplyPrefetchFilters | W4: GeneralPreferencesDefaultRule | X4: GeneralPrefCompanyUserWise | Y4: RenameTradeAttributes | Z4: SetGroupingRules | AA4: SetMasterFundRatio | AB4: CheckFixedPreference | AC4: GetFixedPreference | AD4: BulkChangeCalculatedPreferences | AE4: AddCalculatedPreferences | AF4: DeleteCalculatedPreferences | AG4: RenameCalculatedPreferences | AH4: CopyCalculatedPreferences | AI4: RunAutoGroup | AJ4: BookOrUpdateSwap | AK4: RunProrata | AL4: SetDefaultRuleCalculatedPref | AM4: SetAccountValueCalculatedPref | AN4: TradeAttributeBulkChangeGroups | AO4: TradeAttributeBulkChangeTaxlots | AP4: AddCalculatedPreferenceToolbar | AQ4: SetStrategyValueCalculatedPref | AR4: ApplyBulkUpdateOnTaxlots | AS4: CommissionBulkChangeOnGroups | AT4: CommissionBulkChangeOnTaxlots | AU4: SelectUnallocatedGroup | AV4: EnterAccountValuesToAllocate | AW4: EnterAllocatePreference | AX4: UnallocateWithOutSave | AY4: GenerateCashTransaction | AZ4: EnterStrategyValuesToAllocate | BA4: CopyCalculatedPreferenceToolbar | BB4: SetGeneralRuleCalculatedPref | BC4: ExportAllCalculatedPreferences | BD4: SetMFPrefFundDefaultRule | BE4: SetMFPreferencesDefaultRule | BF4: SetMFPrefFundDistribution | BG4: SetMFPrefGeneralRule | BH4: SetMFPrefStrategyValues | BI4: SetMFPrefAccountValues | BJ4: RenameMFPreferences | BK4: ExportCalculatedPreference | BL4: DeleteMFPreferenceToolbar | BM4: DeleteMFPreferences | BN4: AddMFPreferenceToolbar | BO4: AddMFPreferences | BP4: ModifyGRPreferenceValues | BQ4: ImportCalculatedPreferences | BR4: OpenAuditTrailUnallocatedGroup | BS4: DeleteCalculatedPreferencesTool | BT4: ImportCalculatedPreferencesTool | BU4: ExportAllCalculatedPreferTool | BV4: OpenAuditTrailAllocatedGroup | BW4: OpenSymbolLookupUnallocateGroup | BX4: OpenSymbolLookupAllocatedGroup | BY4: DeleteFixedPreference | BZ4: UpdateGRDefaultRule | CA4: UpdateGeneralRulePref | CB4: EditAllocatedGroupSidePanel | CC4: UpdateGRStrategyValue | CD4: UpdateGRAccountValue | CE4: CheckUnallocatedGroups | CF4: SetGeneralPreferences | CG4: UngroupTrades | CH4: GroupTrades | CI4: DeleteGroup | CJ4: Unallocate | CK4: UpdateGeneralRulePref | CL4: CloseOrder | CM4: CheckUnallocatedGroups | CN4: EditAllocatedGroupSidePanel | CO4: DeleteFixedPreference | CP4: ExportCalculatedPreference
A5: =IFERROR(__xludf.DUMMYFUNCTION("TRANSPOSE(IMPORTRANGE(VLOOKUP($E$3,IMPORTRANGE('_Settings'!$B$3,$C$3&""!A4:B1000""),2,FALSE),$G$3&""!A4:A1000""))"),"") | B5: Accrual Basis | C5: Accrued Interest | D5: Allocated Qty | E5: Allocation Scheme Name | F5: Asset Category | G5: AUEC Fee1 | H5: AUEC Fee2 | I5: AUECID | J5: Avg Price(Base) | K5: Avg Price(Local) | L5: Bloomberg | M5: Bond Type | N5: Broker | O5: Change Comment | P5: Change Type | Q5: Clearing Broker Fee | R5: Closing Method | S5: Closing Status | T5: Commission | U5: Commission Per Share | V5: Company | W5: Contract Multiplier | X5: Coupon Rate | Y5: Cum Qty For Sub Order | Z5: Currency | AA5: Cusip Symbol | AB5: Delta | AC5: Description | AD5: Exchange | AE5: Executed Qty | AF5: Execution Time | AG5: FX Conversion Operator | AH5: FX Rate | AI5: Group Status | AJ5: GroupID | AK5: IDCOSymbol | AL5: Import File Name | AM5: Internal Comments | AN5: IsAnotherTaxlotAttributesUpdated | AO5: ISIN | AP5: IsManual Group | AQ5: ISNDF | AR5: IsPreAllocated | AS5: M2MProfitLoss | AT5: Net Amount( Base) | AU5: Net Amount( Local) | AV5: Nirvana Process Date | AW5: OCC Fee | AX5: Option Premium Adjustment | AY5: Order Type | AZ5: ORF Fee | BA5: Original Purchase Date | BB5: OSISSymbol | BC5: Other Broker Fees | BD5: Prana Msg Type | BE5: Principal Amount( Base) | BF5: Principal Amount( Local) | BG5: Process Date | BH5: Proxy Symbol | BI5: Put Or Call | BJ5: Quantity | BK5: SEC Fee | BL5: Sedol Symbol | BM5: Settlement Currency | BN5: Settlement Date | BO5: Side | BP5: Soft Commission | BQ5: Soft Commission Per Share | BR5: Stamp Duty | BS5: Symbol | BT5: Tax On Commissions | BU5: Total Commission | BV5: Total Commission And Fee | BW5: Total Commission Per Share | BX5: Trade Attribute 1 | BY5: Trade Attribute 2 | BZ5: Trade Attribute 3 | CA5: Trade Attribute 4 | CB5: Trade Attribute 5 | CC5: Trade Attribute 6 | CD5: Trade Date | CE5: Trading Account | CF5: Transaction Levy | CG5: Transaction Source | CH5: Transaction Type | CI5: UnAllocatedQty | CJ5: Underlying | CK5: Underlying Delta | CL5: Underlying Symbol | CM5: User | CN5: Venue | CO5: Closing Date | CP5: Expiration Date
J6: 1 | K6: 1 | AE6: 600 | BJ6: 600 | BO6: Sell | BS6: AAPL
J7: 1 | K7: 1 | AE7: 400 | BJ7: 400 | BO7: Sell | BS7: INFY

Sheet GetDataAllocation
B1: Data
J2: =VLOOKUP($E$3,_MasterData!B4:D1000,3,FALSE) -> #N/A
B3: Module | C3: Allocation | D3: Step | E3: GetDataAllocation | F3: Data Format | G3: Input Format
B4: =IFERROR(__xludf.DUMMYFUNCTION("IF(C3="""","""",Transpose(IMPORTRANGE('_Settings'!$B$3,C3&""!A4:A1000"")))"),"Allocate") -> Allocate | C4: Reallocate | D4: CleanUp | E4: SaveCalculatedPreferences | F4: CloseCalculatedPreferences | G4: CloseAllocation | H4: SaveCloseMFPreference | I4: ModifyMFPrefGeneralRuleValues | J4: ClearPrefetchFilters | K4: ExpandCollapseAllUnallocated | L4: ExpandCollapseAllAllocated | M4: SaveAllocation | N4: CheckAllocatedGroups | O4: GetDataAllocation | P4: SelectAllocatedGroup | Q4: EditTradesAllocated | R4: EditTradesUnallocated | S4: EditUnallocatedGroupSidePanel | T4: TradeAttributeBulkChange | U4: ApplyBulkUpdateOnGroups | V4: ApplyPrefetchFilters | W4: GeneralPreferencesDefaultRule | X4: GeneralPrefCompanyUserWise | Y4: RenameTradeAttributes | Z4: SetGroupingRules | AA4: SetMasterFundRatio | AB4: CheckFixedPreference | AC4: GetFixedPreference | AD4: BulkChangeCalculatedPreferences | AE4: AddCalculatedPreferences | AF4: DeleteCalculatedPreferences | AG4: RenameCalculatedPreferences | AH4: CopyCalculatedPreferences | AI4: RunAutoGroup | AJ4: BookOrUpdateSwap | AK4: RunProrata | AL4: SetDefaultRuleCalculatedPref | AM4: SetAccountValueCalculatedPref | AN4: TradeAttributeBulkChangeGroups | AO4: TradeAttributeBulkChangeTaxlots | AP4: AddCalculatedPreferenceToolbar | AQ4: SetStrategyValueCalculatedPref | AR4: ApplyBulkUpdateOnTaxlots | AS4: CommissionBulkChangeOnGroups | AT4: CommissionBulkChangeOnTaxlots | AU4: SelectUnallocatedGroup | AV4: EnterAccountValuesToAllocate | AW4: EnterAllocatePreference | AX4: UnallocateWithOutSave | AY4: GenerateCashTransaction | AZ4: EnterStrategyValuesToAllocate | BA4: CopyCalculatedPreferenceToolbar | BB4: SetGeneralRuleCalculatedPref | BC4: ExportAllCalculatedPreferences | BD4: SetMFPrefFundDefaultRule | BE4: SetMFPreferencesDefaultRule | BF4: SetMFPrefFundDistribution | BG4: SetMFPrefGeneralRule | BH4: SetMFPrefStrategyValues | BI4: SetMFPrefAccountValues | BJ4: RenameMFPreferences | BK4: ExportCalculatedPreference | BL4: DeleteMFPreferenceToolbar | BM4: DeleteMFPreferences | BN4: AddMFPreferenceToolbar | BO4: AddMFPreferences | BP4: ModifyGRPreferenceValues | BQ4: ImportCalculatedPreferences | BR4: OpenAuditTrailUnallocatedGroup | BS4: DeleteCalculatedPreferencesTool | BT4: ImportCalculatedPreferencesTool | BU4: ExportAllCalculatedPreferTool | BV4: OpenAuditTrailAllocatedGroup | BW4: OpenSymbolLookupUnallocateGroup | BX4: OpenSymbolLookupAllocatedGroup | BY4: DeleteFixedPreference | BZ4: UpdateGRDefaultRule | CA4: UpdateGeneralRulePref | CB4: EditAllocatedGroupSidePanel | CC4: UpdateGRStrategyValue | CD4: UpdateGRAccountValue | CE4: CheckUnallocatedGroups | CF4: SetGeneralPreferences | CG4: UngroupTrades | CH4: GroupTrades | CI4: DeleteGroup | CJ4: Unallocate | CK4: UpdateGeneralRulePref | CL4: CloseOrder | CM4: CheckUnallocatedGroups | CN4: EditAllocatedGroupSidePanel | CO4: DeleteFixedPreference | CP4: ExportCalculatedPreference
A5: =IFERROR(__xludf.DUMMYFUNCTION("TRANSPOSE(IMPORTRANGE(VLOOKUP($E$3,IMPORTRANGE('_Settings'!$B$3,$C$3&""!A4:B1000""),2,FALSE),$G$3&""!A4:A1000""))"),"") | B5: RangeType | C5: From | D5: To | E5: FilterTabName | F5: Symbol | G5: Asset | H5: Side | I5: Account | J5: Broker | K5: Currency | L5: Exchange | M5: StrategyName | N5: Underlying | O5: Venue | P5: TradingAccount | Q5: PreAllocated | R5: ManualGroup
B6: Current

Sheet GetDataClosing
B1: Data
J2: =VLOOKUP($E$3,_MasterData!B4:D1000,3,FALSE) -> #N/A
B3: Module | C3: Closing | D3: Step | E3: GetDataClosing | F3: Data Format | G3: Input Format
B4: =IFERROR(__xludf.DUMMYFUNCTION("IF(C3="""","""",Transpose(IMPORTRANGE('_Settings'!$B$3,C3&""!A4:A1000"")))"),"GetDataClosing") -> GetDataClosing | C4: ManualClosing | D4: UnwindClosing | E4: VerifyClosedTrades | F4: VerifyLongPositionsGrid | G4: VerifyShortPositionsGrid | H4: SelectTradeUnexpiredUnsettled | I4: CashSettlementAtCost | J4: CashSettlementAtZeroPrice | K4: CashSettlementAtClosingDtSpotPx | L4: PhysicalSettlement | M4: AutomaticClosing | N4: Expire | O4: ExerciseAssignment | P4: ExerciseAssignmentAtZero | Q4: SwapExpireAndRollover | R4: SwapExpire | S4: VerifyExpiredSettledGrid | T4: VerifyUnExpiredUnSettledGrid | U4: UnWindTradeSettlement | V4: CloseOrder | W4: VerifyCloseOrder | X4: UnWindCloseOrder | Y4: ClosingCleanUp | Z4: CloseClosingUI
A5: =IFERROR(__xludf.DUMMYFUNCTION("TRANSPOSE(IMPORTRANGE(VLOOKUP($E$3,IMPORTRANGE('_Settings'!$B$3,$C$3&""!A4:B1000""),2,FALSE),$G$3&""!A4:A1000""))"),"") | B5: RangeType | C5: From | D5: To | E5: Account Filter
B6: Current

Sheet VerifyLongPositionsGrid
B1: Data
J2: =VLOOKUP($E$3,_MasterData!B4:D1000,3,FALSE) -> #N/A
B3: Module | C3: Closing | D3: Step | E3: VerifyLongPositionsGrid | F3: Data Format | G3: Input Format
B4: =IFERROR(__xludf.DUMMYFUNCTION("IF(C3="""","""",Transpose(IMPORTRANGE('_Settings'!$B$3,C3&""!A4:A1000"")))"),"GetDataClosing") -> GetDataClosing | C4: ManualClosing | D4: UnwindClosing | E4: VerifyClosedTrades | F4: VerifyLongPositionsGrid | G4: VerifyShortPositionsGrid | H4: SelectTradeUnexpiredUnsettled | I4: CashSettlementAtCost | J4: CashSettlementAtZeroPrice | K4: CashSettlementAtClosingDtSpotPx | L4: PhysicalSettlement | M4: AutomaticClosing | N4: Expire | O4: ExerciseAssignment | P4: ExerciseAssignmentAtZero | Q4: SwapExpireAndRollover | R4: SwapExpire | S4: VerifyExpiredSettledGrid | T4: VerifyUnExpiredUnSettledGrid | U4: UnWindTradeSettlement | V4: CloseOrder | W4: VerifyCloseOrder | X4: UnWindCloseOrder | Y4: ClosingCleanUp | Z4: CloseClosingUI
A5: =IFERROR(__xludf.DUMMYFUNCTION("TRANSPOSE(IMPORTRANGE(VLOOKUP($E$3,IMPORTRANGE('_Settings'!$B$3,$C$3&""!A4:B1000""),2,FALSE),$G$3&""!A4:A1000""))"),"") | B5: Account | C5: Asset Class | D5: AUECID | E5: ExternalTransId | F5: IsSwapped | G5: LotId | H5: Net Notional | I5: Opening Price | J5: Original Purchase Date | K5: PositionTag | L5: Process Date | M5: Quantity | N5: Security Name | O5: Settlement Currency | P5: Side | Q5: Strategy | R5: Symbol | S5: Taxlot ID | T5: Total Fees and Commission | U5: Trade Date | V5: Transaction Type | W5: UnderlyingName | X5: UnitCost | Y5: Unit Cost(Base) | Z5: AvgPriceBase
B6: Allocation1 | M6: 59 | P6: Buy | R6: MSFT
B7: Allocation2 | M7: 12 | P7: Buy | R7: MSFT
B8: Allocation3 | M8: 29 | P8: Buy | R8: MSFT
B9: Allocation1 | P9: Buy | R9: HITT
B10: Allocation2 | P10: Buy | R10: HITT
B11: Allocation3 | P11: Buy | R11: HITT

Sheet VerifyShortPositionsGrid
B1: Data
J2: =VLOOKUP($E$3,_MasterData!B4:D1000,3,FALSE) -> #N/A
B3: Module | C3: Closing | D3: Step | E3: VerifyShortPositionsGrid | F3: Data Format | G3: Input Format
B4: =IFERROR(__xludf.DUMMYFUNCTION("IF(C3="""","""",Transpose(IMPORTRANGE('_Settings'!$B$3,C3&""!A4:A1000"")))"),"GetDataClosing") -> GetDataClosing | C4: ManualClosing | D4: UnwindClosing | E4: VerifyClosedTrades | F4: VerifyLongPositionsGrid | G4: VerifyShortPositionsGrid | H4: SelectTradeUnexpiredUnsettled | I4: CashSettlementAtCost | J4: CashSettlementAtZeroPrice | K4: CashSettlementAtClosingDtSpotPx | L4: PhysicalSettlement | M4: AutomaticClosing | N4: Expire | O4: ExerciseAssignment | P4: ExerciseAssignmentAtZero | Q4: SwapExpireAndRollover | R4: SwapExpire | S4: VerifyExpiredSettledGrid | T4: VerifyUnExpiredUnSettledGrid | U4: UnWindTradeSettlement | V4: CloseOrder | W4: VerifyCloseOrder | X4: UnWindCloseOrder | Y4: ClosingCleanUp | Z4: CloseClosingUI
A5: =IFERROR(__xludf.DUMMYFUNCTION("TRANSPOSE(IMPORTRANGE(VLOOKUP($E$3,IMPORTRANGE('_Settings'!$B$3,$C$3&""!A4:B1000""),2,FALSE),$G$3&""!A4:A1000""))"),"") | B5: Account | C5: Asset Class | D5: AUECID | E5: ExternalTransId | F5: IsSwapped | G5: LotId | H5: Net Notional | I5: Opening Price | J5: Original Purchase Date | K5: PositionTag | L5: Process Date | M5: Quantity | N5: Security Name | O5: Settlement Currency | P5: Side | Q5: Strategy | R5: Symbol | S5: Taxlot ID | T5: Total Fees and Commission | U5: Trade Date | V5: Transaction Type | W5: UnderlyingName | X5: UnitCost | Y5: Unit Cost(Base) | Z5: AvgPriceBase
B6: Allocation1 | M6: 59 | P6: Sell short | R6: TESS
B7: Allocation2 | M7: 12 | P7: Sell short | R7: TESS
B8: Allocation3 | M8: 29 | P8: Sell short | R8: TESS

Sheet GetActivityData
B1: Data
J2: =VLOOKUP($E$3,_MasterData!B4:D1000,3,FALSE) -> #N/A
B3: Module | C3: GeneralLedger | D3: Step | E3: GetActivityData | F3: Data Format | G3: Input Format
B4: =IFERROR(__xludf.DUMMYFUNCTION("IF(C3="""","""",Transpose(IMPORTRANGE('_Settings'!$B$3,C3&""!A4:A1000"")))"),"CloseGeneralLedger") -> CloseGeneralLedger | C4: GetDataCash | D4: EnterCashDividends | E4: EnterNonTradingTransaction | F4: VerifyCash | G4: VerifyActivity | H4: VerifyTradingTransaction | I4: VerifyRevaluationData | J4: GetTradingTransaction | K4: GetActivityData | L4: GetTradingTransaction | M4: GetActivityData | N4: GetRevaluationData | O4: GetAccountDetails | P4: GetNonTradingTransaction | Q4: GetDividendData | R4: VerifyNonTradingTransaction | S4: VerifyDividend | T4: GetOpeningBalanceData | U4: GetAccountBalance | V4: SelectNonTradingTransaction | W4: SelectNonTradingTranItem | X4: DeleteNonTradingTransaction | Y4: DeleteNonTradingTranItem | Z4: AddNonTradingTransaction | AA4: AddNonTradingTranItem | AB4: VerifyOpeningBalanceData | AC4: SelectOpeningBalanceTransaction | AD4: SelectOpeningBalanceTranItem | AE4: EditNonTradingTransaction | AF4: EditNonTradingTranItem | AG4: DeleteOpeningBalanceTransaction | AH4: DeleteOpeningBalanceTranItem | AI4: GetDayEndCash | AJ4: RunRevaluation | AK4: CalculateDayEndCash | AL4: VerifyDayEndCash | AM4: GetCashTransaction | AN4: SelectCashTransaction | AO4: EditCashTransaction | AP4: DeleteCashTransaction | AQ4: AddCashTransaction | AR4: AddOpeningBalanceTransaction | AS4: AddOpeningBalanceTranItem | AT4: VerifyAccountDetails | AU4: GetDailyCalculationsData | AV4: CalculateDailyCalculations | AW4: CloseGeneralLedger | AX4: EditOpeningBalanceTransaction | AY4: EditOpeningBalanceTranItem | AZ4: VerifyDailyCalTransactions | CE4: VerifyDividend | CF4: GetOpeningBalanceData | CG4: GetAccountBalance | CH4: SelectNonTradingTransaction | CI4: SelectNonTradingTranItem | CJ4: DeleteNonTradingTransaction | CK4: DeleteNonTradingTranItem | CL4: AddNonTradingTransaction | CM4: AddNonTradingTranItem | CN4: VerifyOpeningBalanceData | CO4: SelectOpeningBalanceTransaction | CP4: SelectOpeningBalanceTranItem | CQ4: EditNonTradingTransaction | CR4: EditNonTradingTranItem | CS4: DeleteOpeningBalanceTransaction | CT4: DeleteOpeningBalanceTranItem | CU4: GetDayEndCash | CV4: RunRevaluation | CW4: CalculateDayEndCash | CX4: VerifyDayEndCash | CY4: GetCashTransaction | CZ4: SelectCashTransaction | DA4: EditCashTransaction | DB4: DeleteCashTransaction | DC4: AddCashTransaction | DD4: AddOpeningBalanceTransaction | DE4: AddOpeningBalanceTranItem | DF4: VerifyAccountDetails | DG4: GetDailyCalculationsData | DH4: CalculateDailyCalculations | DI4: CloseGeneralLedger | DJ4: EditOpeningBalanceTransaction | DK4: EditOpeningBalanceTranItem | DL4: VerifyDailyCalTransactions
A5: =IFERROR(__xludf.DUMMYFUNCTION("TRANSPOSE(IMPORTRANGE(VLOOKUP($E$3,IMPORTRANGE('_Settings'!$B$3,$C$3&""!A4:B1000""),2,FALSE),$G$3&""!A4:A1000""))"),"") | B5: MasterFund | C5: Accounts | D5: From | E5: To | F5: SettlementDate | G5: TradeDate | H5: All
B6: SelectAll | C6: Allocation1,Allocation2,Allocation3,OFFSHORE | D6: =TODAY() -> 43642 | E6: =TODAY() -> 43642 | F6: No | G6: Yes | H6: No

Sheet VerifyActivity
B1: Data
J2: =VLOOKUP($E$3,_MasterData!B4:D1000,3,FALSE) -> #N/A
B3: Module | C3: GeneralLedger | D3: Step | E3: VerifyActivity | F3: Data Format | G3: Input Format
B4: =IFERROR(__xludf.DUMMYFUNCTION("IF(C3="""","""",Transpose(IMPORTRANGE('_Settings'!$B$3,C3&""!A4:A1000"")))"),"CloseGeneralLedger") -> CloseGeneralLedger | C4: GetDataCash | D4: EnterCashDividends | E4: EnterNonTradingTransaction | F4: VerifyCash | G4: VerifyActivity | H4: VerifyTradingTransaction | I4: VerifyRevaluationData | J4: GetTradingTransaction | K4: GetActivityData | L4: GetTradingTransaction | M4: GetActivityData | N4: GetRevaluationData | O4: GetAccountDetails | P4: GetNonTradingTransaction | Q4: GetDividendData | R4: VerifyNonTradingTransaction | S4: VerifyDividend | T4: GetOpeningBalanceData | U4: GetAccountBalance | V4: SelectNonTradingTransaction | W4: SelectNonTradingTranItem | X4: DeleteNonTradingTransaction | Y4: DeleteNonTradingTranItem | Z4: AddNonTradingTransaction | AA4: AddNonTradingTranItem | AB4: VerifyOpeningBalanceData | AC4: SelectOpeningBalanceTransaction | AD4: SelectOpeningBalanceTranItem | AE4: EditNonTradingTransaction | AF4: EditNonTradingTranItem | AG4: DeleteOpeningBalanceTransaction | AH4: DeleteOpeningBalanceTranItem | AI4: GetDayEndCash | AJ4: RunRevaluation | AK4: CalculateDayEndCash | AL4: VerifyDayEndCash | AM4: GetCashTransaction | AN4: SelectCashTransaction | AO4: EditCashTransaction | AP4: DeleteCashTransaction | AQ4: AddCashTransaction | AR4: AddOpeningBalanceTransaction | AS4: AddOpeningBalanceTranItem | AT4: VerifyAccountDetails | AU4: GetDailyCalculationsData | AV4: CalculateDailyCalculations | AW4: CloseGeneralLedger | AX4: EditOpeningBalanceTransaction | AY4: EditOpeningBalanceTranItem | AZ4: VerifyDailyCalTransactions | CE4: VerifyDividend | CF4: GetOpeningBalanceData | CG4: GetAccountBalance | CH4: SelectNonTradingTransaction | CI4: SelectNonTradingTranItem | CJ4: DeleteNonTradingTransaction | CK4: DeleteNonTradingTranItem | CL4: AddNonTradingTransaction | CM4: AddNonTradingTranItem | CN4: VerifyOpeningBalanceData | CO4: SelectOpeningBalanceTransaction | CP4: SelectOpeningBalanceTranItem | CQ4: EditNonTradingTransaction | CR4: EditNonTradingTranItem | CS4: DeleteOpeningBalanceTransaction | CT4: DeleteOpeningBalanceTranItem | CU4: GetDayEndCash | CV4: RunRevaluation | CW4: CalculateDayEndCash | CX4: VerifyDayEndCash | CY4: GetCashTransaction | CZ4: SelectCashTransaction | DA4: EditCashTransaction | DB4: DeleteCashTransaction | DC4: AddCashTransaction | DD4: AddOpeningBalanceTransaction | DE4: AddOpeningBalanceTranItem | DF4: VerifyAccountDetails | DG4: GetDailyCalculationsData | DH4: CalculateDailyCalculations | DI4: CloseGeneralLedger | DJ4: EditOpeningBalanceTransaction | DK4: EditOpeningBalanceTranItem | DL4: VerifyDailyCalTransactions
A5: =IFERROR(__xludf.DUMMYFUNCTION("TRANSPOSE(IMPORTRANGE(VLOOKUP($E$3,IMPORTRANGE('_Settings'!$B$3,$C$3&""!A4:B1000""),2,FALSE),$G$3&""!A4:A1000""))"),"") | B5: Account | C5: Activity Source | D5: ActivityType | E5: Net Amount(Local) | F5: AUEC Fee1 | G5: AUEC Fee2 | H5: Balance Type | I5: Clearing Broker Fees | J5: Commission | K5: Currency | L5: Description | M5: Entry Date | N5: FX Conversion Method Operator | O5: Fx Rate | P5: Lead Currency | Q5: Modify date | R5: OCC Fee | S5: OptionPremiumAdjustment | T5: ORF Fee | U5: Other Broker Fees | V5: Quantity | W5: SEC Fee | X5: Settlement Currency | Y5: Settlement Date | Z5: Soft Commission | AA5: Stamp Duty | AB5: Symbol | AC5: Tax On Commissions | AD5: Total Commissions | AE5: Trade Date | AF5: Transaction Levy | AG5: Transaction Source | AH5: User | AI5: Vs Currency | AJ5: SettlCurrencyID
B6: Allocation1 | D6: EquityL | K6: USD | V6: 59 | AB6: MSFT
B7: Allocation2 | D7: EquityL | K7: USD | V7: 12 | AB7: MSFT
B8: Allocation3 | D8: EquityL | K8: USD | V8: 29 | AB8: MSFT
B9: Allocation1 | D9: EquityL | K9: USD | AB9: HITT
B10: Allocation2 | D10: EquityL | K10: USD | AB10: HITT
B11: Allocation3 | D11: EquityL | K11: USD | AB11: HITT
B12: Allocation1 | D12: EquityS | K12: USD | V12: 59 | AB12: TESS
B13: Allocation2 | D13: EquityS | K13: USD | V13: 12 | AB13: TESS
B14: Allocation3 | D14: EquityS | K14: USD | V14: 29 | AB14: TESS

Sheet CheckPortfolioManagement
B1: Data
J2: =VLOOKUP($E$3,_MasterData!B4:D1000,3,FALSE) -> #N/A
B3: Module | C3: PortfolioManagement | D3: Step | E3: CheckPortfolioManagement | F3: Data Format | G3: Input Format
B4: =IFERROR(__xludf.DUMMYFUNCTION("IF(C3="""","""",Transpose(IMPORTRANGE('_Settings'!$B$3,C3&""!A4:A1000"")))"),"CheckDashboardPM") -> CheckDashboardPM | C4: CheckPortfolioManagement | D4: OpenPSTFromPM | E4: ClosePM | F4: OpenPTTFromPM | G4: FilterPM | H4: GroupRowPM | I4: CheckDashboardWithPM | J4: RemoveFilterPM | K4: CheckSummaryRowsPM
A5: =IFERROR(__xludf.DUMMYFUNCTION("TRANSPOSE(IMPORTRANGE(VLOOKUP($E$3,IMPORTRANGE('_Settings'!$B$3,$C$3&""!A4:B1000""),2,FALSE),$G$3&""!A4:A1000""))"),"") | B5: Trade Date | C5: Symbol | D5: Position | E5: Account | F5: MasterFund | G5: Cost Basis | H5: Position Side | I5: Market Value (Base) | J5: % Day P&L (Gross MV) | K5: Net Exposure (Base) | L5: Beta Adj. Gross Exposure (Base) | M5: Beta Adj. Gross Exposure (Underlying) (Base) | N5: Day P&L (Base) | O5: Security Name | P5: Closing Mark | Q5: Cost Basis P&L (Base) | R5: Prime Broker | S5: Strategy | T5: Asset Class | U5: Underlying | V5: Exchange | W5: Trade Currency | X5: Multiplier | Y5: FX Rate | Z5: Vs Currency | AA5: Lead Currency | AB5: Dividend Yield (%) | AC5: % Change | AD5: Net Exposure (Local) | AE5: Exposure (Local) | AF5: Delta Adj. Position | AG5: Exposure (Base) | AH5: Beta Adj. Exposure (Local) | AI5: Beta Adj. Exposure (Base) | AJ5: Exposure (BP)(Base) | AK5: Day P&L (Local) | AL5: Delta | AM5: Leveraged Factor | AN5: Order Side | AO5: Master Strategy | AP5: Transaction Side | AQ5: Underlying Symbol | AR5: Underlying Price | AS5: Side Multiplier | AT5: Description | AU5: Internal Comments | AV5: FX Rate On Trade Date | AW5: Cost Basis P&L (Local) | AX5: Day Interest | AY5: Total Interest | AZ5: Market Value (Local) | BA5: % Gain/Loss Day | BB5: Update Time (Last Price) | BC5: Beta | BD5: Cash Impact (Local) | BE5: User Asset | BF5: Security Type | BG5: Sector | BH5: Sub Sector | BI5: Country | BJ5: Market Cap | BK5: Shares Outstanding | BL5: Avg Volume 20 Day | BM5: % Avg Volume (Delta Adj.) | BN5: Ex Dividend Date | BO5: Cash Impact (Base) | BP5: Volatility (%) | BQ5: User | BR5: Broker | BS5: Earned Dividend (Local) | BT5: Earned Dividend (Base) | BU5: Put/Call | BV5: Expiration Date | BW5: Strike Price | BX5: Gross Exposure (Base) | BY5: Gross Market Value (Base) | BZ5: Px Selected Feed (Local) | CA5: Px Selected Feed (Base) | CB5: Settlement Date | CC5: % Avg Volume | CD5: Day P&L (Base)(Price Gain) | CE5: Day P&L (Base)(FX Gain) | CF5: Cost Basis P&L (Base)(FX Gain) | CG5: Cost Basis P&L (Base)(Price Gain) | CH5: % Gain/Loss Cost | CI5: Underlying Value (Options) | CJ5: Avg Volume 20 Day (Underlying Symbol) | CK5: IsStaleData | CL5: IDCO | CM5: OSI | CN5: SEDOL | CO5: CUSIP | CP5: Bloomberg | CQ5: ISIN | CR5: Start Trade Date | CS5: Cost Basis (Break Even) | CT5: % Day Return (Gross MV) | CU5: Trade Attribute 3 | CV5: Trade Attribute 4 | CW5: Trade Attribute 5 | CX5: Trade Attribute 6 | CY5: Proxy Symbol | CZ5: Pricing Source | DA5: Delta Source | DB5: Gross Exposure (Local) | DC5: % Day P&L (Net MV) | DD5: Expiration Month | DE5: Delta Adj. Position (LME) | DF5: Premium | DG5: Premium $ | DH5: Forward Points | DI5: Closing Mark (Underlying) | DJ5: % Change (Underlying Price) | DK5: Transaction Type | DL5: Closing Market Value (Local) | DM5: Closing Market Value (Base) | DN5: Closing FX Rate | DO5: Change In Underlying Price | DP5: RIC | DQ5: Position Side Exposure (Boxed) | DR5: Analyst | DS5: Country Of Risk | DT5: Custom UDA1 | DU5: Custom UDA2 | DV5: Custom UDA3 | DW5: Custom UDA4 | DX5: Custom UDA5 | DY5: Custom UDA6 | DZ5: Custom UDA7 | EA5: Issuer | EB5: Liquid Tag | EC5: Market Cap UDA | ED5: Region | EE5: Risk Currency | EF5: UCITS Eligible Tag | EG5: FX Rate (Display) | EH5: % Net Exposure (Base) | EI5: % Gross Exposure (Base) | EJ5: % Exposure (Base) | EK5: % Gross Exposure (Underlying) (Base) | EL5: % Beta Adj. Gross Exposure (Base) | EM5: Position Side Exposure (Underlying) | EN5: Gross Exposure (Underlying) (Base) | EO5: Gross Exposure (Underlying) | EP5: Day Return | EQ5: Start of Day NAV | ER5: % Gross Market Value (Base) | ES5: Beta Adj. Gross Exposure (Underlying) (Local) | ET5: NAV | EU5: % P&L Contribution | EV5: % Net Market Value (Base) | EW5: Position Side Exposure | EX5: NAV (Touch) | EY5: IgnorePropertyChangeEvents | EZ5: Trade Attribute 1 | FA5: Trade Attribute 2
C6: MSFT | D6: 59 | E6: Allocation1 | AN6: Buy
C7: MSFT | D7: 12 | E7: Allocation2 | AN7: Buy
C8: MSFT | D8: 29 | E8: Allocation3 | AN8: Buy
C9: HITT | AN9: Buy
C10: HITT | AN10: Buy
C11: HITT | AN11: Buy
C12: TESS | D12: -59 | E12: Allocation1 | AN12: Sell short
C13: TESS | D13: -12 | E13: Allocation2 | AN13: Sell short
C14: TESS | D14: -29 | E14: Allocation3 | AN14: Sell short
C15: INFY | D15: -400 | AN15: Sell
C16: AAPL | D16: -600 | AN16: Sell
