Workbook

Sheet _Modules
A1: Modules Info
A3: Modules
A4: =IFERROR(__xludf.DUMMYFUNCTION("IMPORTRANGE('_Settings'!B3,""Modules!A4:L1000"")"),"Allocation") -> Allocation | B4: Allocate | C4: undefined
A5: Allocation | B5: CheckAllocatedGroups | C5: 1s6xSSuH2dXhiPG92ak5HNMCcI_5om5xTW9weKdOggF4
A6: Allocation | B6: Unallocate | C6: 1XyIil3zqcvapCkiTWmnbLfcWEXl6C6APSGdFr3NZJG8
A7: Allocation | B7: GetDataAllocation | C7: 1a3Dn4n6eD-X9nnNbnU92sB5jG5LSO7Qo2tpxFa3FQt8
A8: Allocation | B8: SelectAllocatedGroup | C8: 1XyIil3zqcvapCkiTWmnbLfcWEXl6C6APSGdFr3NZJG8
A9: Allocation | B9: EditTradesAllocated | C9: 1pbt55ATYJHDR4SfOXUZo6zw1nd03tFCXi4meQToVOBk
A10: Allocation | B10: EditTradesUnallocated | C10: 1AoXvD1WHILQO_2sX7IbQf5JgEoe6FpY-VpIQA7JK_RM
A11: Allocation | B11: Reallocate | C11: undefined
A12: Blotter | B12: ReplaceFillsOnBlotter | C12: undefined
A13: Blotter | B13: CheckBlotter | C13: 1CLA7rrLA5DYmgmrJpMLY00RZXOdGHHAH4HzdV5sucnQ
A14: GeneralLedger | B14: GetDataCash | C14: 1j7mHywxV-bGmOO0NXRqFuArg1pE3qwseCBFuZmok0dg
A15: GeneralLedger | B15: EnterCashDividends | C15: 1njex5IOqy-lKaVwNV8iaqbo0KCZQr13futyhB4ZWQqw
A16: GeneralLedger | B16: EnterNonTradingTransaction | C16: 16L2ujbIr6SzTq33MV6LrLSIBTCT4Kwi26Dt0Qyfi94I
... A136: Blotter | B136: TransferToUserOrder | C136: 13H5BvVwQ2vDv6reJBp_wdw8QvgvYcTxu7VhQ0_jlbGI
A137: Allocation | B137: CloseCalculatedPreferences
A138: TradingTicket | B138: CreateReplaceOrder | C138: 1HieUFNahA0Ynbr0l-FOo3fJMK3isp-HBt4f6Anm8Rik
A139: Blotter | B139: EditOrder | C139: 1O2rPwFuGUs6amVZ-bTvdZjXwNajT_BBjAETBrVsuSoI
A140: Blotter | B140: SelectTradeSubOrderBlotter | C140: 1cNG6EBUYTksqVpqN9GQmSnfLLRt2DgHBPIHDbDGaxGM
A141: Blotter | B141: VerifyOrder | C141: 10EowMcZ_xiIjuewbkRqoGUgzzFr5BKxuAI3EGQleztQ
A142: Blotter | B142: VerifySubOrder | C142: 1YavVPhJw24wl-vz8Vy93oG8P66xyKNidXcbsIWwSA_A
A143: Blotter | B143: RemoveSelectedOrders | C143: 1oqvBSe9jbvMOaK8Gxlbo_Ylh-2o3AuGaEyaJbr3SctM
A144: Blotter | B144: CancelAllSelectedSubs | C144: 1p6aIVJqJtjjHsyfrcvCLR88GL3DBxP3ZbjRWHoMzMsY
A145: Blotter | B145: MultiTradingTicket | C145: 1b7eh2Ho8oxyrnu1I-wg2vv9ueMmHUKA681AmqLWLVgk
A146: Blotter | B146: AuditTrailOrderBlotter | C146: 1frUGX7ejqKZ-sHZFF4QRCZX3myd-p59Zp_gbJ5OTPHc
A147: Blotter | B147: TradeNewSubOrder | C147: 1wj5FNrpD5l4kHAGG9El_wLyoJM1UlA-tZscPY-51LBE
A148: Blotter | B148: RemoveStageOrder | C148: 1Ep_FswKLx59R3emL8ldne_-4WDhKGm1CEwx8HKs9JQI
A149: TradingTicket | B149: SetGeneralPreference | C149: 1NnZ8i6Ex0qgilG5aupFD5QbPhHOHuht5brqUAb354kk
... A165: GeneralLedger | B165: RunRevaluation | C165: 1vjxnjIOPJvHPR0k7y7PfORLGAPyEf4BojqAg_NpAEts
A166: GeneralLedger | B166: CalculateDayEndCash
A167: Allocation | B167: ExportAllCalculatedPreferTool | C167: 1VKV55LPMWMna6kj0b4fot6gZpSZ0XpkxEFX7x2HRJgQ
A168: Allocation | B168: OpenAuditTrailAllocatedGroup | C168: 1C6yttP5lG5uETgDxqCNAkOohnkZ8vRjVKseGDcd6RFs
A169: Allocation | B169: OpenSymbolLookupUnallocateGroup | C169: 1DwZwgsw7tW2e2lhdRKpSj9zrjTbWw5bY9UgkL2vDhCM
A170: Allocation | B170: OpenSymbolLookupAllocatedGroup | C170: 1XyIil3zqcvapCkiTWmnbLfcWEXl6C6APSGdFr3NZJG8
A171: Allocation | B171: DeleteFixedPreference | C171: 1Lc-ML_4b7mnzXBfCq-LRzFQuGbQPc39jG1KhSPiuFlE
A172: Blotter | B172: TransferToUserSubOrder | C172: 1JMP-lQIkD2QwHSSHVwOE1j_7tIv85AktZPPB_zFBu4g
A173: Blotter | B173: DetailsForAlgoTradeOrder | C173: 135vbRrrwrzk897F89o7GD1m6iNZsBp_lnj4InoCVNE0
A174: Blotter | B174: AddFillsSubOrder | C174: 1Ec_IWzMeUliNjKol2y6pmSgRum2J9VsqCvZFt3xqFco
A175: Blotter | B175: ViewAllocationDetailsSubOrder | C175: 1ObGJiH8e0w2LI1lmBMhqnl9SViMwVKJ6px28_Q92VNM
...

Sheet _Settings
A1: Settings
A3: Module Step Setting File | B3: 1l_e8VvGuwCFxAKLBGkTuz3SAc2MbR8Czf_PhA-Ma5cc
A4: Master Data Settings File | B4: 1IgG4rPFvDd69IZFqvmXQloBfQky1cnS4suoIvGHGhF4

Sheet _MasterData
A1: Master Data Info
A3: Module | B3: Step | C3: Master Data Sheet
A4: =IFERROR(__xludf.DUMMYFUNCTION("IMPORTRANGE('_Settings'!B4,""Master Data!A4:L1000"")"),"TradingTicket") -> TradingTicket | B4: TradeUsingTT | C4: TTTrades | D4: 1Q0knOJ8odySzW9kzE5w8PdOc44G2QBZUfKg5ZvUx-xw
A5: Allocation | B5: SelectAllocatedGroup | C5: TradesForAllocation | D5: 1-RJhOo2E5PhyqaiMEjsPi8RpfYBuiSqE9fj_-bRpkKw
A6: Allocation | B6: SelectUnallocatedGroup | C6: TradesForAllocation | D6: 1-RJhOo2E5PhyqaiMEjsPi8RpfYBuiSqE9fj_-bRpkKw
A7: TradingTicket | B7: CreateDoneAwayOrder | C7: TTInput | D7: 1b5S4Xpp4fgZ1ez6cK92QFnVBylqz8jhwxdAyEvwDqUI
A8: Allocation | B8: SetGroupingRules | C8: GroupingRules | D8: 1oiITP7kpTv6Zgm5fpjzHWhIjzPRoRqS_CIZxqoxWRkA
A9: Allocation | B9: CheckUnallocatedGroups | C9: UnallocatedGroupCheck | D9: 1c7aP-E18Fb8lEVGiXac03BLoNVdUNRzodD2Xjn-9pzU
A10: GeneralLedger | B10: GetTradingTransaction | C10: GetTradingTransaction | D10: 1IuJkgEDoDUSnmXhZVZdA_x-3VnlMPyzRsUMpf_eRTTQ
A11: TradingTicket | B11: CreateDoneAwayOrder | C11: CreateDoneAwayOrder | D11: 1Wybl1BX2sjPWI0uYzeN6KZO-tnk3-pf5NWNrZR7m_8I
A12: Allocation | B12: GeneralPreferencesDefaultRule | C12: GeneralPreferencesDefualtRules | D12: 1t-y8DW-cux-RoCJhMs9d4iDbW4QOQ-BXfiT1GYQBvbw
A13: Allocation | B13: GeneralPrefCompanyUserWise | C13: GeneralPrefCoUserRules | D13: 154-ES2jrM9C4VoMik8t5SCjN2LjvQHLPe8ANoIosIcc
A14: Allocation | B14: EnterAccountValuesToAllocate | C14: AccountValues | D14: 1mOtszotVOdqHquQTLi-4CBnAUrtAF2MEABuvYJh_hzw
A15: Allocation | B15: CheckFixedPreference | C15: CheckFixedPreference | D15: 1RNofLIplBOnX_vwsD6AecMNF72I9x58kWSMHVy9EgsM
A16: Allocation | B16: SetAccountValueCalculatedPref | C16: AccountValueCalculatePref | D16: 1svq-61dzaRHeNDz1TSSUPXQbbN3Mi4bhNQabvGVoz2c
... A20: Closing | B20: AutomaticClosing | C20: AutomaticClosingMasterData | D20: 1zwv-aZp-DRCpq8bqLR0XRiyt0av-GAm0ORqbhnV-FKI

Sheet CreateDoneAwayOrder
B1: Data
J2: =VLOOKUP($E$3,'_MasterData'!B4:D1000,3,FALSE) -> 1b5S4Xpp4fgZ1ez6cK92QFnVBylqz8jhwxdAyEvwDqUI
B3: Module | C3: TradingTicket | D3: Step | E3: CreateDoneAwayOrder | F3: Data Format | G3: Input Format
B4: =IFERROR(__xludf.DUMMYFUNCTION("IF(C3="""","""",Transpose(IMPORTRANGE('_Settings'!$B$3,C3&""!A4:A1000"")))"),"OpenTTFromPST") -> OpenTTFromPST | C4: EnterDetailsOnTT | D4: ValidateSymbolTT | E4: VerifyDataTT | F4: SetUIPreferencesTT | G4: SetBrokerWisePreferencesTT | H4: TradeNewSub | I4: CreateStageOrder | J4: CreateReplaceOrder | K4: SetGeneralPreference | L4: CreateDoneAwayOrder | M4: CreateNewSubOrder | N4: TradeBloomberg | O4: ClickSymbolLookup | P4: VerifyTT
A5: =IFERROR(__xludf.DUMMYFUNCTION("TRANSPOSE(IMPORTRANGE(VLOOKUP($E$3,IMPORTRANGE('_Settings'!$B$3,$C$3&""!A4:B1000""),2,FALSE),$G$3&""!A4:A1000""))"),"") | B5: Symbol | C5: Order Side | D5: Quantity | E5: TargetQuantityIn | F5: AllocationMethod | G5: Broker | H5: TIF | I5: Order Type | J5: Price | K5: Stop | L5: Limit | M5: Strategy | N5: Trade Date | O5: FxRate | P5: Notes | Q5: Broker Notes | R5: CommissionBasis | S5: CommissionRate | T5: SoftBasis | U5: SoftRate | V5: TradeAttribute1 | W5: TradeAttribute2 | X5: TradeAttribute3 | Y5: TradeAttribute4 | Z5: TradeAttribute5 | AA5: TradeAttribute6 | AB5: Venue | AC5: ExecutionInstructions | AD5: HandlingInstructions | AE5: Trader | AF5: SettlementCurrency | AG5: SettlementFXRate | AH5: SettlementAmount | AI5: SettlementFXOperator | AJ5: SettleByBroker | AK5: Account | AL5: Account % | AM5: Deal In
B6: GOOG | C6: Buy | D6: 10 | E6: 10 | F6: Allocation1 | J6: 10 | N6: =TODAY() -> 43270
B7: AAPL | C7: Buy | D7: 1000 | E7: 1000 | F7: Allocation2 | J7: 11 | N7: =TODAY() -> 43270

Sheet GetDataAllocation
B1: Data
J2: =VLOOKUP($E$3,'_MasterData'!B4:D1000,3,FALSE) -> #N/A
B3: Module | C3: Allocation | D3: Step | E3: GetDataAllocation | F3: Data Format | G3: Input Format
B4: =IFERROR(__xludf.DUMMYFUNCTION("IF(C3="""","""",Transpose(IMPORTRANGE('_Settings'!$B$3,C3&""!A4:A1000"")))"),"Allocate") -> Allocate | C4: CheckAllocatedGroups | D4: Unallocate | E4: GetDataAllocation | F4: SelectAllocatedGroup | G4: EditTradesAllocated | H4: EditTradesUnallocated | I4: Reallocate | J4: CleanUp | K4: EditUnallocatedGroupSidePanel | L4: TradeAttributeBulkChange | M4: ApplyBulkUpdateOnGroups | N4: ApplyPrefetchFilters | O4: GeneralPreferencesDefaultRule | P4: GeneralPrefCompanyUserWise | Q4: RenameTradeAttributes | R4: SetGroupingRules | S4: SetMasterFundRatio | T4: CheckFixedPreference | U4: GetFixedPreference | V4: AddCalculatedPreferences | W4: BulkChangeCalculatedPreferences | X4: DeleteCalculatedPreferences | Y4: RenameCalculatedPreferences | Z4: CopyCalculatedPreferences | AA4: RunAutoGroup | AB4: BookOrUpdateSwap | AC4: RunProrata | AD4: SetDefaultRuleCalculatedPref | AE4: SetAccountValueCalculatedPref | AF4: TradeAttributeBulkChangeGroups | AG4: TradeAttributeBulkChangeTaxlots | AH4: AddCalculatedPreferenceToolbar | AI4: SetStrategyValueCalculatedPref | AJ4: ApplyBulkUpdateOnTaxlots | AK4: CommissionBulkChangeOnGroups | AL4: CommissionBulkChangeOnTaxlots | AM4: SelectUnallocatedGroup | AN4: EnterAccountValuesToAllocate | AO4: EnterAllocatePreference | AP4: EnterStrategyValuesToAllocate | AQ4: CopyCalculatedPreferenceToolbar | AR4: SetGeneralRuleCalculatedPref | AS4: ExportAllCalculatedPreferences | AT4: SaveCalculatedPreferences | AU4: SaveCalculatedPreferences | AV4: CloseCalculatedPreferences | AW4: ExportCalculatedPreference | AX4: ImportCalculatedPreferences | AY4: OpenAuditTrailUnallocatedGroup | AZ4: DeleteCalculatedPreferencesTool | BA4: ImportCalculatedPreferencesTool | BB4: ExportAllCalculatedPreferTool | BC4: OpenAuditTrailAllocatedGroup | BD4: OpenSymbolLookupUnallocateGroup | BE4: OpenSymbolLookupAllocatedGroup | BF4: DeleteFixedPreference | BG4: EditAllocatedGroupSidePanel | BH4: CheckUnallocatedGroups | BI4: SetGeneralPreferences | BJ4: UngroupTrades | BK4: GroupTrades | BL4: DeleteGroup | BM4: CloseOrder | BN4: Unallocate | BO4: CloseAllocation | BP4: UpdateGRAccountValue | BQ4: UpdateGRStrategyValue | BR4: UpdateGRDefaultRule | BS4: UpdateGeneralRulePref | BT4: ModifyGRPreferenceValues | BU4: AddMFPreferences | BV4: AddMFPreferenceToolbar | BW4: DeleteMFPreferences | BX4: DeleteMFPreferenceToolbar | BY4: RenameMFPreferences | BZ4: SaveCloseMFPreference | CA4: SetMFPrefAccountValues | CB4: ModifyMFPrefGeneralRuleValues | CC4: SetMFPrefStrategyValues | CD4: SetMFPrefGeneralRule | CE4: SetMFPrefFundDistribution | CF4: SetMFPreferencesDefaultRule | CG4: SetMFPrefFundDefaultRule | CH4: ClearPrefetchFilters | CI4: ExpandCollapseAllUnallocated | CJ4: ExpandCollapseAllAllocated | CK4: GenerateCashTransaction | CL4: SaveAllocation | CM4: SaveAllocation | CN4: UnallocateWithOutSave | CO4: EditUnallocatedGrid | CP4: EditAllocatedGrid | CQ4: SaveLayoutAllocatedGrid | CR4: SaveLayoutUnallocatedGrid | CS4: SaveLayoutAllocationUI | CT4: ClearFiltersAllocatedGrid | CU4: ClearFiltersUnallocatedGrid | CV4: VerifyLayoutAllocatedGrid | CW4: VerifyLayoutUnallocatedGrid
A5: =IFERROR(__xludf.DUMMYFUNCTION("TRANSPOSE(IMPORTRANGE(VLOOKUP($E$3,IMPORTRANGE('_Settings'!$B$3,$C$3&""!A4:B1000""),2,FALSE),$G$3&""!A4:A1000""))"),"") | B5: RangeType | C5: From | D5: To | E5: FilterTabName | F5: Symbol | G5: Asset | H5: Side | I5: Account | J5: Broker | K5: Currency | L5: Exchange | M5: StrategyName | N5: Underlying | O5: Venue | P5: TradingAccount | Q5: PreAllocated | R5: ManualGroup
B6: Historical | C6: =TODAY() -> 43270 | D6: =TODAY() -> 43270

Sheet SelectAllocatedGroup
B1: Data
J2: =VLOOKUP($E$3,'_MasterData'!B4:D1000,3,FALSE) -> 1-RJhOo2E5PhyqaiMEjsPi8RpfYBuiSqE9fj_-bRpkKw
B3: Module | C3: Allocation | D3: Step | E3: SelectAllocatedGroup | F3: Data Format | G3: Input Format
B4: =IFERROR(__xludf.DUMMYFUNCTION("IF(C3="""","""",Transpose(IMPORTRANGE('_Settings'!$B$3,C3&""!A4:A1000"")))"),"Allocate") -> Allocate | C4: CheckAllocatedGroups | D4: Unallocate | E4: GetDataAllocation | F4: SelectAllocatedGroup | G4: EditTradesAllocated | H4: EditTradesUnallocated | I4: Reallocate | J4: CleanUp | K4: EditUnallocatedGroupSidePanel | L4: TradeAttributeBulkChange | M4: ApplyBulkUpdateOnGroups | N4: ApplyPrefetchFilters | O4: GeneralPreferencesDefaultRule | P4: GeneralPrefCompanyUserWise | Q4: RenameTradeAttributes | R4: SetGroupingRules | S4: SetMasterFundRatio | T4: CheckFixedPreference | U4: GetFixedPreference | V4: AddCalculatedPreferences | W4: BulkChangeCalculatedPreferences | X4: DeleteCalculatedPreferences | Y4: RenameCalculatedPreferences | Z4: CopyCalculatedPreferences | AA4: RunAutoGroup | AB4: BookOrUpdateSwap | AC4: RunProrata | AD4: SetDefaultRuleCalculatedPref | AE4: SetAccountValueCalculatedPref | AF4: TradeAttributeBulkChangeGroups | AG4: TradeAttributeBulkChangeTaxlots | AH4: AddCalculatedPreferenceToolbar | AI4: SetStrategyValueCalculatedPref | AJ4: ApplyBulkUpdateOnTaxlots | AK4: CommissionBulkChangeOnGroups | AL4: CommissionBulkChangeOnTaxlots | AM4: SelectUnallocatedGroup | AN4: EnterAccountValuesToAllocate | AO4: EnterAllocatePreference | AP4: EnterStrategyValuesToAllocate | AQ4: CopyCalculatedPreferenceToolbar | AR4: SetGeneralRuleCalculatedPref | AS4: ExportAllCalculatedPreferences | AT4: SaveCalculatedPreferences | AU4: SaveCalculatedPreferences | AV4: CloseCalculatedPreferences | AW4: ExportCalculatedPreference | AX4: ImportCalculatedPreferences | AY4: OpenAuditTrailUnallocatedGroup | AZ4: DeleteCalculatedPreferencesTool | BA4: ImportCalculatedPreferencesTool | BB4: ExportAllCalculatedPreferTool | BC4: OpenAuditTrailAllocatedGroup | BD4: OpenSymbolLookupUnallocateGroup | BE4: OpenSymbolLookupAllocatedGroup | BF4: DeleteFixedPreference | BG4: EditAllocatedGroupSidePanel | BH4: CheckUnallocatedGroups | BI4: SetGeneralPreferences | BJ4: UngroupTrades | BK4: GroupTrades | BL4: DeleteGroup | BM4: CloseOrder | BN4: Unallocate | BO4: CloseAllocation | BP4: UpdateGRAccountValue | BQ4: UpdateGRStrategyValue | BR4: UpdateGRDefaultRule | BS4: UpdateGeneralRulePref | BT4: ModifyGRPreferenceValues | BU4: AddMFPreferences | BV4: AddMFPreferenceToolbar | BW4: DeleteMFPreferences | BX4: DeleteMFPreferenceToolbar | BY4: RenameMFPreferences | BZ4: SaveCloseMFPreference | CA4: SetMFPrefAccountValues | CB4: ModifyMFPrefGeneralRuleValues | CC4: SetMFPrefStrategyValues | CD4: SetMFPrefGeneralRule | CE4: SetMFPrefFundDistribution | CF4: SetMFPreferencesDefaultRule | CG4: SetMFPrefFundDefaultRule | CH4: ClearPrefetchFilters | CI4: ExpandCollapseAllUnallocated | CJ4: ExpandCollapseAllAllocated | CK4: GenerateCashTransaction | CL4: SaveAllocation | CM4: SaveAllocation | CN4: UnallocateWithOutSave | CO4: EditUnallocatedGrid | CP4: EditAllocatedGrid | CQ4: SaveLayoutAllocatedGrid | CR4: SaveLayoutUnallocatedGrid | CS4: SaveLayoutAllocationUI | CT4: ClearFiltersAllocatedGrid | CU4: ClearFiltersUnallocatedGrid | CV4: VerifyLayoutAllocatedGrid | CW4: VerifyLayoutUnallocatedGrid
A5: =IFERROR(__xludf.DUMMYFUNCTION("TRANSPOSE(IMPORTRANGE(VLOOKUP($E$3,IMPORTRANGE('_Settings'!$B$3,$C$3&""!A4:B1000""),2,FALSE),$G$3&""!A4:A1000""))"),"") | B5: Symbol | C5: Quantity | D5: Trade Date | E5: Account Name | F5: Side | G5: Group Status | H5: Avg Price(Base) | I5: Execution Time | J5: Trade Attribute 1 | K5: Avg Price(Local) | L5: Trade Attribute 2 | M5: Accrued Interest | N5: Commission | O5: Soft Commission | P5: Broker | Q5: Transaction Type | R5: AUEC Fee1 | S5: AUEC Fee2 | T5: Clearing Broker Fee | U5: Other Broker Fees | V5: OCC Fee | W5: SEC Fee | X5: ORF Fee | Y5: IsPreAllocated | Z5: Stamp Duty | AA5: IsManual Group | AB5: Tax On Commissions | AC5: IsAnotherTaxlotAttributesUpdated | AD5: ISNDF | AE5: Transaction Levy | AF5: Description | AG5: GroupID | AH5: Internal Comments | AI5: M2MProfitLoss | AJ5: FX Rate | AK5: FX Conversion Operator | AL5: Trade Attribute 3 | AM5: Trade Attribute 4 | AN5: Trade Attribute 5 | AO5: Trade Attribute 6 | AP5: Put Or Call | AQ5: Allocated Qty | AR5: Total Commission And Fee | AS5: Executed Qty | AT5: Net Amount( Local) | AU5: Net Amount( Base) | AV5: UnAllocatedQty | AW5: Option Premium Adjustment | AX5: Principal Amount( Local) | AY5: Principal Amount( Base) | AZ5: Settlement Currency | BA5: User | BB5: Asset Category | BC5: Change Type | BD5: Strategy Name | BE5: Prana Msg Type | BF5: Total Commission | BG5: Commission Per Share | BH5: Soft Commission Per Share | BI5: Total Commission Per Share | BJ5: Closing Status | BK5: Closing Method | BL5: Allocation Scheme Name | BM5: Change Comment | BN5: Order Type | BO5: Underlying | BP5: Exchange | BQ5: Currency | BR5: AUECID | BS5: Trading Account | BT5: Venue | BU5: Cum Qty For Sub Order | BV5: Contract Multiplier | BW5: Company | BX5: Nirvana Process Date | BY5: Process Date | BZ5: Original Purchase Date | CA5: Closing Date | CB5: Settlement Date | CC5: Expiration Date | CD5: Underlying Symbol | CE5: Accrual Basis | CF5: Bond Type | CG5: Coupon Rate | CH5: Delta | CI5: Bloomberg | CJ5: Sedol Symbol | CK5: Cusip Symbol | CL5: ISIN | CM5: OSISSymbol | CN5: IDCOSymbol | CO5: Underlying Delta | CP5: Proxy Symbol | CQ5: Transaction Source | CR5: Import File Name
B6: GOOG | C6: 10 | E6: Allocation1 | F6: Buy | H6: 10
B7: AAPL | C7: 1000 | E7: Allocation2 | F7: Buy | H7: 11

Sheet EnterAccountValuesToAllocate
B1: Data
J2: =VLOOKUP($E$3,'_MasterData'!B4:D1000,3,FALSE) -> 1mOtszotVOdqHquQTLi-4CBnAUrtAF2MEABuvYJh_hzw
B3: Module | C3: Allocation | D3: Step | E3: EnterAccountValuesToAllocate | F3: Data Format | G3: Input Format
B4: =IFERROR(__xludf.DUMMYFUNCTION("IF(C3="""","""",Transpose(IMPORTRANGE('_Settings'!$B$3,C3&""!A4:A1000"")))"),"Allocate") -> Allocate | C4: CheckAllocatedGroups | D4: Unallocate | E4: GetDataAllocation | F4: SelectAllocatedGroup | G4: EditTradesAllocated | H4: EditTradesUnallocated | I4: Reallocate | J4: CleanUp | K4: EditUnallocatedGroupSidePanel | L4: TradeAttributeBulkChange | M4: ApplyBulkUpdateOnGroups | N4: ApplyPrefetchFilters | O4: GeneralPreferencesDefaultRule | P4: GeneralPrefCompanyUserWise | Q4: RenameTradeAttributes | R4: SetGroupingRules | S4: SetMasterFundRatio | T4: CheckFixedPreference | U4: GetFixedPreference | V4: AddCalculatedPreferences | W4: BulkChangeCalculatedPreferences | X4: DeleteCalculatedPreferences | Y4: RenameCalculatedPreferences | Z4: CopyCalculatedPreferences | AA4: RunAutoGroup | AB4: BookOrUpdateSwap | AC4: RunProrata | AD4: SetDefaultRuleCalculatedPref | AE4: SetAccountValueCalculatedPref | AF4: TradeAttributeBulkChangeGroups | AG4: TradeAttributeBulkChangeTaxlots | AH4: AddCalculatedPreferenceToolbar | AI4: SetStrategyValueCalculatedPref | AJ4: ApplyBulkUpdateOnTaxlots | AK4: CommissionBulkChangeOnGroups | AL4: CommissionBulkChangeOnTaxlots | AM4: SelectUnallocatedGroup | AN4: EnterAccountValuesToAllocate | AO4: EnterAllocatePreference | AP4: EnterStrategyValuesToAllocate | AQ4: CopyCalculatedPreferenceToolbar | AR4: SetGeneralRuleCalculatedPref | AS4: ExportAllCalculatedPreferences | AT4: SaveCalculatedPreferences | AU4: SaveCalculatedPreferences | AV4: CloseCalculatedPreferences | AW4: ExportCalculatedPreference | AX4: ImportCalculatedPreferences | AY4: OpenAuditTrailUnallocatedGroup | AZ4: DeleteCalculatedPreferencesTool | BA4: ImportCalculatedPreferencesTool | BB4: ExportAllCalculatedPreferTool | BC4: OpenAuditTrailAllocatedGroup | BD4: OpenSymbolLookupUnallocateGroup | BE4: OpenSymbolLookupAllocatedGroup | BF4: DeleteFixedPreference | BG4: EditAllocatedGroupSidePanel | BH4: CheckUnallocatedGroups | BI4: SetGeneralPreferences | BJ4: UngroupTrades | BK4: GroupTrades | BL4: DeleteGroup | BM4: CloseOrder | BN4: Unallocate | BO4: CloseAllocation | BP4: UpdateGRAccountValue | BQ4: UpdateGRStrategyValue | BR4: UpdateGRDefaultRule | BS4: UpdateGeneralRulePref | BT4: ModifyGRPreferenceValues | BU4: AddMFPreferences | BV4: AddMFPreferenceToolbar | BW4: DeleteMFPreferences | BX4: DeleteMFPreferenceToolbar | BY4: RenameMFPreferences | BZ4: SaveCloseMFPreference | CA4: SetMFPrefAccountValues | CB4: ModifyMFPrefGeneralRuleValues | CC4: SetMFPrefStrategyValues | CD4: SetMFPrefGeneralRule | CE4: SetMFPrefFundDistribution | CF4: SetMFPreferencesDefaultRule | CG4: SetMFPrefFundDefaultRule | CH4: ClearPrefetchFilters | CI4: ExpandCollapseAllUnallocated | CJ4: ExpandCollapseAllAllocated | CK4: GenerateCashTransaction | CL4: SaveAllocation | CM4: SaveAllocation | CN4: UnallocateWithOutSave | CO4: EditUnallocatedGrid | CP4: EditAllocatedGrid | CQ4: SaveLayoutAllocatedGrid | CR4: SaveLayoutUnallocatedGrid | CS4: SaveLayoutAllocationUI | CT4: ClearFiltersAllocatedGrid | CU4: ClearFiltersUnallocatedGrid | CV4: VerifyLayoutAllocatedGrid | CW4: VerifyLayoutUnallocatedGrid
A5: =IFERROR(__xludf.DUMMYFUNCTION("TRANSPOSE(IMPORTRANGE(VLOOKUP($E$3,IMPORTRANGE('_Settings'!$B$3,$C$3&""!A4:B1000""),2,FALSE),$G$3&""!A4:A1000""))"),"") | B5: Account Name | C5: Account Percentage | D5: Account Quantity
B6: Allocation2 | C6: 50
B7: Allocation1 | C7: 50

Sheet CheckAllocatedGroups
B1: Data
J2: =VLOOKUP($E$3,'_MasterData'!B4:D1000,3,FALSE) -> #N/A
B3: Module | C3: Allocation | D3: Step | E3: CheckAllocatedGroups | F3: Data Format | G3: Input Format
B4: =IFERROR(__xludf.DUMMYFUNCTION("IF(C3="""","""",Transpose(IMPORTRANGE('_Settings'!$B$3,C3&""!A4:A1000"")))"),"Allocate") -> Allocate | C4: CheckAllocatedGroups | D4: Unallocate | E4: GetDataAllocation | F4: SelectAllocatedGroup | G4: EditTradesAllocated | H4: EditTradesUnallocated | I4: Reallocate | J4: CleanUp | K4: EditUnallocatedGroupSidePanel | L4: TradeAttributeBulkChange | M4: ApplyBulkUpdateOnGroups | N4: ApplyPrefetchFilters | O4: GeneralPreferencesDefaultRule | P4: GeneralPrefCompanyUserWise | Q4: RenameTradeAttributes | R4: SetGroupingRules | S4: SetMasterFundRatio | T4: CheckFixedPreference | U4: GetFixedPreference | V4: AddCalculatedPreferences | W4: BulkChangeCalculatedPreferences | X4: DeleteCalculatedPreferences | Y4: RenameCalculatedPreferences | Z4: CopyCalculatedPreferences | AA4: RunAutoGroup | AB4: BookOrUpdateSwap | AC4: RunProrata | AD4: SetDefaultRuleCalculatedPref | AE4: SetAccountValueCalculatedPref | AF4: TradeAttributeBulkChangeGroups | AG4: TradeAttributeBulkChangeTaxlots | AH4: AddCalculatedPreferenceToolbar | AI4: SetStrategyValueCalculatedPref | AJ4: ApplyBulkUpdateOnTaxlots | AK4: CommissionBulkChangeOnGroups | AL4: CommissionBulkChangeOnTaxlots | AM4: SelectUnallocatedGroup | AN4: EnterAccountValuesToAllocate | AO4: EnterAllocatePreference | AP4: EnterStrategyValuesToAllocate | AQ4: CopyCalculatedPreferenceToolbar | AR4: SetGeneralRuleCalculatedPref | AS4: ExportAllCalculatedPreferences | AT4: SaveCalculatedPreferences | AU4: SaveCalculatedPreferences | AV4: CloseCalculatedPreferences | AW4: ExportCalculatedPreference | AX4: ImportCalculatedPreferences | AY4: OpenAuditTrailUnallocatedGroup | AZ4: DeleteCalculatedPreferencesTool | BA4: ImportCalculatedPreferencesTool | BB4: ExportAllCalculatedPreferTool | BC4: OpenAuditTrailAllocatedGroup | BD4: OpenSymbolLookupUnallocateGroup | BE4: OpenSymbolLookupAllocatedGroup | BF4: DeleteFixedPreference | BG4: EditAllocatedGroupSidePanel | BH4: CheckUnallocatedGroups | BI4: SetGeneralPreferences | BJ4: UngroupTrades | BK4: GroupTrades | BL4: DeleteGroup | BM4: CloseOrder | BN4: Unallocate | BO4: CloseAllocation | BP4: UpdateGRAccountValue | BQ4: UpdateGRStrategyValue | BR4: UpdateGRDefaultRule | BS4: UpdateGeneralRulePref | BT4: ModifyGRPreferenceValues | BU4: AddMFPreferences | BV4: AddMFPreferenceToolbar | BW4: DeleteMFPreferences | BX4: DeleteMFPreferenceToolbar | BY4: RenameMFPreferences | BZ4: SaveCloseMFPreference | CA4: SetMFPrefAccountValues | CB4: ModifyMFPrefGeneralRuleValues | CC4: SetMFPrefStrategyValues | CD4: SetMFPrefGeneralRule | CE4: SetMFPrefFundDistribution | CF4: SetMFPreferencesDefaultRule | CG4: SetMFPrefFundDefaultRule | CH4: ClearPrefetchFilters | CI4: ExpandCollapseAllUnallocated | CJ4: ExpandCollapseAllAllocated | CK4: GenerateCashTransaction | CL4: SaveAllocation | CM4: SaveAllocation | CN4: UnallocateWithOutSave | CO4: EditUnallocatedGrid | CP4: EditAllocatedGrid | CQ4: SaveLayoutAllocatedGrid | CR4: SaveLayoutUnallocatedGrid | CS4: SaveLayoutAllocationUI | CT4: ClearFiltersAllocatedGrid | CU4: ClearFiltersUnallocatedGrid | CV4: VerifyLayoutAllocatedGrid | CW4: VerifyLayoutUnallocatedGrid
A5: =IFERROR(__xludf.DUMMYFUNCTION("TRANSPOSE(IMPORTRANGE(VLOOKUP($E$3,IMPORTRANGE('_Settings'!$B$3,$C$3&""!A4:B1000""),2,FALSE),$G$3&""!A4:A1000""))"),"") | B5: Account Name | C5: Accrual Basis | D5: Accrued Interest | E5: Allocated Qty | F5: Allocation Scheme Name | G5: Asset Category | H5: AUEC Fee1 | I5: AUEC Fee2 | J5: AUECID | K5: Avg Price(Base) | L5: Avg Price(Local) | M5: Bloomberg | N5: Bond Type | O5: Broker | P5: Change Comment | Q5: Change Type | R5: Clearing Broker Fee | S5: Closing Status | T5: Commission | U5: Commission Per Share | V5: Company | W5: Contract Multiplier | X5: Coupon Rate | Y5: Cum Qty For Sub Order | Z5: Currency | AA5: Cusip Symbol | AB5: Delta | AC5: Description | AD5: Exchange | AE5: Executed Qty | AF5: Exceution Time | AG5: Expiration Date | AH5: FX Conversion Operator | AI5: FX Rate | AJ5: Group Status | AK5: IDCOSymbol | AL5: Import File Name | AM5: Internal Comments | AN5: IsAnotherTaxlotAttributesUpdated | AO5: ISIN | AP5: IsManualGroup | AQ5: ISNDF | AR5: IsPreAllocated | AS5: M2MProfitLoss | AT5: Net Amount( Base) | AU5: Net Amount( Local) | AV5: Nirvana Process Date | AW5: OCC Fee | AX5: Option Premium Adjustment | AY5: Order Type | AZ5: ORF Fee | BA5: Original Purchase Date | BB5: OSISSymbol | BC5: Other Broker Fees | BD5: Prana Msg Type | BE5: Principal Amount( Base) | BF5: Principal Amount( Local) | BG5: Process Date | BH5: Proxy Symbol | BI5: Put Or Call | BJ5: Quantity | BK5: SEC Fee | BL5: Sedol Symbol | BM5: Settlement Currency | BN5: Settlement Date | BO5: Side | BP5: Soft Commission | BQ5: Soft Commission Per Share | BR5: Stamp Duty | BS5: Strategy Name | BT5: Symbol | BU5: Tax On Commissions | BV5: Total Commission | BW5: Total Commission And Fee | BX5: Total Commission Per Share | BY5: Trade Attribute 1 | BZ5: Trade Attribute 2 | CA5: Trade Attribute 3 | CB5: Trade Attribute 4 | CC5: Trade Attribute 5 | CD5: Trade Attribute 6 | CE5: Trade Date | CF5: Trading Account | CG5: Transaction Levy | CH5: Transaction Source | CI5: Transaction Type | CJ5: UnAllocatedQty | CK5: Underlying | CL5: Underlying Delta | CM5: Underlying Symbol | CN5: User | CO5: Venue | CP5: Closing Method | CQ5: Closing Date | CR5: GroupID
B6: Multiple | BJ6: 10 | BO6: Buy | BT6: GOOG
B7: Multiple | BJ7: 1000 | BO7: Buy | BT7: AAPL

Sheet CheckPortfolioManagement
B1: Data
J2: =VLOOKUP($E$3,'_MasterData'!B4:D1000,3,FALSE) -> #N/A
B3: Module | C3: PortfolioManagement | D3: Step | E3: CheckPortfolioManagement | F3: Data Format | G3: Input Format
B4: =IFERROR(__xludf.DUMMYFUNCTION("IF(C3="""","""",Transpose(IMPORTRANGE('_Settings'!$B$3,C3&""!A4:A1000"")))"),"CheckDashboardPM") -> CheckDashboardPM | C4: CheckPortfolioManagement | D4: OpenPSTFromPM | E4: ClosePM | F4: FilterPM | G4: GroupRowPM | H4: CheckDashboardWithPM | I4: RemoveFilterPM | J4: CheckSummaryRowsPM | K4: OpenPTTFromPM | L4: OpenCreateTransactionFromPM | M4: OpenClosingFromPM | N4: OpenCorporateActionFromPM | O4: OpenDailyValuationFromPM | P4: ClosePositionFromPM | Q4: ShowSummaryToolFromPM | R4: HideSummaryToolFromPM | S4: CloseAccountPositionFromPM | T4: CloseSelectedTaxlotsFromPM | U4: ExpandCollapsePM | V4: AddCustomViewPM | W4: AddCustomViewRightClickPM | X4: RenameCustomViewPM | Y4: DeleteCustomViewPM
A5: =IFERROR(__xludf.DUMMYFUNCTION("TRANSPOSE(IMPORTRANGE(VLOOKUP($E$3,IMPORTRANGE('_Settings'!$B$3,$C$3&""!A4:B1000""),2,FALSE),$G$3&""!A4:A1000""))"),"") | B5: Trade Date | C5: Symbol | D5: Position | E5: Account | F5: MasterFund | G5: Cost Basis | H5: Position Side | I5: Market Value (Base) | J5: % Day P&L (Gross MV) | K5: Net Exposure (Base) | L5: Beta Adj. Gross Exposure (Base) | M5: Beta Adj. Gross Exposure (Underlying) (Base) | N5: Day P&L (Base) | O5: Security Name | P5: Closing Mark | Q5: Cost Basis P&L (Base) | R5: Prime Broker | S5: Strategy | T5: Asset Class | U5: Underlying | V5: Exchange | W5: Trade Currency | X5: Multiplier | Y5: FX Rate | Z5: Vs Currency | AA5: Lead Currency | AB5: Dividend Yield (%) | AC5: % Change | AD5: Net Exposure (Local) | AE5: Exposure (Local) | AF5: Delta Adj. Position | AG5: Exposure (Base) | AH5: Beta Adj. Exposure (Local) | AI5: Beta Adj. Exposure (Base) | AJ5: Exposure (BP)(Base) | AK5: Day P&L (Local) | AL5: Delta | AM5: Leveraged Factor | AN5: Order Side | AO5: Master Strategy | AP5: Transaction Side | AQ5: Underlying Symbol | AR5: Underlying Price | AS5: Side Multiplier | AT5: Description | AU5: Internal Comments | AV5: FX Rate On Trade Date | AW5: Cost Basis P&L (Local) | AX5: Day Interest | AY5: Total Interest | AZ5: Market Value (Local) | BA5: % Gain/Loss Day | BB5: Update Time (Last Price) | BC5: Beta | BD5: Cash Impact (Local) | BE5: User Asset | BF5: Security Type | BG5: Sector | BH5: Sub Sector | BI5: Country | BJ5: Market Cap | BK5: Shares Outstanding | BL5: Avg Volume 20 Day | BM5: % Avg Volume (Delta Adj.) | BN5: Ex Dividend Date | BO5: Cash Impact (Base) | BP5: Volatility (%) | BQ5: User | BR5: Broker | BS5: Earned Dividend (Local) | BT5: Earned Dividend (Base) | BU5: Put/Call | BV5: Expiration Date | BW5: Strike Price | BX5: Gross Exposure (Base) | BY5: Gross Market Value (Base) | BZ5: Px Selected Feed (Local) | CA5: Px Selected Feed (Base) | CB5: Settlement Date | CC5: % Avg Volume | CD5: Day P&L (Base)(Price Gain) | CE5: Day P&L (Base)(FX Gain) | CF5: Cost Basis P&L (Base)(FX Gain) | CG5: Cost Basis P&L (Base)(Price Gain) | CH5: % Gain/Loss Cost | CI5: Underlying Value (Options) | CJ5: Avg Volume 20 Day (Underlying Symbol) | CK5: IsStaleData | CL5: IDCO | CM5: OSI | CN5: SEDOL | CO5: CUSIP | CP5: Bloomberg | CQ5: ISIN | CR5: Start Trade Date | CS5: Cost Basis (Break Even) | CT5: % Day Return (Gross MV) | CU5: Trade Attribute 3 | CV5: Trade Attribute 4 | CW5: Trade Attribute 5 | CX5: Trade Attribute 6 | CY5: Proxy Symbol | CZ5: Pricing Source | DA5: Delta Source | DB5: Gross Exposure (Local) | DC5: % Day P&L (Net MV) | DD5: Expiration Month | DE5: Delta Adj. Position (LME) | DF5: Premium | DG5: Premium $ | DH5: Forward Points | DI5: Closing Mark (Underlying) | DJ5: % Change (Underlying Price) | DK5: Transaction Type | DL5: Closing Market Value (Local) | DM5: Closing Market Value (Base) | DN5: Closing FX Rate | DO5: Change In Underlying Price | DP5: RIC | DQ5: Position Side Exposure (Boxed) | DR5: Analyst | DS5: Country Of Risk | DT5: Custom UDA1 | DU5: Custom UDA2 | DV5: Custom UDA3 | DW5: Custom UDA4 | DX5: Custom UDA5 | DY5: Custom UDA6 | DZ5: Custom UDA7 | EA5: Issuer | EB5: Liquid Tag | EC5: Market Cap UDA | ED5: Region | EE5: Risk Currency | EF5: UCITS Eligible Tag | EG5: FX Rate (Display) | EH5: % Net Exposure (Base) | EI5: % Gross Exposure (Base) | EJ5: % Exposure (Base) | EK5: % Gross Exposure (Underlying) (Base) | EL5: % Beta Adj. Gross Exposure (Base) | EM5: Position Side Exposure (Underlying) | EN5: Gross Exposure (Underlying) (Base) | EO5: Gross Exposure (Underlying) | EP5: Day Return | EQ5: Start of Day NAV | ER5: % Gross Market Value (Base) | ES5: Beta Adj. Gross Exposure (Underlying) (Local) | ET5: NAV | EU5: % P&L Contribution | EV5: % Net Market Value (Base) | EW5: Position Side Exposure | EX5: NAV (Touch) | EY5: IgnorePropertyChangeEvents | EZ5: Trade Attribute 1 | FA5: Trade Attribute 2
C6: GOOG | D6: 5 | E6: Allocation2 | AN6: Buy
C7: GOOG | D7: 5 | E7: Allocation1 | AN7: Buy
C8: AAPL | D8: 500 | E8: Allocation2 | AN8: Buy
C9: AAPL | D9: 500 | E9: Allocation1 | AN9: Buy

Sheet GetDataClosing
B1: Data
J2: =VLOOKUP($E$3,'_MasterData'!B4:D1000,3,FALSE) -> #N/A
B3: Module | C3: Closing | D3: Step | E3: GetDataClosing | F3: Data Format | G3: Input Format
B4: =IFERROR(__xludf.DUMMYFUNCTION("IF(C3="""","""",Transpose(IMPORTRANGE('_Settings'!$B$3,C3&""!A4:A1000"")))"),"SwapExpire") -> SwapExpire | C4: GetDataClosing | D4: ManualClosing | E4: AutomaticClosing | F4: UnwindClosing | G4: VerifyClosedTrades | H4: VerifyLongPositionsGrid | I4: VerifyShortPositionsGrid | J4: SelectTradeUnexpiredUnsettled | K4: CashSettlementAtCost | L4: CashSettlementAtZeroPrice | M4: CashSettlementAtClosingDtSpotPx | N4: PhysicalSettlement | O4: Expire | P4: ExerciseAssignment | Q4: ExerciseAssignmentAtZero | R4: SwapExpireAndRollover | S4: SwapExpire | T4: VerifyExpiredSettledGrid | U4: VerifyUnExpiredUnSettledGrid | V4: UnWindTradeSettlement | W4: CloseOrder | X4: VerifyCloseOrder | Y4: UnWindCloseOrder | Z4: ClosingCleanUp | AA4: CloseClosingUI | AB4: SetClosingPreference
A5: =IFERROR(__xludf.DUMMYFUNCTION("TRANSPOSE(IMPORTRANGE(VLOOKUP($E$3,IMPORTRANGE('_Settings'!$B$3,$C$3&""!A4:B1000""),2,FALSE),$G$3&""!A4:A1000""))"),"") | B5: RangeType | C5: From | D5: To | E5: Account Filter
B6: Historical | C6: =TODAY() -> 43270 | D6: =TODAY() -> 43270 | E6: Allocation1,Allocation2

Sheet VerifyLongPositionsGrid
B1: Data
J2: =VLOOKUP($E$3,'_MasterData'!B4:D1000,3,FALSE) -> #N/A
B3: Module | C3: Closing | D3: Step | E3: VerifyLongPositionsGrid | F3: Data Format | G3: Input Format
B4: =IFERROR(__xludf.DUMMYFUNCTION("IF(C3="""","""",Transpose(IMPORTRANGE('_Settings'!$B$3,C3&""!A4:A1000"")))"),"SwapExpire") -> SwapExpire | C4: GetDataClosing | D4: ManualClosing | E4: AutomaticClosing | F4: UnwindClosing | G4: VerifyClosedTrades | H4: VerifyLongPositionsGrid | I4: VerifyShortPositionsGrid | J4: SelectTradeUnexpiredUnsettled | K4: CashSettlementAtCost | L4: CashSettlementAtZeroPrice | M4: CashSettlementAtClosingDtSpotPx | N4: PhysicalSettlement | O4: Expire | P4: ExerciseAssignment | Q4: ExerciseAssignmentAtZero | R4: SwapExpireAndRollover | S4: SwapExpire | T4: VerifyExpiredSettledGrid | U4: VerifyUnExpiredUnSettledGrid | V4: UnWindTradeSettlement | W4: CloseOrder | X4: VerifyCloseOrder | Y4: UnWindCloseOrder | Z4: ClosingCleanUp | AA4: CloseClosingUI | AB4: SetClosingPreference
A5: =IFERROR(__xludf.DUMMYFUNCTION("TRANSPOSE(IMPORTRANGE(VLOOKUP($E$3,IMPORTRANGE('_Settings'!$B$3,$C$3&""!A4:B1000""),2,FALSE),$G$3&""!A4:A1000""))"),"") | B5: Account | C5: AssetCategoryValue | D5: AUECID | E5: ExternalTransId | F5: IsSwapped | G5: LotId | H5: Net Notional | I5: Opening Price | J5: Original Purchase Date | K5: PositionTag | L5: Process Date | M5: Quantity | N5: Security Name | O5: Settlement Currency | P5: Side | Q5: Strategy | R5: Symbol | S5: Taxlot ID | T5: Total Fees and Commission | U5: Trade Date | V5: Transaction Type | W5: UnderlyingName | X5: UnitCost | Y5: Unit Cost(Base) | Z5: AvgPriceBase
B6: Allocation2 | M6: 5 | P6: Buy | R6: GOOG
B7: Allocation1 | M7: 5 | P7: Buy | R7: GOOG
B8: Allocation2 | M8: 500 | P8: Buy | R8: AAPL
B9: Allocation1 | M9: 500 | P9: Buy | R9: AAPL

Sheet GetActivityData
B1: Data
J2: =VLOOKUP($E$3,'_MasterData'!B4:D1000,3,FALSE) -> #N/A
B3: Module | C3: GeneralLedger | D3: Step | E3: GetActivityData | F3: Data Format | G3: Input Format
B4: =IFERROR(__xludf.DUMMYFUNCTION("IF(C3="""","""",Transpose(IMPORTRANGE('_Settings'!$B$3,C3&""!A4:A1000"")))"),"GetDataCash") -> GetDataCash | C4: EnterCashDividends | D4: EnterNonTradingTransaction | E4: VerifyCash | F4: VerifyActivity | G4: VerifyTradingTransaction | H4: VerifyRevaluationData | I4: GetTradingTransaction | J4: GetActivityData | K4: GetRevaluationData | L4: GetAccountDetails | M4: GetNonTradingTransaction | N4: GetDividendData | O4: VerifyNonTradingTransaction | P4: VerifyDividend | Q4: GetOpeningBalanceData | R4: GetAccountBalance | S4: SelectNonTradingTransaction | T4: SelectNonTradingTranItem | U4: DeleteNonTradingTransaction | V4: DeleteNonTradingTranItem | W4: AddNonTradingTransaction | X4: AddNonTradingTranItem | Y4: VerifyOpeningBalanceData | Z4: SelectOpeningBalanceTransaction | AA4: SelectOpeningBalanceTranItem | AB4: EditNonTradingTransaction | AC4: EditNonTradingTranItem | AD4: DeleteOpeningBalanceTransaction | AE4: DeleteOpeningBalanceTranItem | AF4: GetDayEndCash | AG4: VerifyDayEndCash | AH4: RunRevaluation | AI4: CalculateDayEndCash | AJ4: GetCashTransaction | AK4: SelectCashTransaction | AL4: DeleteCashTransaction | AM4: EditCashTransaction | AN4: AddCashTransaction | AO4: AddOpeningBalanceTransaction | AP4: AddOpeningBalanceTranItem | AQ4: GetDailyCalculationsData | AR4: CalculateDailyCalculations | AS4: EditOpeningBalanceTransaction | AT4: EditOpeningBalanceTranItem | AU4: VerifyDailyCalTransactions | AV4: CloseGeneralLedger | AW4: VerifyAccountDetails | AX4: SaveTransaction
A5: =IFERROR(__xludf.DUMMYFUNCTION("TRANSPOSE(IMPORTRANGE(VLOOKUP($E$3,IMPORTRANGE('_Settings'!$B$3,$C$3&""!A4:B1000""),2,FALSE),$G$3&""!A4:A1000""))"),"") | B5: MasterFund | C5: Accounts | D5: From | E5: To | F5: SettlementDate | G5: TradeDate | H5: All
B6: SelectAll | C6: Allocation1,Allocation2 | D6: =TODAY() -> 43270 | E6: =TODAY() -> 43270 | F6: No | G6: Yes | H6: No

Sheet VerifyActivity
B1: Data
J2: =VLOOKUP($E$3,'_MasterData'!B4:D1000,3,FALSE) -> #N/A
B3: Module | C3: GeneralLedger | D3: Step | E3: VerifyActivity | F3: Data Format | G3: Input Format
B4: =IFERROR(__xludf.DUMMYFUNCTION("IF(C3="""","""",Transpose(IMPORTRANGE('_Settings'!$B$3,C3&""!A4:A1000"")))"),"GetDataCash") -> GetDataCash | C4: EnterCashDividends | D4: EnterNonTradingTransaction | E4: VerifyCash | F4: VerifyActivity | G4: VerifyTradingTransaction | H4: VerifyRevaluationData | I4: GetTradingTransaction | J4: GetActivityData | K4: GetRevaluationData | L4: GetAccountDetails | M4: GetNonTradingTransaction | N4: GetDividendData | O4: VerifyNonTradingTransaction | P4: VerifyDividend | Q4: GetOpeningBalanceData | R4: GetAccountBalance | S4: SelectNonTradingTransaction | T4: SelectNonTradingTranItem | U4: DeleteNonTradingTransaction | V4: DeleteNonTradingTranItem | W4: AddNonTradingTransaction | X4: AddNonTradingTranItem | Y4: VerifyOpeningBalanceData | Z4: SelectOpeningBalanceTransaction | AA4: SelectOpeningBalanceTranItem | AB4: EditNonTradingTransaction | AC4: EditNonTradingTranItem | AD4: DeleteOpeningBalanceTransaction | AE4: DeleteOpeningBalanceTranItem | AF4: GetDayEndCash | AG4: VerifyDayEndCash | AH4: RunRevaluation | AI4: CalculateDayEndCash | AJ4: GetCashTransaction | AK4: SelectCashTransaction | AL4: DeleteCashTransaction | AM4: EditCashTransaction | AN4: AddCashTransaction | AO4: AddOpeningBalanceTransaction | AP4: AddOpeningBalanceTranItem | AQ4: GetDailyCalculationsData | AR4: CalculateDailyCalculations | AS4: EditOpeningBalanceTransaction | AT4: EditOpeningBalanceTranItem | AU4: VerifyDailyCalTransactions | AV4: CloseGeneralLedger | AW4: VerifyAccountDetails | AX4: SaveTransaction
A5: =IFERROR(__xludf.DUMMYFUNCTION("TRANSPOSE(IMPORTRANGE(VLOOKUP($E$3,IMPORTRANGE('_Settings'!$B$3,$C$3&""!A4:B1000""),2,FALSE),$G$3&""!A4:A1000""))"),"") | B5: Account | C5: Activity Source | D5: ActivityType | E5: Net Amount(Local) | F5: AUEC Fee1 | G5: AUEC Fee2 | H5: Balance Type | I5: Clearing Broker Fees | J5: Commission | K5: Currency | L5: Description | M5: Entry Date | N5: FX Conversion Method Operator | O5: Fx Rate | P5: Lead Currency | Q5: Modify date | R5: OCC Fee | S5: OptionPremiumAdjustment | T5: ORF Fee | U5: Other Broker Fees | V5: Quantity | W5: SEC Fee | X5: Settlement Currency | Y5: Settlement Date | Z5: Soft Commission | AA5: Stamp Duty | AB5: Symbol | AC5: Tax On Commissions | AD5: Total Commissions | AE5: Trade Date | AF5: Transaction Levy | AG5: Transaction Source | AH5: User | AI5: Vs Currency | AJ5: SettlCurrencyID
B6: Allocation2 | D6: EquityL | K6: USD | AB6: GOOG | AE6: =TODAY() -> 43270
B7: Allocation1 | D7: EquityL | K7: USD | AB7: GOOG | AE7: =TODAY() -> 43270
B8: Allocation2 | D8: EquityL | K8: USD | AB8: AAPL | AE8: =TODAY() -> 43270
B9: Allocation1 | D9: EquityL | K9: USD | AB9: AAPL | AE9: =TODAY() -> 43270

Sheet GetTradingTransaction
B1: Data
J2: =VLOOKUP($E$3,'_MasterData'!B4:D1000,3,FALSE) -> 1IuJkgEDoDUSnmXhZVZdA_x-3VnlMPyzRsUMpf_eRTTQ
B3: Module | C3: GeneralLedger | D3: Step | E3: GetTradingTransaction | F3: Data Format | G3: Input Format
B4: =IFERROR(__xludf.DUMMYFUNCTION("IF(C3="""","""",Transpose(IMPORTRANGE('_Settings'!$B$3,C3&""!A4:A1000"")))"),"GetDataCash") -> GetDataCash | C4: EnterCashDividends | D4: EnterNonTradingTransaction | E4: VerifyCash | F4: VerifyActivity | G4: VerifyTradingTransaction | H4: VerifyRevaluationData | I4: GetTradingTransaction | J4: GetActivityData | K4: GetRevaluationData | L4: GetAccountDetails | M4: GetNonTradingTransaction | N4: GetDividendData | O4: VerifyNonTradingTransaction | P4: VerifyDividend | Q4: GetOpeningBalanceData | R4: GetAccountBalance | S4: SelectNonTradingTransaction | T4: SelectNonTradingTranItem | U4: DeleteNonTradingTransaction | V4: DeleteNonTradingTranItem | W4: AddNonTradingTransaction | X4: AddNonTradingTranItem | Y4: VerifyOpeningBalanceData | Z4: SelectOpeningBalanceTransaction | AA4: SelectOpeningBalanceTranItem | AB4: EditNonTradingTransaction | AC4: EditNonTradingTranItem | AD4: DeleteOpeningBalanceTransaction | AE4: DeleteOpeningBalanceTranItem | AF4: GetDayEndCash | AG4: VerifyDayEndCash | AH4: RunRevaluation | AI4: CalculateDayEndCash | AJ4: GetCashTransaction | AK4: SelectCashTransaction | AL4: DeleteCashTransaction | AM4: EditCashTransaction | AN4: AddCashTransaction | AO4: AddOpeningBalanceTransaction | AP4: AddOpeningBalanceTranItem | AQ4: GetDailyCalculationsData | AR4: CalculateDailyCalculations | AS4: EditOpeningBalanceTransaction | AT4: EditOpeningBalanceTranItem | AU4: VerifyDailyCalTransactions | AV4: CloseGeneralLedger | AW4: VerifyAccountDetails | AX4: SaveTransaction
A5: =IFERROR(__xludf.DUMMYFUNCTION("TRANSPOSE(IMPORTRANGE(VLOOKUP($E$3,IMPORTRANGE('_Settings'!$B$3,$C$3&""!A4:B1000""),2,FALSE),$G$3&""!A4:A1000""))"),"") | B5: MasterFund | C5: Accounts | D5: From Date | E5: To Date
B6: SelectAll | C6: Allocation1,Allocation2 | D6: =TODAY() -> 43270 | E6: =TODAY() -> 43270

Sheet VerifyTradingTransaction
B1: Data
J2: =VLOOKUP($E$3,'_MasterData'!B4:D1000,3,FALSE) -> #N/A
B3: Module | C3: GeneralLedger | D3: Step | E3: VerifyTradingTransaction | F3: Data Format | G3: Input Format
B4: =IFERROR(__xludf.DUMMYFUNCTION("IF(C3="""","""",Transpose(IMPORTRANGE('_Settings'!$B$3,C3&""!A4:A1000"")))"),"GetDataCash") -> GetDataCash | C4: EnterCashDividends | D4: EnterNonTradingTransaction | E4: VerifyCash | F4: VerifyActivity | G4: VerifyTradingTransaction | H4: VerifyRevaluationData | I4: GetTradingTransaction | J4: GetActivityData | K4: GetRevaluationData | L4: GetAccountDetails | M4: GetNonTradingTransaction | N4: GetDividendData | O4: VerifyNonTradingTransaction | P4: VerifyDividend | Q4: GetOpeningBalanceData | R4: GetAccountBalance | S4: SelectNonTradingTransaction | T4: SelectNonTradingTranItem | U4: DeleteNonTradingTransaction | V4: DeleteNonTradingTranItem | W4: AddNonTradingTransaction | X4: AddNonTradingTranItem | Y4: VerifyOpeningBalanceData | Z4: SelectOpeningBalanceTransaction | AA4: SelectOpeningBalanceTranItem | AB4: EditNonTradingTransaction | AC4: EditNonTradingTranItem | AD4: DeleteOpeningBalanceTransaction | AE4: DeleteOpeningBalanceTranItem | AF4: GetDayEndCash | AG4: VerifyDayEndCash | AH4: RunRevaluation | AI4: CalculateDayEndCash | AJ4: GetCashTransaction | AK4: SelectCashTransaction | AL4: DeleteCashTransaction | AM4: EditCashTransaction | AN4: AddCashTransaction | AO4: AddOpeningBalanceTransaction | AP4: AddOpeningBalanceTranItem | AQ4: GetDailyCalculationsData | AR4: CalculateDailyCalculations | AS4: EditOpeningBalanceTransaction | AT4: EditOpeningBalanceTranItem | AU4: VerifyDailyCalTransactions | AV4: CloseGeneralLedger | AW4: VerifyAccountDetails | AX4: SaveTransaction
A5: =IFERROR(__xludf.DUMMYFUNCTION("TRANSPOSE(IMPORTRANGE(VLOOKUP($E$3,IMPORTRANGE('_Settings'!$B$3,$C$3&""!A4:B1000""),2,FALSE),$G$3&""!A4:A1000""))"),"") | B5: Date | C5: Modify Date | D5: Entry Date | E5: DR | F5: CR | G5: Fx Rate | H5: FX Conversion Method Operator | I5: Account Side | J5: TransactionSource | K5: Currency | L5: Base Currency | M5: Symbol | N5: Description | O5: DR (Base) | P5: CR (Base) | Q5: Cash Sub-Account | R5: Account | S5: TaxLotId
B6: =TODAY() -> 43270 | K6: USD | M6: GOOG | Q6: Investment - Long Equity [Asset] | R6: Allocation2
B7: =TODAY() -> 43270 | K7: USD | M7: GOOG | Q7: Investment - Long Equity [Asset] | R7: Allocation1
B8: =TODAY() -> 43270 | K8: USD | M8: AAPL | Q8: Investment - Long Equity [Asset] | R8: Allocation2
B9: =TODAY() -> 43270 | K9: USD | M9: AAPL | Q9: Investment - Long Equity [Asset] | R9: Allocation1

Sheet GetRevaluationData
B1: Data
J2: =VLOOKUP($E$3,'_MasterData'!B4:D1000,3,FALSE) -> #N/A
B3: Module | C3: GeneralLedger | D3: Step | E3: GetRevaluationData | F3: Data Format | G3: Input Format
B4: =IFERROR(__xludf.DUMMYFUNCTION("IF(C3="""","""",Transpose(IMPORTRANGE('_Settings'!$B$3,C3&""!A4:A1000"")))"),"GetDataCash") -> GetDataCash | C4: EnterCashDividends | D4: EnterNonTradingTransaction | E4: VerifyCash | F4: VerifyActivity | G4: VerifyTradingTransaction | H4: VerifyRevaluationData | I4: GetTradingTransaction | J4: GetActivityData | K4: GetRevaluationData | L4: GetAccountDetails | M4: GetNonTradingTransaction | N4: GetDividendData | O4: VerifyNonTradingTransaction | P4: VerifyDividend | Q4: GetOpeningBalanceData | R4: GetAccountBalance | S4: SelectNonTradingTransaction | T4: SelectNonTradingTranItem | U4: DeleteNonTradingTransaction | V4: DeleteNonTradingTranItem | W4: AddNonTradingTransaction | X4: AddNonTradingTranItem | Y4: VerifyOpeningBalanceData | Z4: SelectOpeningBalanceTransaction | AA4: SelectOpeningBalanceTranItem | AB4: EditNonTradingTransaction | AC4: EditNonTradingTranItem | AD4: DeleteOpeningBalanceTransaction | AE4: DeleteOpeningBalanceTranItem | AF4: GetDayEndCash | AG4: VerifyDayEndCash | AH4: RunRevaluation | AI4: CalculateDayEndCash | AJ4: GetCashTransaction | AK4: SelectCashTransaction | AL4: DeleteCashTransaction | AM4: EditCashTransaction | AN4: AddCashTransaction | AO4: AddOpeningBalanceTransaction | AP4: AddOpeningBalanceTranItem | AQ4: GetDailyCalculationsData | AR4: CalculateDailyCalculations | AS4: EditOpeningBalanceTransaction | AT4: EditOpeningBalanceTranItem | AU4: VerifyDailyCalTransactions | AV4: CloseGeneralLedger | AW4: VerifyAccountDetails | AX4: SaveTransaction
A5: =IFERROR(__xludf.DUMMYFUNCTION("TRANSPOSE(IMPORTRANGE(VLOOKUP($E$3,IMPORTRANGE('_Settings'!$B$3,$C$3&""!A4:B1000""),2,FALSE),$G$3&""!A4:A1000""))"),"") | B5: MasterFund | C5: Accounts | D5: From Date | E5: To Date
B6: SelectAll | C6: Allocation1,Allocation2 | D6: =TODAY() -> 43270 | E6: =TODAY() -> 43270

Sheet RunRevaluation
B1: Data
J2: =VLOOKUP($E$3,'_MasterData'!B4:D1000,3,FALSE) -> #N/A
B3: Module | C3: GeneralLedger | D3: Step | E3: RunRevaluation | F3: Data Format | G3: Input Format
B4: =IFERROR(__xludf.DUMMYFUNCTION("IF(C3="""","""",Transpose(IMPORTRANGE('_Settings'!$B$3,C3&""!A4:A1000"")))"),"GetDataCash") -> GetDataCash | C4: EnterCashDividends | D4: EnterNonTradingTransaction | E4: VerifyCash | F4: VerifyActivity | G4: VerifyTradingTransaction | H4: VerifyRevaluationData | I4: GetTradingTransaction | J4: GetActivityData | K4: GetRevaluationData | L4: GetAccountDetails | M4: GetNonTradingTransaction | N4: GetDividendData | O4: VerifyNonTradingTransaction | P4: VerifyDividend | Q4: GetOpeningBalanceData | R4: GetAccountBalance | S4: SelectNonTradingTransaction | T4: SelectNonTradingTranItem | U4: DeleteNonTradingTransaction | V4: DeleteNonTradingTranItem | W4: AddNonTradingTransaction | X4: AddNonTradingTranItem | Y4: VerifyOpeningBalanceData | Z4: SelectOpeningBalanceTransaction | AA4: SelectOpeningBalanceTranItem | AB4: EditNonTradingTransaction | AC4: EditNonTradingTranItem | AD4: DeleteOpeningBalanceTransaction | AE4: DeleteOpeningBalanceTranItem | AF4: GetDayEndCash | AG4: VerifyDayEndCash | AH4: RunRevaluation | AI4: CalculateDayEndCash | AJ4: GetCashTransaction | AK4: SelectCashTransaction | AL4: DeleteCashTransaction | AM4: EditCashTransaction | AN4: AddCashTransaction | AO4: AddOpeningBalanceTransaction | AP4: AddOpeningBalanceTranItem | AQ4: GetDailyCalculationsData | AR4: CalculateDailyCalculations | AS4: EditOpeningBalanceTransaction | AT4: EditOpeningBalanceTranItem | AU4: VerifyDailyCalTransactions | AV4: CloseGeneralLedger | AW4: VerifyAccountDetails | AX4: SaveTransaction
A5: =IFERROR(__xludf.DUMMYFUNCTION("TRANSPOSE(IMPORTRANGE(VLOOKUP($E$3,IMPORTRANGE('_Settings'!$B$3,$C$3&""!A4:B1000""),2,FALSE),$G$3&""!A4:A1000""))"),"") | B5: MasterFund | C5: Accounts | D5: Balances as on date
B6: Selelct All | C6: Allocation1,Allocation2 | D6: =today() -> 43270

Sheet VerifyRevaluationData
B1: Data
J2: =VLOOKUP($E$3,'_MasterData'!B4:D1000,3,FALSE) -> #N/A
B3: Module | C3: GeneralLedger | D3: Step | E3: VerifyRevaluationData | F3: Data Format | G3: Input Format
B4: =IFERROR(__xludf.DUMMYFUNCTION("IF(C3="""","""",Transpose(IMPORTRANGE('_Settings'!$B$3,C3&""!A4:A1000"")))"),"GetDataCash") -> GetDataCash | C4: EnterCashDividends | D4: EnterNonTradingTransaction | E4: VerifyCash | F4: VerifyActivity | G4: VerifyTradingTransaction | H4: VerifyRevaluationData | I4: GetTradingTransaction | J4: GetActivityData | K4: GetRevaluationData | L4: GetAccountDetails | M4: GetNonTradingTransaction | N4: GetDividendData | O4: VerifyNonTradingTransaction | P4: VerifyDividend | Q4: GetOpeningBalanceData | R4: GetAccountBalance | S4: SelectNonTradingTransaction | T4: SelectNonTradingTranItem | U4: DeleteNonTradingTransaction | V4: DeleteNonTradingTranItem | W4: AddNonTradingTransaction | X4: AddNonTradingTranItem | Y4: VerifyOpeningBalanceData | Z4: SelectOpeningBalanceTransaction | AA4: SelectOpeningBalanceTranItem | AB4: EditNonTradingTransaction | AC4: EditNonTradingTranItem | AD4: DeleteOpeningBalanceTransaction | AE4: DeleteOpeningBalanceTranItem | AF4: GetDayEndCash | AG4: VerifyDayEndCash | AH4: RunRevaluation | AI4: CalculateDayEndCash | AJ4: GetCashTransaction | AK4: SelectCashTransaction | AL4: DeleteCashTransaction | AM4: EditCashTransaction | AN4: AddCashTransaction | AO4: AddOpeningBalanceTransaction | AP4: AddOpeningBalanceTranItem | AQ4: GetDailyCalculationsData | AR4: CalculateDailyCalculations | AS4: EditOpeningBalanceTransaction | AT4: EditOpeningBalanceTranItem | AU4: VerifyDailyCalTransactions | AV4: CloseGeneralLedger | AW4: VerifyAccountDetails | AX4: SaveTransaction
A5: =IFERROR(__xludf.DUMMYFUNCTION("TRANSPOSE(IMPORTRANGE(VLOOKUP($E$3,IMPORTRANGE('_Settings'!$B$3,$C$3&""!A4:B1000""),2,FALSE),$G$3&""!A4:A1000""))"),"") | B5: Date | C5: Account | D5: Symbol | E5: Currency | F5: Cash Sub-Account | G5: DR | H5: CR | I5: Modify Date | J5: Entry Date | K5: User | L5: Fx Rate | M5: FX Conversion Method Operator | N5: Account Side | O5: TransactionSource | P5: Base Currency | Q5: Description | R5: DR (Base) | S5: CR (Base)
B6: =TODAY() -> 43270 | C6: Allocation2 | D6: GOOG | E6: USD | F6: Equity Long Revaluation [Asset]
B7: =TODAY() -> 43270 | C7: Allocation1 | D7: GOOG | E7: USD | F7: Equity Long Revaluation [Asset]
B8: =TODAY() -> 43270 | C8: Allocation2 | D8: AAPL | E8: USD | F8: Equity Long Revaluation [Asset]
B9: =TODAY() -> 43270 | C9: Allocation1 | D9: AAPL | E9: USD | F9: Equity Long Revaluation [Asset]
