Workbook

Sheet _Modules
A1: Modules Info
A3: Modules
A4: =IFERROR(__xludf.DUMMYFUNCTION("IMPORTRANGE('_Settings'!B3,""Modules!A4:L1000"")"),"Allocation") -> Allocation | B4: =IFERROR(__xludf.DUMMYFUNCTION("""COMPUTED_VALUE"""),"Allocate") -> Allocate | C4: =IFERROR(__xludf.DUMMYFUNCTION("""COMPUTED_VALUE"""),"Undefined") -> Undefined
A5: =IFERROR(__xludf.DUMMYFUNCTION("""COMPUTED_VALUE"""),"Allocation") -> Allocation | B5: =IFERROR(__xludf.DUMMYFUNCTION("""COMPUTED_VALUE"""),"CheckAllocatedGroups") -> CheckAllocatedGroups | C5: =IFERROR(__xludf.DUMMYFUNCTION("""COMPUTED_VALUE"""),"17hQQja2JxgHYc91C7e_NxNoHLA89SiPSSBCEIFHCoTk") -> 17hQQja2JxgHYc91C7e_NxNoHLA89SiPSSBCEIFHCoTk
A6: =IFERROR(__xludf.DUMMYFUNCTION("""COMPUTED_VALUE"""),"Allocation") -> Allocation | B6: =IFERROR(__xludf.DUMMYFUNCTION("""COMPUTED_VALUE"""),"GetDataAllocation") -> GetDataAllocation | C6: =IFERROR(__xludf.DUMMYFUNCTION("""COMPUTED_VALUE"""),"108eHf5dlaU-2uUYuHfGgKKJqgdRILzey4i21uN8VBpc") -> 108eHf5dlaU-2uUYuHfGgKKJqgdRILzey4i21uN8VBpc
A7: =IFERROR(__xludf.DUMMYFUNCTION("""COMPUTED_VALUE"""),"Allocation") -> Allocation | B7: =IFERROR(__xludf.DUMMYFUNCTION("""COMPUTED_VALUE"""),"SelectAllocatedGroup") -> SelectAllocatedGroup | C7: =IFERROR(__xludf.DUMMYFUNCTION("""COMPUTED_VALUE"""),"1xOLrriXpynkiEARWECFOoYcCjgpJ_r_B8l8himR40tc") -> 1xOLrriXpynkiEARWECFOoYcCjgpJ_r_B8l8himR40tc
A8: =IFERROR(__xludf.DUMMYFUNCTION("""COMPUTED_VALUE"""),"Allocation") -> Allocation | B8: =IFERROR(__xludf.DUMMYFUNCTION("""COMPUTED_VALUE"""),"EditTradesAllocated") -> EditTradesAllocated | C8: =IFERROR(__xludf.DUMMYFUNCTION("""COMPUTED_VALUE"""),"1czFgc0rQ9Yr0z5XyYhwS9vTzyyW8C_kbFoZotVQvRGU") -> 1czFgc0rQ9Yr0z5XyYhwS9vTzyyW8C_kbFoZotVQvRGU
A9: =IFERROR(__xludf.DUMMYFUNCTION("""COMPUTED_VALUE"""),"Allocation") -> Allocation | B9: =IFERROR(__xludf.DUMMYFUNCTION("""COMPUTED_VALUE"""),"EditTradesUnallocated") -> EditTradesUnallocated | C9: =IFERROR(__xludf.DUMMYFUNCTION("""COMPUTED_VALUE"""),"1IzyG5_6aGu2OE6b5hRX3Fsz__PyNpFOt5iSq6kKmpgs") -> 1IzyG5_6aGu2OE6b5hRX3Fsz__PyNpFOt5iSq6kKmpgs
A10: =IFERROR(__xludf.DUMMYFUNCTION("""COMPUTED_VALUE"""),"Allocation") -> Allocation | B10: =IFERROR(__xludf.DUMMYFUNCTION("""COMPUTED_VALUE"""),"Reallocate") -> Reallocate | C10: =IFERROR(__xludf.DUMMYFUNCTION("""COMPUTED_VALUE"""),"Undefined") -> Undefined
A11: =IFERROR(__xludf.DUMMYFUNCTION("""COMPUTED_VALUE"""),"Blotter") -> Blotter | B11: =IFERROR(__xludf.DUMMYFUNCTION("""COMPUTED_VALUE"""),"ReplaceFillsOnBlotter") -> ReplaceFillsOnBlotter | C11: =IFERROR(__xludf.DUMMYFUNCTION("""COMPUTED_VALUE"""),"1Diy-Nhw7lqGk8BUcJ7_tudF9wi_ZJxiWQvXjEtj0fbg") -> 1Diy-Nhw7lqGk8BUcJ7_tudF9wi_ZJxiWQvXjEtj0fbg
A12: =IFERROR(__xludf.DUMMYFUNCTION("""COMPUTED_VALUE"""),"a") -> a | B12: =IFERROR(__xludf.DUMMYFUNCTION("""COMPUTED_VALUE"""),"1s") -> 1s | C12: =IFERROR(__xludf.DUMMYFUNCTION("""COMPUTED_VALUE"""),"1enUPqyPREGl3f2eye-2V4zEhW4eTEsQWbHsvbHWKlLQ") -> 1enUPqyPREGl3f2eye-2V4zEhW4eTEsQWbHsvbHWKlLQ
A13: =IFERROR(__xludf.DUMMYFUNCTION("""COMPUTED_VALUE"""),"GeneralLedger") -> GeneralLedger | B13: =IFERROR(__xludf.DUMMYFUNCTION("""COMPUTED_VALUE"""),"GetDataCash") -> GetDataCash | C13: =IFERROR(__xludf.DUMMYFUNCTION("""COMPUTED_VALUE"""),"11pF8hppeASHIBEU4fJBPX4H2s826R1k7KA4JaccEGq0") -> 11pF8hppeASHIBEU4fJBPX4H2s826R1k7KA4JaccEGq0
A14: =IFERROR(__xludf.DUMMYFUNCTION("""COMPUTED_VALUE"""),"GeneralLedger") -> GeneralLedger | B14: =IFERROR(__xludf.DUMMYFUNCTION("""COMPUTED_VALUE"""),"EnterCashDividends") -> EnterCashDividends | C14: =IFERROR(__xludf.DUMMYFUNCTION("""COMPUTED_VALUE"""),"1qI9l0oxajDKeZluTNrlCeeZ28QX8NkbvZl6ujxbGJnI") -> 1qI9l0oxajDKeZluTNrlCeeZ28QX8NkbvZl6ujxbGJnI
A15: =IFERROR(__xludf.DUMMYFUNCTION("""COMPUTED_VALUE"""),"GeneralLedger") -> GeneralLedger | B15: =IFERROR(__xludf.DUMMYFUNCTION("""COMPUTED_VALUE"""),"EnterNonTradingTransaction") -> EnterNonTradingTransaction | C15: =IFERROR(__xludf.DUMMYFUNCTION("""COMPUTED_VALUE"""),"1n0XgxxbStGy3VjvQS309fIpzG_L1vcwVX484ib8d3QU") -> 1n0XgxxbStGy3VjvQS309fIpzG_L1vcwVX484ib8d3QU
A16: =IFERROR(__xludf.DUMMYFUNCTION("""COMPUTED_VALUE"""),"GeneralLedger") -> GeneralLedger | B16: =IFERROR(__xludf.DUMMYFUNCTION("""COMPUTED_VALUE"""),"VerifyCash") -> VerifyCash | C16: =IFERROR(__xludf.DUMMYFUNCTION("""COMPUTED_VALUE"""),"1dm_rO3DsjDpe_rov3TM-pXjFB8WSzw6eN-gEqIFDT2M") -> 1dm_rO3DsjDpe_rov3TM-pXjFB8WSzw6eN-gEqIFDT2M
A17: =IFERROR(__xludf.DUMMYFUNCTION("""COMPUTED_VALUE"""),"GeneralLedger") -> GeneralLedger | B17: =IFERROR(__xludf.DUMMYFUNCTION("""COMPUTED_VALUE"""),"VerifyActivity") -> VerifyActivity | C17: =IFERROR(__xludf.DUMMYFUNCTION("""COMPUTED_VALUE"""),"1n2_KWleIEyqXIdrb2wBU9n9HG3wOCbtLJiXuNliDxbo") -> 1n2_KWleIEyqXIdrb2wBU9n9HG3wOCbtLJiXuNliDxbo
A18: =IFERROR(__xludf.DUMMYFUNCTION("""COMPUTED_VALUE"""),"GeneralLedger") -> GeneralLedger | B18: =IFERROR(__xludf.DUMMYFUNCTION("""COMPUTED_VALUE"""),"VerifyTradingTransaction") -> VerifyTradingTransaction | C18: =IFERROR(__xludf.DUMMYFUNCTION("""COMPUTED_VALUE"""),"1HUrg5HC-uhaySvPqKlbfDJy_tRqbpd3tG5-BRQbvQNE") -> 1HUrg5HC-uhaySvPqKlbfDJy_tRqbpd3tG5-BRQbvQNE
A19: =IFERROR(__xludf.DUMMYFUNCTION("""COMPUTED_VALUE"""),"GeneralLedger") -> GeneralLedger | B19: =IFERROR(__xludf.DUMMYFUNCTION("""COMPUTED_VALUE"""),"VerifyRevaluationData") -> VerifyRevaluationData | C19: =IFERROR(__xludf.DUMMYFUNCTION("""COMPUTED_VALUE"""),"1ogDmXxmcH2S6ctXbFXoGdWmaCJRo_ECxi411UEwWYtk") -> 1ogDmXxmcH2S6ctXbFXoGdWmaCJRo_ECxi411UEwWYtk
A20: =IFERROR(__xludf.DUMMYFUNCTION("""COMPUTED_VALUE"""),"CorporateAction") -> CorporateAction | B20: =IFERROR(__xludf.DUMMYFUNCTION("""COMPUTED_VALUE"""),"CorporateAction") -> CorporateAction | C20: =IFERROR(__xludf.DUMMYFUNCTION("""COMPUTED_VALUE"""),"15KSHSnHyfcV68P-BAz-qSKIAViB6QpZ5pCYmrYItUS4") -> 15KSHSnHyfcV68P-BAz-qSKIAViB6QpZ5pCYmrYItUS4
A21: =IFERROR(__xludf.DUMMYFUNCTION("""COMPUTED_VALUE"""),"CreateTransaction") -> CreateTransaction | B21: =IFERROR(__xludf.DUMMYFUNCTION("""COMPUTED_VALUE"""),"CreateTransaction") -> CreateTransaction | C21: =IFERROR(__xludf.DUMMYFUNCTION("""COMPUTED_VALUE"""),"1JZcaOlNrERZ2pJDJY1f-UuSxW_EJa6FmaMW4Ng69G-Y") -> 1JZcaOlNrERZ2pJDJY1f-UuSxW_EJa6FmaMW4Ng69G-Y
A22: =IFERROR(__xludf.DUMMYFUNCTION("""COMPUTED_VALUE"""),"DailyValuation") -> DailyValuation | B22: =IFERROR(__xludf.DUMMYFUNCTION("""COMPUTED_VALUE"""),"UpdateBeta") -> UpdateBeta | C22: =IFERROR(__xludf.DUMMYFUNCTION("""COMPUTED_VALUE"""),"14bzYQBiZIs2a3lfzwT4TROCDnXpt72UALcJjBTZdEAk") -> 14bzYQBiZIs2a3lfzwT4TROCDnXpt72UALcJjBTZdEAk
A23: =IFERROR(__xludf.DUMMYFUNCTION("""COMPUTED_VALUE"""),"DailyValuation") -> DailyValuation | B23: =IFERROR(__xludf.DUMMYFUNCTION("""COMPUTED_VALUE"""),"UpdateDailyCash") -> UpdateDailyCash | C23: =IFERROR(__xludf.DUMMYFUNCTION("""COMPUTED_VALUE"""),"1qlSfNvUHenegqRyv9ZFeKA5gN-iwbykaaRHcYfx0vR8") -> 1qlSfNvUHenegqRyv9ZFeKA5gN-iwbykaaRHcYfx0vR8
A24: =IFERROR(__xludf.DUMMYFUNCTION("""COMPUTED_VALUE"""),"DailyValuation") -> DailyValuation | B24: =IFERROR(__xludf.DUMMYFUNCTION("""COMPUTED_VALUE"""),"UpdateMultipleDailyCash") -> UpdateMultipleDailyCash | C24: =IFERROR(__xludf.DUMMYFUNCTION("""COMPUTED_VALUE"""),"1hVwFlW5MKD4NHZXvDHfS6l0ApW93ZHmg5lFN4Tn10aY") -> 1hVwFlW5MKD4NHZXvDHfS6l0ApW93ZHmg5lFN4Tn10aY
A25: =IFERROR(__xludf.DUMMYFUNCTION("""COMPUTED_VALUE"""),"DailyValuation") -> DailyValuation | B25: =IFERROR(__xludf.DUMMYFUNCTION("""COMPUTED_VALUE"""),"UpdateForexConversion") -> UpdateForexConversion | C25: =IFERROR(__xludf.DUMMYFUNCTION("""COMPUTED_VALUE"""),"1ovsWSW4IX_ESJf6L_l_o3LFV2g37EWvXALJwiSoMOOk") -> 1ovsWSW4IX_ESJf6L_l_o3LFV2g37EWvXALJwiSoMOOk
A26: =IFERROR(__xludf.DUMMYFUNCTION("""COMPUTED_VALUE"""),"DailyValuation") -> DailyValuation | B26: =IFERROR(__xludf.DUMMYFUNCTION("""COMPUTED_VALUE"""),"UpdateMarkPrice") -> UpdateMarkPrice | C26: =IFERROR(__xludf.DUMMYFUNCTION("""COMPUTED_VALUE"""),"16KBVroR_j9VfEeynsJjMmeERh-LHCXp_Q3zfX2ptUbk") -> 16KBVroR_j9VfEeynsJjMmeERh-LHCXp_Q3zfX2ptUbk
A27: =IFERROR(__xludf.DUMMYFUNCTION("""COMPUTED_VALUE"""),"Import") -> Import | B27: =IFERROR(__xludf.DUMMYFUNCTION("""COMPUTED_VALUE"""),"Import") -> Import | C27: =IFERROR(__xludf.DUMMYFUNCTION("""COMPUTED_VALUE"""),"1_vNaQNw1K3VUjBqTVyF_y9hpe8G2ewy1wQSeMFKnIsw") -> 1_vNaQNw1K3VUjBqTVyF_y9hpe8G2ewy1wQSeMFKnIsw
A28: =IFERROR(__xludf.DUMMYFUNCTION("""COMPUTED_VALUE"""),"PortfolioManagement") -> PortfolioManagement | B28: =IFERROR(__xludf.DUMMYFUNCTION("""COMPUTED_VALUE"""),"CheckDashboardPM") -> CheckDashboardPM | C28: =IFERROR(__xludf.DUMMYFUNCTION("""COMPUTED_VALUE"""),"1XML_rKDwoATUqQEdSmAgWZeBq0nRAO-QFlPnVgX1Uac") -> 1XML_rKDwoATUqQEdSmAgWZeBq0nRAO-QFlPnVgX1Uac
A29: =IFERROR(__xludf.DUMMYFUNCTION("""COMPUTED_VALUE"""),"PortfolioManagement") -> PortfolioManagement | B29: =IFERROR(__xludf.DUMMYFUNCTION("""COMPUTED_VALUE"""),"CheckPortfolioManagement") -> CheckPortfolioManagement | C29: =IFERROR(__xludf.DUMMYFUNCTION("""COMPUTED_VALUE"""),"10mJBbfEKw8miuRHDwCV7_-8V_E3ZX1n6jlsC5kfflVY") -> 10mJBbfEKw8miuRHDwCV7_-8V_E3ZX1n6jlsC5kfflVY
A30: =IFERROR(__xludf.DUMMYFUNCTION("""COMPUTED_VALUE"""),"PortfolioManagement") -> PortfolioManagement | B30: =IFERROR(__xludf.DUMMYFUNCTION("""COMPUTED_VALUE"""),"CheckPMLiveFeed") -> CheckPMLiveFeed | C30: =IFERROR(__xludf.DUMMYFUNCTION("""COMPUTED_VALUE"""),"1Q4XgYTYb3ng95eo0AHEW34QHB-UqihXSsfRcQQpkVXw") -> 1Q4XgYTYb3ng95eo0AHEW34QHB-UqihXSsfRcQQpkVXw
A31: =IFERROR(__xludf.DUMMYFUNCTION("""COMPUTED_VALUE"""),"PricingInput") -> PricingInput | B31: =IFERROR(__xludf.DUMMYFUNCTION("""COMPUTED_VALUE"""),"PricingInput") -> PricingInput | C31: =IFERROR(__xludf.DUMMYFUNCTION("""COMPUTED_VALUE"""),"1oej4n4PC8RE49pB4-TiWxTqbDPyninh9e03DcCsTU80") -> 1oej4n4PC8RE49pB4-TiWxTqbDPyninh9e03DcCsTU80
A32: =IFERROR(__xludf.DUMMYFUNCTION("""COMPUTED_VALUE"""),"PricingInput") -> PricingInput | B32: =IFERROR(__xludf.DUMMYFUNCTION("""COMPUTED_VALUE"""),"UpdateSharesOutstanding") -> UpdateSharesOutstanding | C32: =IFERROR(__xludf.DUMMYFUNCTION("""COMPUTED_VALUE"""),"1crnQkc3JZblrRatY8QxWLuk7JnchsXg0e_CyrN38bbE") -> 1crnQkc3JZblrRatY8QxWLuk7JnchsXg0e_CyrN38bbE
A33: =IFERROR(__xludf.DUMMYFUNCTION("""COMPUTED_VALUE"""),"SymbolLookup") -> SymbolLookup | B33: =IFERROR(__xludf.DUMMYFUNCTION("""COMPUTED_VALUE"""),"VerifySymbolLookUp") -> VerifySymbolLookUp | C33: =IFERROR(__xludf.DUMMYFUNCTION("""COMPUTED_VALUE"""),"1YWFFwFn67kSD8UqbzR_g6NbGZ9pjemCMVA9QmSA4_S8") -> 1YWFFwFn67kSD8UqbzR_g6NbGZ9pjemCMVA9QmSA4_S8
A34: =IFERROR(__xludf.DUMMYFUNCTION("""COMPUTED_VALUE"""),"SymbolLookup") -> SymbolLookup | B34: =IFERROR(__xludf.DUMMYFUNCTION("""COMPUTED_VALUE"""),"SymbolLookupFromTT") -> SymbolLookupFromTT | C34: =IFERROR(__xludf.DUMMYFUNCTION("""COMPUTED_VALUE"""),"1gDvMDcnV_Cq-gd3uSiTszH4Q8IYBAMQu9lTMq8Rpy3o") -> 1gDvMDcnV_Cq-gd3uSiTszH4Q8IYBAMQu9lTMq8Rpy3o
A35: =IFERROR(__xludf.DUMMYFUNCTION("""COMPUTED_VALUE"""),"SymbolLookup") -> SymbolLookup | B35: =IFERROR(__xludf.DUMMYFUNCTION("""COMPUTED_VALUE"""),"UpdateUDA") -> UpdateUDA | C35: =IFERROR(__xludf.DUMMYFUNCTION("""COMPUTED_VALUE"""),"1dhqVPgdlk0qqXkJ78cDzBf_Mq3MegKBc6RXPw3xiPrw") -> 1dhqVPgdlk0qqXkJ78cDzBf_Mq3MegKBc6RXPw3xiPrw
A36: =IFERROR(__xludf.DUMMYFUNCTION("""COMPUTED_VALUE"""),"SymbolLookup") -> SymbolLookup | B36: =IFERROR(__xludf.DUMMYFUNCTION("""COMPUTED_VALUE"""),"GetSymbol") -> GetSymbol | C36: =IFERROR(__xludf.DUMMYFUNCTION("""COMPUTED_VALUE"""),"173hAXGieMVvXY5pe0UbKu68RfryU3RaXKikGhyg-rOo") -> 173hAXGieMVvXY5pe0UbKu68RfryU3RaXKikGhyg-rOo
A37: =IFERROR(__xludf.DUMMYFUNCTION("""COMPUTED_VALUE"""),"SymbolLookup") -> SymbolLookup | B37: =IFERROR(__xludf.DUMMYFUNCTION("""COMPUTED_VALUE"""),"GetDataSymbolLookup") -> GetDataSymbolLookup | C37: =IFERROR(__xludf.DUMMYFUNCTION("""COMPUTED_VALUE"""),"1NAyBh7MvMUe-ymIgaMjhvCcTdXRrdfoOqa5k2oEkEtY") -> 1NAyBh7MvMUe-ymIgaMjhvCcTdXRrdfoOqa5k2oEkEtY
A38: =IFERROR(__xludf.DUMMYFUNCTION("""COMPUTED_VALUE"""),"SymbolLookup") -> SymbolLookup | B38: =IFERROR(__xludf.DUMMYFUNCTION("""COMPUTED_VALUE"""),"DeleteValidateSymbol") -> DeleteValidateSymbol | C38: =IFERROR(__xludf.DUMMYFUNCTION("""COMPUTED_VALUE"""),"1WIb_XXxmZPR_GUhoObQfZ6l1pKvOl5CWOE5mnz2ftU0") -> 1WIb_XXxmZPR_GUhoObQfZ6l1pKvOl5CWOE5mnz2ftU0
A39: =IFERROR(__xludf.DUMMYFUNCTION("""COMPUTED_VALUE"""),"ThirdParty") -> ThirdParty | B39: =IFERROR(__xludf.DUMMYFUNCTION("""COMPUTED_VALUE"""),"GenerateThirdParty") -> GenerateThirdParty | C39: =IFERROR(__xludf.DUMMYFUNCTION("""COMPUTED_VALUE"""),"1MME0WB8RmCV2QKgHuWbTvubmaZmPuF0knOKGp2GUg7o") -> 1MME0WB8RmCV2QKgHuWbTvubmaZmPuF0knOKGp2GUg7o
A40: =IFERROR(__xludf.DUMMYFUNCTION("""COMPUTED_VALUE"""),"ThirdParty") -> ThirdParty | B40: =IFERROR(__xludf.DUMMYFUNCTION("""COMPUTED_VALUE"""),"SendThirdParty") -> SendThirdParty | C40: =IFERROR(__xludf.DUMMYFUNCTION("""COMPUTED_VALUE"""),"1Rq8zeuYkGxaBxmemqN7Z1OVWnaheHVEDxVozT52myRI") -> 1Rq8zeuYkGxaBxmemqN7Z1OVWnaheHVEDxVozT52myRI
A41: =IFERROR(__xludf.DUMMYFUNCTION("""COMPUTED_VALUE"""),"ThirdParty") -> ThirdParty | B41: =IFERROR(__xludf.DUMMYFUNCTION("""COMPUTED_VALUE"""),"ViewThirdParty") -> ViewThirdParty | C41: =IFERROR(__xludf.DUMMYFUNCTION("""COMPUTED_VALUE"""),"1UalkAEsbJcZQAzEnT3T29et4u4PKQ3n66SBTt1HPqVc") -> 1UalkAEsbJcZQAzEnT3T29et4u4PKQ3n66SBTt1HPqVc
...

Sheet _Settings
A1: Settings
A3: Module Step Setting File | B3: 1ua6ENR4AYwAWggYDcO5ubv4JU_7oqW8hUziMaEUEncQ
A4: Master Data Settings File | B4: 1Nt_rf5DtgjbN9Ag4AMMlUkZYROxKZLH5m54YOl7tRT0

Sheet _MasterData
A1: Master Data Info
A3: Module | B3: Step | C3: Master Data Sheet
A4: =IFERROR(__xludf.DUMMYFUNCTION("IMPORTRANGE('_Settings'!B4,""Master Data!A4:L1000"")"),"#REF!") -> #REF!

Sheet CreateDoneAwayOrder
B1: Data
J2: =VLOOKUP($E$3,'_MasterData'!B4:D1000,3,FALSE) -> #N/A
B3: Module | C3: TradingTicket | D3: Step | E3: CreateDoneAwayOrder | F3: Data Format | G3: Input Format
B4: =IFERROR(__xludf.DUMMYFUNCTION("IF(C3="""","""",Transpose(IMPORTRANGE('_Settings'!$B$3,C3&""!A4:A1000"")))"),"#REF!") -> #REF! | C4: EnterDetailsOnTT | D4: ValidateSymbolTT | E4: VerifyDataTT | F4: SetUIPreferencesTT | G4: SetBrokerWisePreferencesTT | H4: TradeNewSub | I4: CreateStageOrder | J4: CreateReplaceOrder | K4: SetGeneralPreference | L4: CreateDoneAwayOrder | M4: CreateNewSubOrder | N4: TradeBloomberg | O4: ClickSymbolLookup | P4: VerifyTT | Q4: CreateLiveOrder
A5: =IFERROR(__xludf.DUMMYFUNCTION("TRANSPOSE(IMPORTRANGE(VLOOKUP($E$3,IMPORTRANGE('_Settings'!$B$3,$C$3&""!A4:B1000""),2,FALSE),$G$3&""!A4:A1000""))"),"") | B5: =IFERROR(__xludf.DUMMYFUNCTION("""COMPUTED_VALUE"""),"Symbol") -> Symbol | C5: =IFERROR(__xludf.DUMMYFUNCTION("""COMPUTED_VALUE"""),"Order Side") -> Order Side | D5: =IFERROR(__xludf.DUMMYFUNCTION("""COMPUTED_VALUE"""),"Quantity") -> Quantity | E5: =IFERROR(__xludf.DUMMYFUNCTION("""COMPUTED_VALUE"""),"TargetQuantityIn") -> TargetQuantityIn | F5: =IFERROR(__xludf.DUMMYFUNCTION("""COMPUTED_VALUE"""),"AllocationMethod") -> AllocationMethod | G5: =IFERROR(__xludf.DUMMYFUNCTION("""COMPUTED_VALUE"""),"Broker") -> Broker | H5: =IFERROR(__xludf.DUMMYFUNCTION("""COMPUTED_VALUE"""),"TIF") -> TIF | I5: =IFERROR(__xludf.DUMMYFUNCTION("""COMPUTED_VALUE"""),"Order Type") -> Order Type | J5: =IFERROR(__xludf.DUMMYFUNCTION("""COMPUTED_VALUE"""),"Price") -> Price | K5: =IFERROR(__xludf.DUMMYFUNCTION("""COMPUTED_VALUE"""),"Stop") -> Stop | L5: =IFERROR(__xludf.DUMMYFUNCTION("""COMPUTED_VALUE"""),"Limit") -> Limit | M5: =IFERROR(__xludf.DUMMYFUNCTION("""COMPUTED_VALUE"""),"Strategy") -> Strategy | N5: =IFERROR(__xludf.DUMMYFUNCTION("""COMPUTED_VALUE"""),"Trade Date") -> Trade Date | O5: =IFERROR(__xludf.DUMMYFUNCTION("""COMPUTED_VALUE"""),"FxRate") -> FxRate | P5: =IFERROR(__xludf.DUMMYFUNCTION("""COMPUTED_VALUE"""),"Notes") -> Notes | Q5: =IFERROR(__xludf.DUMMYFUNCTION("""COMPUTED_VALUE"""),"Broker Notes") -> Broker Notes | R5: =IFERROR(__xludf.DUMMYFUNCTION("""COMPUTED_VALUE"""),"CommissionBasis") -> CommissionBasis | S5: =IFERROR(__xludf.DUMMYFUNCTION("""COMPUTED_VALUE"""),"CommissionRate") -> CommissionRate | T5: =IFERROR(__xludf.DUMMYFUNCTION("""COMPUTED_VALUE"""),"SoftBasis") -> SoftBasis | U5: =IFERROR(__xludf.DUMMYFUNCTION("""COMPUTED_VALUE"""),"SoftRate") -> SoftRate | V5: =IFERROR(__xludf.DUMMYFUNCTION("""COMPUTED_VALUE"""),"TradeAttribute1") -> TradeAttribute1 | W5: =IFERROR(__xludf.DUMMYFUNCTION("""COMPUTED_VALUE"""),"TradeAttribute2") -> TradeAttribute2 | X5: =IFERROR(__xludf.DUMMYFUNCTION("""COMPUTED_VALUE"""),"TradeAttribute3") -> TradeAttribute3 | Y5: =IFERROR(__xludf.DUMMYFUNCTION("""COMPUTED_VALUE"""),"TradeAttribute4") -> TradeAttribute4 | Z5: =IFERROR(__xludf.DUMMYFUNCTION("""COMPUTED_VALUE"""),"TradeAttribute5") -> TradeAttribute5 | AA5: =IFERROR(__xludf.DUMMYFUNCTION("""COMPUTED_VALUE"""),"TradeAttribute6") -> TradeAttribute6 | AB5: =IFERROR(__xludf.DUMMYFUNCTION("""COMPUTED_VALUE"""),"Venue") -> Venue | AC5: =IFERROR(__xludf.DUMMYFUNCTION("""COMPUTED_VALUE"""),"ExecutionInstructions") -> ExecutionInstructions | AD5: =IFERROR(__xludf.DUMMYFUNCTION("""COMPUTED_VALUE"""),"HandlingInstructions") -> HandlingInstructions | AE5: =IFERROR(__xludf.DUMMYFUNCTION("""COMPUTED_VALUE"""),"Trader") -> Trader | AF5: =IFERROR(__xludf.DUMMYFUNCTION("""COMPUTED_VALUE"""),"SettlementCurrency") -> SettlementCurrency | AG5: =IFERROR(__xludf.DUMMYFUNCTION("""COMPUTED_VALUE"""),"SettlementFXRate") -> SettlementFXRate | AH5: =IFERROR(__xludf.DUMMYFUNCTION("""COMPUTED_VALUE"""),"SettlementAmount") -> SettlementAmount | AI5: =IFERROR(__xludf.DUMMYFUNCTION("""COMPUTED_VALUE"""),"SettlementFXOperator") -> SettlementFXOperator | AJ5: =IFERROR(__xludf.DUMMYFUNCTION("""COMPUTED_VALUE"""),"SettleByBroker") -> SettleByBroker | AK5: =IFERROR(__xludf.DUMMYFUNCTION("""COMPUTED_VALUE"""),"Account") -> Account | AL5: =IFERROR(__xludf.DUMMYFUNCTION("""COMPUTED_VALUE"""),"Account %") -> Account % | AM5: =IFERROR(__xludf.DUMMYFUNCTION("""COMPUTED_VALUE"""),"Deal In") -> Deal In | AN5: =IFERROR(__xludf.DUMMYFUNCTION("""COMPUTED_VALUE"""),"ChkBoxBookAsSwap") -> ChkBoxBookAsSwap | AO5: =IFERROR(__xludf.DUMMYFUNCTION("""COMPUTED_VALUE"""),"PopUpQuantity") -> PopUpQuantity | AP5: =IFERROR(__xludf.DUMMYFUNCTION("""COMPUTED_VALUE"""),"ShortLocate") -> ShortLocate | AQ5: =IFERROR(__xludf.DUMMYFUNCTION("""COMPUTED_VALUE"""),"AllowTrade") -> AllowTrade | AR5: =IFERROR(__xludf.DUMMYFUNCTION("""COMPUTED_VALUE"""),"SharesOutstandingPopUpQty") -> SharesOutstandingPopUpQty | AS5: =IFERROR(__xludf.DUMMYFUNCTION("""COMPUTED_VALUE"""),"SharesOutstandingPopUp") -> SharesOutstandingPopUp | AT5: =IFERROR(__xludf.DUMMYFUNCTION("""COMPUTED_VALUE"""),"ResAllowedListPopUp") -> ResAllowedListPopUp | AU5: =IFERROR(__xludf.DUMMYFUNCTION("""COMPUTED_VALUE"""),"Rate(%)") -> Rate(%) | AV5: =IFERROR(__xludf.DUMMYFUNCTION("""COMPUTED_VALUE"""),"Interest Rate") -> Interest Rate | AW5: =IFERROR(__xludf.DUMMYFUNCTION("""COMPUTED_VALUE"""),"SelectAlgoStrategy") -> SelectAlgoStrategy | AX5: =IFERROR(__xludf.DUMMYFUNCTION("""COMPUTED_VALUE"""),"Increase/Decrease Quantity") -> Increase/Decrease Quantity | AY5: =IFERROR(__xludf.DUMMYFUNCTION("""COMPUTED_VALUE"""),"Master Funds") -> Master Funds | AZ5: =IFERROR(__xludf.DUMMYFUNCTION("""COMPUTED_VALUE"""),"TRVAccountName") -> TRVAccountName | BA5: =IFERROR(__xludf.DUMMYFUNCTION("""COMPUTED_VALUE"""),"TRVTradeQuantity") -> TRVTradeQuantity | BB5: =IFERROR(__xludf.DUMMYFUNCTION("""COMPUTED_VALUE"""),"TRVCurrentPosition") -> TRVCurrentPosition | BC5: =IFERROR(__xludf.DUMMYFUNCTION("""COMPUTED_VALUE"""),"TRVNav") -> TRVNav | BD5: =IFERROR(__xludf.DUMMYFUNCTION("""COMPUTED_VALUE"""),"Account QTY") -> Account QTY | BE5: =IFERROR(__xludf.DUMMYFUNCTION("""COMPUTED_VALUE"""),"DoneAwayClickOnNO") -> DoneAwayClickOnNO | BF5: =IFERROR(__xludf.DUMMYFUNCTION("""COMPUTED_VALUE"""),"HotbuttonQty") -> HotbuttonQty | BG5: =IFERROR(__xludf.DUMMYFUNCTION("""COMPUTED_VALUE"""),"HotButtonPrice") -> HotButtonPrice | BH5: =IFERROR(__xludf.DUMMYFUNCTION("""COMPUTED_VALUE"""),"HotButtonLimit") -> HotButtonLimit | BI5: =IFERROR(__xludf.DUMMYFUNCTION("""COMPUTED_VALUE"""),"HotButtonStop") -> HotButtonStop | BJ5: =IFERROR(__xludf.DUMMYFUNCTION("""COMPUTED_VALUE"""),"Broker PadLock") -> Broker PadLock | BK5: =IFERROR(__xludf.DUMMYFUNCTION("""COMPUTED_VALUE"""),"TradeBy") -> TradeBy | BL5: =IFERROR(__xludf.DUMMYFUNCTION("""COMPUTED_VALUE"""),"PendingApprovalPopUp") -> PendingApprovalPopUp
B6: EF828225 | C6: Buy | D6: 100 | E6: 100 | F6: Allocation1 | G6: GS | J6: 14 | N6: 43290 | O6: 1.5 | R6: Flat Amount | S6: 70 | T6: Flat Amount | U6: 10
B7: EF828225 | C7: Sell | D7: 50 | E7: 50 | F7: Allocation1 | G7: GS | J7: 12 | N7: 43292 | O7: 1.8 | R7: Flat Amount | S7: 30 | T7: Flat Amount | U7: 10

Sheet GetDataAllocation
B1: Data
J2: =VLOOKUP($E$3,'_MasterData'!B4:D1000,3,FALSE) -> #N/A
B3: Module | C3: Allocation | D3: Step | E3: GetDataAllocation | F3: Data Format | G3: Input Format
B4: =IFERROR(__xludf.DUMMYFUNCTION("IF(C3="""","""",Transpose(IMPORTRANGE('_Settings'!$B$3,C3&""!A4:A1000"")))"),"#REF!") -> #REF! | C4: CheckAllocatedGroups | D4: Unallocate | E4: GetDataAllocation | F4: SelectAllocatedGroup | G4: EditTradesAllocated | H4: EditTradesUnallocated | I4: Reallocate | J4: CleanUp | K4: EditUnallocatedGroupSidePanel | L4: TradeAttributeBulkChange | M4: ApplyBulkUpdateOnGroups | N4: ApplyPrefetchFilters | O4: GeneralPreferencesDefaultRule | P4: GeneralPrefCompanyUserWise | Q4: RenameTradeAttributes | R4: SetGroupingRules | S4: SetMasterFundRatio | T4: CheckFixedPreference | U4: GetFixedPreference | V4: AddCalculatedPreferences | W4: BulkChangeCalculatedPreferences | X4: DeleteCalculatedPreferences | Y4: RenameCalculatedPreferences | Z4: CopyCalculatedPreferences | AA4: RunAutoGroup | AB4: BookOrUpdateSwap | AC4: RunProrata | AD4: SetDefaultRuleCalculatedPref | AE4: SetAccountValueCalculatedPref | AF4: TradeAttributeBulkChangeGroups | AG4: TradeAttributeBulkChangeTaxlots | AH4: AddCalculatedPreferenceToolbar | AI4: SetStrategyValueCalculatedPref | AJ4: ApplyBulkUpdateOnTaxlots | AK4: CommissionBulkChangeOnGroups | AL4: CommissionBulkChangeOnTaxlots | AM4: SelectUnallocatedGroup | AN4: EnterAccountValuesToAllocate | AO4: EnterAllocatePreference | AP4: EnterStrategyValuesToAllocate | AQ4: CopyCalculatedPreferenceToolbar | AR4: SetGeneralRuleCalculatedPref | AS4: ExportAllCalculatedPreferences | AT4: SaveCalculatedPreferences | AU4: SaveCalculatedPreferences | AV4: CloseCalculatedPreferences | AW4: ExportCalculatedPreference | AX4: ImportCalculatedPreferences | AY4: OpenAuditTrailUnallocatedGroup | AZ4: DeleteCalculatedPreferencesTool | BA4: ImportCalculatedPreferencesTool | BB4: ExportAllCalculatedPreferTool | BC4: OpenAuditTrailAllocatedGroup | BD4: OpenSymbolLookupUnallocateGroup | BE4: OpenSymbolLookupAllocatedGroup | BF4: DeleteFixedPreference | BG4: EditAllocatedGroupSidePanel | BH4: CheckUnallocatedGroups | BI4: SetGeneralPreferences | BJ4: UngroupTrades | BK4: GroupTrades | BL4: DeleteGroup | BM4: CloseOrder | BN4: Unallocate | BO4: CloseAllocation | BP4: UpdateGRAccountValue | BQ4: UpdateGRStrategyValue | BR4: UpdateGRDefaultRule | BS4: UpdateGeneralRulePref | BT4: ModifyGRPreferenceValues | BU4: AddMFPreferences | BV4: AddMFPreferenceToolbar | BW4: DeleteMFPreferences | BX4: DeleteMFPreferenceToolbar | BY4: RenameMFPreferences | BZ4: SaveCloseMFPreference | CA4: SetMFPrefAccountValues | CB4: ModifyMFPrefGeneralRuleValues | CC4: SetMFPrefStrategyValues | CD4: SetMFPrefGeneralRule | CE4: SetMFPrefFundDistribution | CF4: SetMFPreferencesDefaultRule | CG4: SetMFPrefFundDefaultRule | CH4: ClearPrefetchFilters | CI4: ExpandCollapseAllUnallocated | CJ4: ExpandCollapseAllAllocated | CK4: GenerateCashTransaction | CL4: SaveAllocation | CM4: SaveAllocation | CN4: UnallocateWithOutSave | CO4: EditUnallocatedGrid | CP4: EditAllocatedGrid | CQ4: SaveLayoutAllocatedGrid | CR4: SaveLayoutUnallocatedGrid | CS4: SaveLayoutAllocationUI | CT4: ClearFiltersAllocatedGrid | CU4: ClearFiltersUnallocatedGrid | CV4: VerifyLayoutAllocatedGrid | CW4: VerifyLayoutUnallocatedGrid | CX4: BookOrUpdateSwap | CY4: RunProrata
A5: =IFERROR(__xludf.DUMMYFUNCTION("TRANSPOSE(IMPORTRANGE(VLOOKUP($E$3,IMPORTRANGE('_Settings'!$B$3,$C$3&""!A4:B1000""),2,FALSE),$G$3&""!A4:A1000""))"),"") | B5: =IFERROR(__xludf.DUMMYFUNCTION("""COMPUTED_VALUE"""),"RangeType") -> RangeType | C5: =IFERROR(__xludf.DUMMYFUNCTION("""COMPUTED_VALUE"""),"From") -> From | D5: =IFERROR(__xludf.DUMMYFUNCTION("""COMPUTED_VALUE"""),"To") -> To | E5: =IFERROR(__xludf.DUMMYFUNCTION("""COMPUTED_VALUE"""),"FilterTabName") -> FilterTabName | F5: =IFERROR(__xludf.DUMMYFUNCTION("""COMPUTED_VALUE"""),"Symbol") -> Symbol | G5: =IFERROR(__xludf.DUMMYFUNCTION("""COMPUTED_VALUE"""),"Asset") -> Asset | H5: =IFERROR(__xludf.DUMMYFUNCTION("""COMPUTED_VALUE"""),"Side") -> Side | I5: =IFERROR(__xludf.DUMMYFUNCTION("""COMPUTED_VALUE"""),"Account") -> Account | J5: =IFERROR(__xludf.DUMMYFUNCTION("""COMPUTED_VALUE"""),"Broker") -> Broker | K5: =IFERROR(__xludf.DUMMYFUNCTION("""COMPUTED_VALUE"""),"Currency") -> Currency | L5: =IFERROR(__xludf.DUMMYFUNCTION("""COMPUTED_VALUE"""),"Exchange") -> Exchange | M5: =IFERROR(__xludf.DUMMYFUNCTION("""COMPUTED_VALUE"""),"StrategyName") -> StrategyName | N5: =IFERROR(__xludf.DUMMYFUNCTION("""COMPUTED_VALUE"""),"Underlying") -> Underlying | O5: =IFERROR(__xludf.DUMMYFUNCTION("""COMPUTED_VALUE"""),"Venue") -> Venue | P5: =IFERROR(__xludf.DUMMYFUNCTION("""COMPUTED_VALUE"""),"TradingAccount") -> TradingAccount | Q5: =IFERROR(__xludf.DUMMYFUNCTION("""COMPUTED_VALUE"""),"PreAllocated") -> PreAllocated | R5: =IFERROR(__xludf.DUMMYFUNCTION("""COMPUTED_VALUE"""),"ManualGroup") -> ManualGroup
B6: Historical | C6: 43290 | D6: 43294

Sheet GetMarkPriceData
B1: Data
J2: =VLOOKUP($E$3,'_MasterData'!B4:D1000,3,FALSE) -> #N/A
B3: Module | C3: DailyValuation | D3: Step | E3: GetMarkPriceData | F3: Data Format | G3: Input Format
B4: =IFERROR(__xludf.DUMMYFUNCTION("IF(C3="""","""",Transpose(IMPORTRANGE('_Settings'!$B$3,C3&""!A4:A1000"")))"),"#REF!") -> #REF! | C4: UpdateDailyCash | D4: UpdateForexConversion | E4: UpdateMarkPrice | F4: CleanUp | G4: GetMarkPriceData | H4: GetForwardPoints | I4: UpdateForwardPoints | J4: DeleteNAV | K4: GetForexConversion | L4: GetDailyCash | M4: GetDailyBeta | N4: GetDailyVolatility | O4: GetDailyDividendYield | P4: GetDailyTradingVolume | Q4: GetDailyOutstandings | R4: GetDailyDelta | S4: UpdateDailyVolatility | T4: UpdateDividendYield | U4: UpdateTradingVolume | V4: UpdateDailyDelta | W4: UpdateDailyOutstandings | X4: UpdateBeta | Y4: UpdateNAV | Z4: UpdateDailyCash | AA4: UpdateDailyCreditLimt | AB4: RemoveDailyCreditLimit | AC4: RemoveDailyCash | AD4: RemoveNAV | AE4: UpdateForexConversionMonthly | AF4: UpdateMarkPriceMonthly. | AG4: UpdateMarkPriceMonthly
A5: =IFERROR(__xludf.DUMMYFUNCTION("TRANSPOSE(IMPORTRANGE(VLOOKUP($E$3,IMPORTRANGE('_Settings'!$B$3,$C$3&""!A4:B1000""),2,FALSE),$G$3&""!A4:A1000""))"),"") | B5: =IFERROR(__xludf.DUMMYFUNCTION("""COMPUTED_VALUE"""),"Select Date") -> Select Date | C5: =IFERROR(__xludf.DUMMYFUNCTION("""COMPUTED_VALUE"""),"Copy Date ") -> Copy Date
B6: 43290

Sheet GetForexConversion
B1: Data
J2: =VLOOKUP($E$3,'_MasterData'!B4:D1000,3,FALSE) -> #N/A
B3: Module | C3: DailyValuation | D3: Step | E3: GetForexConversion | F3: Data Format | G3: Input Format
B4: =IFERROR(__xludf.DUMMYFUNCTION("IF(C3="""","""",Transpose(IMPORTRANGE('_Settings'!$B$3,C3&""!A4:A1000"")))"),"#REF!") -> #REF! | C4: UpdateDailyCash | D4: UpdateForexConversion | E4: UpdateMarkPrice | F4: CleanUp | G4: GetMarkPriceData | H4: GetForwardPoints | I4: UpdateForwardPoints | J4: DeleteNAV | K4: GetForexConversion | L4: GetDailyCash | M4: GetDailyBeta | N4: GetDailyVolatility | O4: GetDailyDividendYield | P4: GetDailyTradingVolume | Q4: GetDailyOutstandings | R4: GetDailyDelta | S4: UpdateDailyVolatility | T4: UpdateDividendYield | U4: UpdateTradingVolume | V4: UpdateDailyDelta | W4: UpdateDailyOutstandings | X4: UpdateBeta | Y4: UpdateNAV | Z4: UpdateDailyCash | AA4: UpdateDailyCreditLimt | AB4: RemoveDailyCreditLimit | AC4: RemoveDailyCash | AD4: RemoveNAV | AE4: UpdateForexConversionMonthly | AF4: UpdateMarkPriceMonthly. | AG4: UpdateMarkPriceMonthly
A5: =IFERROR(__xludf.DUMMYFUNCTION("TRANSPOSE(IMPORTRANGE(VLOOKUP($E$3,IMPORTRANGE('_Settings'!$B$3,$C$3&""!A4:B1000""),2,FALSE),$G$3&""!A4:A1000""))"),"") | B5: =IFERROR(__xludf.DUMMYFUNCTION("""COMPUTED_VALUE"""),"Select Date") -> Select Date | C5: =IFERROR(__xludf.DUMMYFUNCTION("""COMPUTED_VALUE"""),"Copy Date") -> Copy Date
B6: 43290

Sheet UpdateMarkPriceMonthly
B1: Data
J2: =VLOOKUP($E$3,'_MasterData'!B4:D1000,3,FALSE) -> #N/A
B3: Module | C3: DailyValuation | D3: Step | E3: UpdateMarkPriceMonthly | F3: Data Format | G3: Input Format
B4: =IFERROR(__xludf.DUMMYFUNCTION("IF(C3="""","""",Transpose(IMPORTRANGE('_Settings'!$B$3,C3&""!A4:A1000"")))"),"#REF!") -> #REF! | C4: UpdateDailyCash | D4: UpdateForexConversion | E4: UpdateMarkPrice | F4: CleanUp | G4: GetMarkPriceData | H4: GetForwardPoints | I4: UpdateForwardPoints | J4: DeleteNAV | K4: GetForexConversion | L4: GetDailyCash | M4: GetDailyBeta | N4: GetDailyVolatility | O4: GetDailyDividendYield | P4: GetDailyTradingVolume | Q4: GetDailyOutstandings | R4: GetDailyDelta | S4: UpdateDailyVolatility | T4: UpdateDividendYield | U4: UpdateTradingVolume | V4: UpdateDailyDelta | W4: UpdateDailyOutstandings | X4: UpdateBeta | Y4: UpdateNAV | Z4: UpdateDailyCash | AA4: UpdateDailyCreditLimt | AB4: RemoveDailyCreditLimit | AC4: RemoveDailyCash | AD4: RemoveNAV | AE4: UpdateForexConversionMonthly | AF4: UpdateMarkPriceMonthly. | AG4: UpdateMarkPriceMonthly
A5: =IFERROR(__xludf.DUMMYFUNCTION("TRANSPOSE(IMPORTRANGE(VLOOKUP($E$3,IMPORTRANGE('_Settings'!$B$3,$C$3&""!A4:B1000""),2,FALSE),$G$3&""!A4:A1000""))"),"") | B5: =IFERROR(__xludf.DUMMYFUNCTION("""COMPUTED_VALUE"""),"Symbol") -> Symbol | C5: =IFERROR(__xludf.DUMMYFUNCTION("""COMPUTED_VALUE"""),"Price") -> Price | D5: =IFERROR(__xludf.DUMMYFUNCTION("""COMPUTED_VALUE"""),"Date") -> Date
B6: EF828225 | C6: 10 | D6: 43290
B7: EF828225 | C7: 20 | D7: 43291
B8: EF828225 | C8: 30 | D8: 43292
B9: EF828225 | C9: 40 | D9: 43293
B10: EF828225 | C10: 50 | D10: 43294

Sheet UpdateForexConversionMonthly
B1: Data
J2: =VLOOKUP($E$3,'_MasterData'!B4:D1000,3,FALSE) -> #N/A
B3: Module | C3: DailyValuation | D3: Step | E3: UpdateForexConversionMonthly | F3: Data Format | G3: Input Format
B4: =IFERROR(__xludf.DUMMYFUNCTION("IF(C3="""","""",Transpose(IMPORTRANGE('_Settings'!$B$3,C3&""!A4:A1000"")))"),"#REF!") -> #REF! | C4: UpdateDailyCash | D4: UpdateForexConversion | E4: UpdateMarkPrice | F4: CleanUp | G4: GetMarkPriceData | H4: GetForwardPoints | I4: UpdateForwardPoints | J4: DeleteNAV | K4: GetForexConversion | L4: GetDailyCash | M4: GetDailyBeta | N4: GetDailyVolatility | O4: GetDailyDividendYield | P4: GetDailyTradingVolume | Q4: GetDailyOutstandings | R4: GetDailyDelta | S4: UpdateDailyVolatility | T4: UpdateDividendYield | U4: UpdateTradingVolume | V4: UpdateDailyDelta | W4: UpdateDailyOutstandings | X4: UpdateBeta | Y4: UpdateNAV | Z4: UpdateDailyCash | AA4: UpdateDailyCreditLimt | AB4: RemoveDailyCreditLimit | AC4: RemoveDailyCash | AD4: RemoveNAV | AE4: UpdateForexConversionMonthly | AF4: UpdateMarkPriceMonthly. | AG4: UpdateMarkPriceMonthly
A5: =IFERROR(__xludf.DUMMYFUNCTION("TRANSPOSE(IMPORTRANGE(VLOOKUP($E$3,IMPORTRANGE('_Settings'!$B$3,$C$3&""!A4:B1000""),2,FALSE),$G$3&""!A4:A1000""))"),"") | B5: =IFERROR(__xludf.DUMMYFUNCTION("""COMPUTED_VALUE"""),"From Currency") -> From Currency | C5: =IFERROR(__xludf.DUMMYFUNCTION("""COMPUTED_VALUE"""),"To Currency") -> To Currency | D5: =IFERROR(__xludf.DUMMYFUNCTION("""COMPUTED_VALUE"""),"Symbol") -> Symbol | E5: =IFERROR(__xludf.DUMMYFUNCTION("""COMPUTED_VALUE"""),"Date") -> Date | F5: =IFERROR(__xludf.DUMMYFUNCTION("""COMPUTED_VALUE"""),"Price") -> Price
B6: AUD | C6: USD | D6: EF828225 | E6: 43290 | F6: 0.749
B7: AUD | C7: USD | D7: EF828226 | E7: 43291 | F7: 0.741
B8: AUD | C8: USD | D8: EF828227 | E8: 43292 | F8: 0.7411
B9: AUD | C9: USD | D9: EF828228 | E9: 43293 | F9: 0.7412
B10: AUD | C10: USD | D10: EF828229 | E10: 43294 | F10: 0.7413

Sheet GetActivityData
B1: Data
J2: =VLOOKUP($E$3,'_MasterData'!B4:D1000,3,FALSE) -> #N/A
B3: Module | C3: GeneralLedger | D3: Step | E3: GetActivityData | F3: Data Format | G3: Input Format
B4: =IFERROR(__xludf.DUMMYFUNCTION("IF(C3="""","""",Transpose(IMPORTRANGE('_Settings'!$B$3,C3&""!A4:A1000"")))"),"#REF!") -> #REF! | C4: EnterCashDividends | D4: EnterNonTradingTransaction | E4: VerifyCash | F4: VerifyActivity | G4: VerifyTradingTransaction | H4: VerifyRevaluationData | I4: GetTradingTransaction | J4: GetActivityData | K4: GetRevaluationData | L4: GetAccountDetails | M4: GetNonTradingTransaction | N4: GetDividendData | O4: VerifyNonTradingTransaction | P4: VerifyDividend | Q4: GetOpeningBalanceData | R4: GetAccountBalance | S4: SelectNonTradingTransaction | T4: SelectNonTradingTranItem | U4: DeleteNonTradingTransaction | V4: DeleteNonTradingTranItem | W4: AddNonTradingTransaction | X4: AddNonTradingTranItem | Y4: VerifyOpeningBalanceData | Z4: SelectOpeningBalanceTransaction | AA4: SelectOpeningBalanceTranItem | AB4: EditNonTradingTransaction | AC4: EditNonTradingTranItem | AD4: DeleteOpeningBalanceTransaction | AE4: DeleteOpeningBalanceTranItem | AF4: GetDayEndCash | AG4: VerifyDayEndCash | AH4: RunRevaluation | AI4: CalculateDayEndCash | AJ4: GetCashTransaction | AK4: SelectCashTransaction | AL4: DeleteCashTransaction | AM4: EditCashTransaction | AN4: AddCashTransaction | AO4: AddOpeningBalanceTransaction | AP4: AddOpeningBalanceTranItem | AQ4: GetDailyCalculationsData | AR4: CalculateDailyCalculations | AS4: EditOpeningBalanceTransaction | AT4: EditOpeningBalanceTranItem | AU4: VerifyDailyCalTransactions | AV4: CloseGeneralLedger | AW4: VerifyAccountDetails | AX4: SaveTransaction
A5: =IFERROR(__xludf.DUMMYFUNCTION("TRANSPOSE(IMPORTRANGE(VLOOKUP($E$3,IMPORTRANGE('_Settings'!$B$3,$C$3&""!A4:B1000""),2,FALSE),$G$3&""!A4:A1000""))"),"") | B5: =IFERROR(__xludf.DUMMYFUNCTION("""COMPUTED_VALUE"""),"MasterFund") -> MasterFund | C5: =IFERROR(__xludf.DUMMYFUNCTION("""COMPUTED_VALUE"""),"Accounts") -> Accounts | D5: =IFERROR(__xludf.DUMMYFUNCTION("""COMPUTED_VALUE"""),"From") -> From | E5: =IFERROR(__xludf.DUMMYFUNCTION("""COMPUTED_VALUE"""),"To") -> To | F5: =IFERROR(__xludf.DUMMYFUNCTION("""COMPUTED_VALUE"""),"SettlementDate") -> SettlementDate | G5: =IFERROR(__xludf.DUMMYFUNCTION("""COMPUTED_VALUE"""),"TradeDate") -> TradeDate | H5: =IFERROR(__xludf.DUMMYFUNCTION("""COMPUTED_VALUE"""),"All") -> All
B6: NewMF | C6: Allocation1 | D6: 43290 | E6: 43294 | G6: Yes

Sheet VerifyActivity
B1: Data
J2: =VLOOKUP($E$3,'_MasterData'!B4:D1000,3,FALSE) -> #N/A
B3: Module | C3: GeneralLedger | D3: Step | E3: VerifyActivity | F3: Data Format | G3: Input Format
B4: =IFERROR(__xludf.DUMMYFUNCTION("IF(C3="""","""",Transpose(IMPORTRANGE('_Settings'!$B$3,C3&""!A4:A1000"")))"),"#REF!") -> #REF! | C4: EnterCashDividends | D4: EnterNonTradingTransaction | E4: VerifyCash | F4: VerifyActivity | G4: VerifyTradingTransaction | H4: VerifyRevaluationData | I4: GetTradingTransaction | J4: GetActivityData | K4: GetRevaluationData | L4: GetAccountDetails | M4: GetNonTradingTransaction | N4: GetDividendData | O4: VerifyNonTradingTransaction | P4: VerifyDividend | Q4: GetOpeningBalanceData | R4: GetAccountBalance | S4: SelectNonTradingTransaction | T4: SelectNonTradingTranItem | U4: DeleteNonTradingTransaction | V4: DeleteNonTradingTranItem | W4: AddNonTradingTransaction | X4: AddNonTradingTranItem | Y4: VerifyOpeningBalanceData | Z4: SelectOpeningBalanceTransaction | AA4: SelectOpeningBalanceTranItem | AB4: EditNonTradingTransaction | AC4: EditNonTradingTranItem | AD4: DeleteOpeningBalanceTransaction | AE4: DeleteOpeningBalanceTranItem | AF4: GetDayEndCash | AG4: VerifyDayEndCash | AH4: RunRevaluation | AI4: CalculateDayEndCash | AJ4: GetCashTransaction | AK4: SelectCashTransaction | AL4: DeleteCashTransaction | AM4: EditCashTransaction | AN4: AddCashTransaction | AO4: AddOpeningBalanceTransaction | AP4: AddOpeningBalanceTranItem | AQ4: GetDailyCalculationsData | AR4: CalculateDailyCalculations | AS4: EditOpeningBalanceTransaction | AT4: EditOpeningBalanceTranItem | AU4: VerifyDailyCalTransactions | AV4: CloseGeneralLedger | AW4: VerifyAccountDetails | AX4: SaveTransaction
A5: =IFERROR(__xludf.DUMMYFUNCTION("TRANSPOSE(IMPORTRANGE(VLOOKUP($E$3,IMPORTRANGE('_Settings'!$B$3,$C$3&""!A4:B1000""),2,FALSE),$G$3&""!A4:A1000""))"),"") | B5: =IFERROR(__xludf.DUMMYFUNCTION("""COMPUTED_VALUE"""),"Account") -> Account | C5: =IFERROR(__xludf.DUMMYFUNCTION("""COMPUTED_VALUE"""),"Activity Source") -> Activity Source | D5: =IFERROR(__xludf.DUMMYFUNCTION("""COMPUTED_VALUE"""),"ActivityType") -> ActivityType | E5: =IFERROR(__xludf.DUMMYFUNCTION("""COMPUTED_VALUE"""),"Net Amount(Local)") -> Net Amount(Local) | F5: =IFERROR(__xludf.DUMMYFUNCTION("""COMPUTED_VALUE"""),"AUEC Fee1") -> AUEC Fee1 | G5: =IFERROR(__xludf.DUMMYFUNCTION("""COMPUTED_VALUE"""),"AUEC Fee2") -> AUEC Fee2 | H5: =IFERROR(__xludf.DUMMYFUNCTION("""COMPUTED_VALUE"""),"Balance Type") -> Balance Type | I5: =IFERROR(__xludf.DUMMYFUNCTION("""COMPUTED_VALUE"""),"Clearing Broker Fees") -> Clearing Broker Fees | J5: =IFERROR(__xludf.DUMMYFUNCTION("""COMPUTED_VALUE"""),"Commission") -> Commission | K5: =IFERROR(__xludf.DUMMYFUNCTION("""COMPUTED_VALUE"""),"Currency") -> Currency | L5: =IFERROR(__xludf.DUMMYFUNCTION("""COMPUTED_VALUE"""),"Description") -> Description | M5: =IFERROR(__xludf.DUMMYFUNCTION("""COMPUTED_VALUE"""),"Entry Date") -> Entry Date | N5: =IFERROR(__xludf.DUMMYFUNCTION("""COMPUTED_VALUE"""),"FX Conversion Method Operator") -> FX Conversion Method Operator | O5: =IFERROR(__xludf.DUMMYFUNCTION("""COMPUTED_VALUE"""),"Fx Rate") -> Fx Rate | P5: =IFERROR(__xludf.DUMMYFUNCTION("""COMPUTED_VALUE"""),"Lead Currency") -> Lead Currency | Q5: =IFERROR(__xludf.DUMMYFUNCTION("""COMPUTED_VALUE"""),"Modify date") -> Modify date | R5: =IFERROR(__xludf.DUMMYFUNCTION("""COMPUTED_VALUE"""),"OCC Fee") -> OCC Fee | S5: =IFERROR(__xludf.DUMMYFUNCTION("""COMPUTED_VALUE"""),"OptionPremiumAdjustment") -> OptionPremiumAdjustment | T5: =IFERROR(__xludf.DUMMYFUNCTION("""COMPUTED_VALUE"""),"ORF Fee") -> ORF Fee | U5: =IFERROR(__xludf.DUMMYFUNCTION("""COMPUTED_VALUE"""),"Other Broker Fees") -> Other Broker Fees | V5: =IFERROR(__xludf.DUMMYFUNCTION("""COMPUTED_VALUE"""),"Quantity") -> Quantity | W5: =IFERROR(__xludf.DUMMYFUNCTION("""COMPUTED_VALUE"""),"SEC Fee") -> SEC Fee | X5: =IFERROR(__xludf.DUMMYFUNCTION("""COMPUTED_VALUE"""),"Settlement Currency") -> Settlement Currency | Y5: =IFERROR(__xludf.DUMMYFUNCTION("""COMPUTED_VALUE"""),"Settlement Date") -> Settlement Date | Z5: =IFERROR(__xludf.DUMMYFUNCTION("""COMPUTED_VALUE"""),"Soft Commission") -> Soft Commission | AA5: =IFERROR(__xludf.DUMMYFUNCTION("""COMPUTED_VALUE"""),"Stamp Duty") -> Stamp Duty | AB5: =IFERROR(__xludf.DUMMYFUNCTION("""COMPUTED_VALUE"""),"Symbol") -> Symbol | AC5: =IFERROR(__xludf.DUMMYFUNCTION("""COMPUTED_VALUE"""),"Tax On Commissions") -> Tax On Commissions | AD5: =IFERROR(__xludf.DUMMYFUNCTION("""COMPUTED_VALUE"""),"Total Commissions") -> Total Commissions | AE5: =IFERROR(__xludf.DUMMYFUNCTION("""COMPUTED_VALUE"""),"Trade Date") -> Trade Date | AF5: =IFERROR(__xludf.DUMMYFUNCTION("""COMPUTED_VALUE"""),"Transaction Levy") -> Transaction Levy | AG5: =IFERROR(__xludf.DUMMYFUNCTION("""COMPUTED_VALUE"""),"Transaction Source") -> Transaction Source | AH5: =IFERROR(__xludf.DUMMYFUNCTION("""COMPUTED_VALUE"""),"User") -> User | AI5: =IFERROR(__xludf.DUMMYFUNCTION("""COMPUTED_VALUE"""),"Vs Currency") -> Vs Currency | AJ5: =IFERROR(__xludf.DUMMYFUNCTION("""COMPUTED_VALUE"""),"SettlCurrencyID") -> SettlCurrencyID
B6: Allocation1 | C6: Trading | D6: BondL | E6: -1522 | F6: 0 | G6: 0 | H6: Cash | I6: 0 | J6: 70 | K6: AUD | N6: M | O6: 1.5 | R6: 0 | S6: 0 | T6: 0 | U6: 0 | V6: 100 | W6: 0 | X6: AUD | Z6: 10 | AA6: 0 | AB6: EF828225 | AC6: 0 | AD6: 80 | AE6: 43290 | AF6: 0 | AG6: Trading
B7: Allocation1 | C7: Trading | D7: Bond_Trading_Interest | E7: -73.93 | F7: 0 | G7: 0 | H7: Cash | I7: 0 | J7: 0 | K7: AUD | N7: M | O7: 1.5 | R7: 0 | S7: 0 | T7: 0 | U7: 0 | V7: 100 | W7: 0 | X7: AUD | Z7: 0 | AA7: 0 | AB7: EF828225 | AC7: 0 | AD7: 0 | AE7: 43290 | AF7: 0 | AG7: Trading
B8: Allocation1 | C8: Trading | D8: BondL | E8: 578 | F8: 0 | G8: 0 | H8: Cash | I8: 0 | J8: 30 | K8: AUD | N8: M | O8: 1.8 | R8: 0 | S8: 0 | T8: 0 | U8: 0 | V8: 50 | W8: 0 | X8: AUD | Z8: 10 | AA8: 0 | AB8: EF828225 | AC8: 0 | AD8: 40 | AE8: 43292 | AF8: 0 | AG8: Trading
B9: Allocation1 | C9: Trading | D9: Bond_Interest_Received | E9: 37.53 | F9: 0 | G9: 0 | H9: Cash | I9: 0 | J9: 0 | K9: AUD | N9: M | O9: 1.8 | R9: 0 | S9: 0 | T9: 0 | U9: 0 | V9: 50 | W9: 0 | X9: AUD | Z9: 0 | AA9: 0 | AB9: EF828225 | AC9: 0 | AD9: 0 | AE9: 43292 | AF9: 0 | AG9: Trading

Sheet GetTradingTransaction
B1: Data
J2: =VLOOKUP($E$3,'_MasterData'!B4:D1000,3,FALSE) -> #N/A
B3: Module | C3: GeneralLedger | D3: Step | E3: GetTradingTransaction | F3: Data Format | G3: Input Format
B4: =IFERROR(__xludf.DUMMYFUNCTION("IF(C3="""","""",Transpose(IMPORTRANGE('_Settings'!$B$3,C3&""!A4:A1000"")))"),"#REF!") -> #REF! | C4: EnterCashDividends | D4: EnterNonTradingTransaction | E4: VerifyCash | F4: VerifyActivity | G4: VerifyTradingTransaction | H4: VerifyRevaluationData | I4: GetTradingTransaction | J4: GetActivityData | K4: GetRevaluationData | L4: GetAccountDetails | M4: GetNonTradingTransaction | N4: GetDividendData | O4: VerifyNonTradingTransaction | P4: VerifyDividend | Q4: GetOpeningBalanceData | R4: GetAccountBalance | S4: SelectNonTradingTransaction | T4: SelectNonTradingTranItem | U4: DeleteNonTradingTransaction | V4: DeleteNonTradingTranItem | W4: AddNonTradingTransaction | X4: AddNonTradingTranItem | Y4: VerifyOpeningBalanceData | Z4: SelectOpeningBalanceTransaction | AA4: SelectOpeningBalanceTranItem | AB4: EditNonTradingTransaction | AC4: EditNonTradingTranItem | AD4: DeleteOpeningBalanceTransaction | AE4: DeleteOpeningBalanceTranItem | AF4: GetDayEndCash | AG4: VerifyDayEndCash | AH4: RunRevaluation | AI4: CalculateDayEndCash | AJ4: GetCashTransaction | AK4: SelectCashTransaction | AL4: DeleteCashTransaction | AM4: EditCashTransaction | AN4: AddCashTransaction | AO4: AddOpeningBalanceTransaction | AP4: AddOpeningBalanceTranItem | AQ4: GetDailyCalculationsData | AR4: CalculateDailyCalculations | AS4: EditOpeningBalanceTransaction | AT4: EditOpeningBalanceTranItem | AU4: VerifyDailyCalTransactions | AV4: CloseGeneralLedger | AW4: VerifyAccountDetails | AX4: SaveTransaction
A5: =IFERROR(__xludf.DUMMYFUNCTION("TRANSPOSE(IMPORTRANGE(VLOOKUP($E$3,IMPORTRANGE('_Settings'!$B$3,$C$3&""!A4:B1000""),2,FALSE),$G$3&""!A4:A1000""))"),"") | B5: =IFERROR(__xludf.DUMMYFUNCTION("""COMPUTED_VALUE"""),"MasterFund") -> MasterFund | C5: =IFERROR(__xludf.DUMMYFUNCTION("""COMPUTED_VALUE"""),"Accounts") -> Accounts | D5: =IFERROR(__xludf.DUMMYFUNCTION("""COMPUTED_VALUE"""),"From Date") -> From Date | E5: =IFERROR(__xludf.DUMMYFUNCTION("""COMPUTED_VALUE"""),"To Date") -> To Date
B6: NewMF | C6: Allocation1 | D6: 43290 | E6: 43294

Sheet VerifyTradingTransaction
B1: Data
J2: =VLOOKUP($E$3,'_MasterData'!B4:D1000,3,FALSE) -> #N/A
B3: Module | C3: GeneralLedger | D3: Step | E3: VerifyTradingTransaction | F3: Data Format | G3: Input Format
B4: =IFERROR(__xludf.DUMMYFUNCTION("IF(C3="""","""",Transpose(IMPORTRANGE('_Settings'!$B$3,C3&""!A4:A1000"")))"),"#REF!") -> #REF! | C4: EnterCashDividends | D4: EnterNonTradingTransaction | E4: VerifyCash | F4: VerifyActivity | G4: VerifyTradingTransaction | H4: VerifyRevaluationData | I4: GetTradingTransaction | J4: GetActivityData | K4: GetRevaluationData | L4: GetAccountDetails | M4: GetNonTradingTransaction | N4: GetDividendData | O4: VerifyNonTradingTransaction | P4: VerifyDividend | Q4: GetOpeningBalanceData | R4: GetAccountBalance | S4: SelectNonTradingTransaction | T4: SelectNonTradingTranItem | U4: DeleteNonTradingTransaction | V4: DeleteNonTradingTranItem | W4: AddNonTradingTransaction | X4: AddNonTradingTranItem | Y4: VerifyOpeningBalanceData | Z4: SelectOpeningBalanceTransaction | AA4: SelectOpeningBalanceTranItem | AB4: EditNonTradingTransaction | AC4: EditNonTradingTranItem | AD4: DeleteOpeningBalanceTransaction | AE4: DeleteOpeningBalanceTranItem | AF4: GetDayEndCash | AG4: VerifyDayEndCash | AH4: RunRevaluation | AI4: CalculateDayEndCash | AJ4: GetCashTransaction | AK4: SelectCashTransaction | AL4: DeleteCashTransaction | AM4: EditCashTransaction | AN4: AddCashTransaction | AO4: AddOpeningBalanceTransaction | AP4: AddOpeningBalanceTranItem | AQ4: GetDailyCalculationsData | AR4: CalculateDailyCalculations | AS4: EditOpeningBalanceTransaction | AT4: EditOpeningBalanceTranItem | AU4: VerifyDailyCalTransactions | AV4: CloseGeneralLedger | AW4: VerifyAccountDetails | AX4: SaveTransaction
A5: =IFERROR(__xludf.DUMMYFUNCTION("TRANSPOSE(IMPORTRANGE(VLOOKUP($E$3,IMPORTRANGE('_Settings'!$B$3,$C$3&""!A4:B1000""),2,FALSE),$G$3&""!A4:A1000""))"),"") | B5: =IFERROR(__xludf.DUMMYFUNCTION("""COMPUTED_VALUE"""),"Date") -> Date | C5: =IFERROR(__xludf.DUMMYFUNCTION("""COMPUTED_VALUE"""),"Modify Date") -> Modify Date | D5: =IFERROR(__xludf.DUMMYFUNCTION("""COMPUTED_VALUE"""),"Entry Date") -> Entry Date | E5: =IFERROR(__xludf.DUMMYFUNCTION("""COMPUTED_VALUE"""),"DR") -> DR | F5: =IFERROR(__xludf.DUMMYFUNCTION("""COMPUTED_VALUE"""),"CR") -> CR | G5: =IFERROR(__xludf.DUMMYFUNCTION("""COMPUTED_VALUE"""),"Fx Rate") -> Fx Rate | H5: =IFERROR(__xludf.DUMMYFUNCTION("""COMPUTED_VALUE"""),"FX Conversion Method Operator") -> FX Conversion Method Operator | I5: =IFERROR(__xludf.DUMMYFUNCTION("""COMPUTED_VALUE"""),"Account Side") -> Account Side | J5: =IFERROR(__xludf.DUMMYFUNCTION("""COMPUTED_VALUE"""),"TransactionSource") -> TransactionSource | K5: =IFERROR(__xludf.DUMMYFUNCTION("""COMPUTED_VALUE"""),"Currency") -> Currency | L5: =IFERROR(__xludf.DUMMYFUNCTION("""COMPUTED_VALUE"""),"Base Currency") -> Base Currency | M5: =IFERROR(__xludf.DUMMYFUNCTION("""COMPUTED_VALUE"""),"Symbol") -> Symbol | N5: =IFERROR(__xludf.DUMMYFUNCTION("""COMPUTED_VALUE"""),"Description") -> Description | O5: =IFERROR(__xludf.DUMMYFUNCTION("""COMPUTED_VALUE"""),"DR (Base)") -> DR (Base) | P5: =IFERROR(__xludf.DUMMYFUNCTION("""COMPUTED_VALUE"""),"CR (Base)") -> CR (Base) | Q5: =IFERROR(__xludf.DUMMYFUNCTION("""COMPUTED_VALUE"""),"Cash Sub-Account") -> Cash Sub-Account | R5: =IFERROR(__xludf.DUMMYFUNCTION("""COMPUTED_VALUE"""),"Account") -> Account | S5: =IFERROR(__xludf.DUMMYFUNCTION("""COMPUTED_VALUE"""),"TaxLotId") -> TaxLotId
B6: 43290 | E6: 1522 | F6: 0 | G6: 1.5 | H6: M | I6: DR | J6: Trading | K6: AUD | L6: USD | M6: EF828225 | O6: 2283 | P6: 0 | Q6: Investment - Long Bond [Asset] | R6: Allocation1
B7: 43290 | E7: 0 | F7: 1522 | G7: 1.5 | H7: M | I7: CR | J7: Trading | K7: AUD | L7: USD | M7: EF828225 | O7: 0 | P7: 2283 | Q7: Cash [Cash] | R7: Allocation1
B8: 43290 | E8: 73.93 | F8: 0 | G8: 1.5 | H8: M | I8: DR | J8: Trading | K8: AUD | L8: USD | M8: EF828225 | O8: 110.9 | P8: 0 | Q8: Interest - Payable [Liability] | R8: Allocation1
B9: 43290 | E9: 0 | F9: 73.93 | G9: 1.5 | H9: M | I9: CR | J9: Trading | K9: AUD | L9: USD | M9: EF828225 | O9: 0 | P9: 110.9 | Q9: Cash [Cash] | R9: Allocation1
B10: 43292 | E10: 40 | F10: 0 | G10: 1.8 | H10: M | I10: DR | J10: Trading | K10: AUD | L10: USD | M10: EF828225 | O10: 72 | P10: 0 | Q10: Investment - Long Bond [Asset] | R10: Allocation1
B11: 43292 | E11: 0 | F11: 40 | G11: 1.8 | H11: M | I11: CR | J11: Trading | K11: AUD | L11: USD | M11: EF828225 | O11: 0 | P11: 72 | Q11: Cash [Cash] | R11: Allocation1
B12: 43292 | E12: 618 | F12: 0 | G12: 1.8 | H12: M | I12: DR | J12: Trading | K12: AUD | L12: USD | M12: EF828225 | O12: 1112.4 | P12: 0 | Q12: Cash [Cash] | R12: Allocation1
B13: 43292 | E13: 0 | F13: 618 | G13: 1.8 | H13: M | I13: CR | J13: Trading | K13: AUD | L13: USD | M13: EF828225 | O13: 0 | P13: 1112.4 | Q13: Investment - Long Bond [Asset] | R13: Allocation1
B14: 43292 | E14: 37.53 | F14: 0 | G14: 1.8 | H14: M | I14: DR | J14: Trading | K14: AUD | L14: USD | M14: EF828225 | O14: 67.56 | P14: 0 | Q14: Interest - Receivable [Asset] | R14: Allocation1
B15: 43292 | E15: 0 | F15: 37.53 | G15: 1.8 | H15: M | I15: CR | J15: Trading | K15: AUD | L15: USD | M15: EF828225 | O15: 0 | P15: 67.56 | Q15: Cash [Cash] | R15: Allocation1

Sheet GetDailyCalculationsData
B1: Data
J2: =VLOOKUP($E$3,'_MasterData'!B4:D1000,3,FALSE) -> #N/A
B3: Module | C3: GeneralLedger | D3: Step | E3: GetDailyCalculationsData | F3: Data Format | G3: Input Format
B4: =IFERROR(__xludf.DUMMYFUNCTION("IF(C3="""","""",Transpose(IMPORTRANGE('_Settings'!$B$3,C3&""!A4:A1000"")))"),"#REF!") -> #REF! | C4: EnterCashDividends | D4: EnterNonTradingTransaction | E4: VerifyCash | F4: VerifyActivity | G4: VerifyTradingTransaction | H4: VerifyRevaluationData | I4: GetTradingTransaction | J4: GetActivityData | K4: GetRevaluationData | L4: GetAccountDetails | M4: GetNonTradingTransaction | N4: GetDividendData | O4: VerifyNonTradingTransaction | P4: VerifyDividend | Q4: GetOpeningBalanceData | R4: GetAccountBalance | S4: SelectNonTradingTransaction | T4: SelectNonTradingTranItem | U4: DeleteNonTradingTransaction | V4: DeleteNonTradingTranItem | W4: AddNonTradingTransaction | X4: AddNonTradingTranItem | Y4: VerifyOpeningBalanceData | Z4: SelectOpeningBalanceTransaction | AA4: SelectOpeningBalanceTranItem | AB4: EditNonTradingTransaction | AC4: EditNonTradingTranItem | AD4: DeleteOpeningBalanceTransaction | AE4: DeleteOpeningBalanceTranItem | AF4: GetDayEndCash | AG4: VerifyDayEndCash | AH4: RunRevaluation | AI4: CalculateDayEndCash | AJ4: GetCashTransaction | AK4: SelectCashTransaction | AL4: DeleteCashTransaction | AM4: EditCashTransaction | AN4: AddCashTransaction | AO4: AddOpeningBalanceTransaction | AP4: AddOpeningBalanceTranItem | AQ4: GetDailyCalculationsData | AR4: CalculateDailyCalculations | AS4: EditOpeningBalanceTransaction | AT4: EditOpeningBalanceTranItem | AU4: VerifyDailyCalTransactions | AV4: CloseGeneralLedger | AW4: VerifyAccountDetails | AX4: SaveTransaction
A5: =IFERROR(__xludf.DUMMYFUNCTION("TRANSPOSE(IMPORTRANGE(VLOOKUP($E$3,IMPORTRANGE('_Settings'!$B$3,$C$3&""!A4:B1000""),2,FALSE),$G$3&""!A4:A1000""))"),"") | B5: =IFERROR(__xludf.DUMMYFUNCTION("""COMPUTED_VALUE"""),"MasterFund") -> MasterFund | C5: =IFERROR(__xludf.DUMMYFUNCTION("""COMPUTED_VALUE"""),"Accounts") -> Accounts | D5: =IFERROR(__xludf.DUMMYFUNCTION("""COMPUTED_VALUE"""),"From Date") -> From Date | E5: =IFERROR(__xludf.DUMMYFUNCTION("""COMPUTED_VALUE"""),"To Date") -> To Date
B6: NewMF | C6: Allocation1 | D6: 43290 | E6: 43294

Sheet VerifyDailyCalTransactions
B1: Data
J2: =VLOOKUP($E$3,'_MasterData'!B4:D1000,3,FALSE) -> #N/A
B3: Module | C3: GeneralLedger | D3: Step | E3: VerifyDailyCalTransactions | F3: Data Format | G3: Input Format
B4: =IFERROR(__xludf.DUMMYFUNCTION("IF(C3="""","""",Transpose(IMPORTRANGE('_Settings'!$B$3,C3&""!A4:A1000"")))"),"#REF!") -> #REF! | C4: EnterCashDividends | D4: EnterNonTradingTransaction | E4: VerifyCash | F4: VerifyActivity | G4: VerifyTradingTransaction | H4: VerifyRevaluationData | I4: GetTradingTransaction | J4: GetActivityData | K4: GetRevaluationData | L4: GetAccountDetails | M4: GetNonTradingTransaction | N4: GetDividendData | O4: VerifyNonTradingTransaction | P4: VerifyDividend | Q4: GetOpeningBalanceData | R4: GetAccountBalance | S4: SelectNonTradingTransaction | T4: SelectNonTradingTranItem | U4: DeleteNonTradingTransaction | V4: DeleteNonTradingTranItem | W4: AddNonTradingTransaction | X4: AddNonTradingTranItem | Y4: VerifyOpeningBalanceData | Z4: SelectOpeningBalanceTransaction | AA4: SelectOpeningBalanceTranItem | AB4: EditNonTradingTransaction | AC4: EditNonTradingTranItem | AD4: DeleteOpeningBalanceTransaction | AE4: DeleteOpeningBalanceTranItem | AF4: GetDayEndCash | AG4: VerifyDayEndCash | AH4: RunRevaluation | AI4: CalculateDayEndCash | AJ4: GetCashTransaction | AK4: SelectCashTransaction | AL4: DeleteCashTransaction | AM4: EditCashTransaction | AN4: AddCashTransaction | AO4: AddOpeningBalanceTransaction | AP4: AddOpeningBalanceTranItem | AQ4: GetDailyCalculationsData | AR4: CalculateDailyCalculations | AS4: EditOpeningBalanceTransaction | AT4: EditOpeningBalanceTranItem | AU4: VerifyDailyCalTransactions | AV4: CloseGeneralLedger | AW4: VerifyAccountDetails | AX4: SaveTransaction
A5: =IFERROR(__xludf.DUMMYFUNCTION("TRANSPOSE(IMPORTRANGE(VLOOKUP($E$3,IMPORTRANGE('_Settings'!$B$3,$C$3&""!A4:B1000""),2,FALSE),$G$3&""!A4:A1000""))"),"") | B5: =IFERROR(__xludf.DUMMYFUNCTION("""COMPUTED_VALUE"""),"Trade Date") -> Trade Date | C5: =IFERROR(__xludf.DUMMYFUNCTION("""COMPUTED_VALUE"""),"Account") -> Account | D5: =IFERROR(__xludf.DUMMYFUNCTION("""COMPUTED_VALUE"""),"Symbol") -> Symbol | E5: =IFERROR(__xludf.DUMMYFUNCTION("""COMPUTED_VALUE"""),"Currency") -> Currency | F5: =IFERROR(__xludf.DUMMYFUNCTION("""COMPUTED_VALUE"""),"Net Amount(Local)") -> Net Amount(Local) | G5: =IFERROR(__xludf.DUMMYFUNCTION("""COMPUTED_VALUE"""),"ActivityType") -> ActivityType | H5: =IFERROR(__xludf.DUMMYFUNCTION("""COMPUTED_VALUE"""),"Transaction Source") -> Transaction Source | I5: =IFERROR(__xludf.DUMMYFUNCTION("""COMPUTED_VALUE"""),"Total Commissions") -> Total Commissions | J5: =IFERROR(__xludf.DUMMYFUNCTION("""COMPUTED_VALUE"""),"Balance Type") -> Balance Type | K5: =IFERROR(__xludf.DUMMYFUNCTION("""COMPUTED_VALUE"""),"Settlement Date") -> Settlement Date | L5: =IFERROR(__xludf.DUMMYFUNCTION("""COMPUTED_VALUE"""),"Lead Currency") -> Lead Currency | M5: =IFERROR(__xludf.DUMMYFUNCTION("""COMPUTED_VALUE"""),"Vs Currency") -> Vs Currency | N5: =IFERROR(__xludf.DUMMYFUNCTION("""COMPUTED_VALUE"""),"Quantity") -> Quantity | O5: =IFERROR(__xludf.DUMMYFUNCTION("""COMPUTED_VALUE"""),"Commission") -> Commission | P5: =IFERROR(__xludf.DUMMYFUNCTION("""COMPUTED_VALUE"""),"Soft Commission") -> Soft Commission | Q5: =IFERROR(__xludf.DUMMYFUNCTION("""COMPUTED_VALUE"""),"Other Broker Fees") -> Other Broker Fees | R5: =IFERROR(__xludf.DUMMYFUNCTION("""COMPUTED_VALUE"""),"Clearing Broker Fees") -> Clearing Broker Fees | S5: =IFERROR(__xludf.DUMMYFUNCTION("""COMPUTED_VALUE"""),"Stamp Duty") -> Stamp Duty | T5: =IFERROR(__xludf.DUMMYFUNCTION("""COMPUTED_VALUE"""),"Transaction Levy") -> Transaction Levy | U5: =IFERROR(__xludf.DUMMYFUNCTION("""COMPUTED_VALUE"""),"AUEC Fee1") -> AUEC Fee1 | V5: =IFERROR(__xludf.DUMMYFUNCTION("""COMPUTED_VALUE"""),"Tax On Commissions") -> Tax On Commissions | W5: =IFERROR(__xludf.DUMMYFUNCTION("""COMPUTED_VALUE"""),"AUEC Fee2") -> AUEC Fee2 | X5: =IFERROR(__xludf.DUMMYFUNCTION("""COMPUTED_VALUE"""),"SEC Fee") -> SEC Fee | Y5: =IFERROR(__xludf.DUMMYFUNCTION("""COMPUTED_VALUE"""),"OCC Fee") -> OCC Fee | Z5: =IFERROR(__xludf.DUMMYFUNCTION("""COMPUTED_VALUE"""),"ORF Fee") -> ORF Fee | AA5: =IFERROR(__xludf.DUMMYFUNCTION("""COMPUTED_VALUE"""),"Fx Rate") -> Fx Rate | AB5: =IFERROR(__xludf.DUMMYFUNCTION("""COMPUTED_VALUE"""),"Modify Date") -> Modify Date | AC5: =IFERROR(__xludf.DUMMYFUNCTION("""COMPUTED_VALUE"""),"Entry Date") -> Entry Date | AD5: =IFERROR(__xludf.DUMMYFUNCTION("""COMPUTED_VALUE"""),"User") -> User | AE5: =IFERROR(__xludf.DUMMYFUNCTION("""COMPUTED_VALUE"""),"FX Conversion Method Operator") -> FX Conversion Method Operator | AF5: =IFERROR(__xludf.DUMMYFUNCTION("""COMPUTED_VALUE"""),"Description") -> Description | AG5: =IFERROR(__xludf.DUMMYFUNCTION("""COMPUTED_VALUE"""),"Activity Source") -> Activity Source | AH5: =IFERROR(__xludf.DUMMYFUNCTION("""COMPUTED_VALUE"""),"OptionPremiumAdjustment") -> OptionPremiumAdjustment | AI5: =IFERROR(__xludf.DUMMYFUNCTION("""COMPUTED_VALUE"""),"Settlement Currency") -> Settlement Currency | AJ5: =IFERROR(__xludf.DUMMYFUNCTION("""COMPUTED_VALUE"""),"SettlCurrencyID") -> SettlCurrencyID
B6: 43291 | C6: Allocation1 | D6: EF828225 | E6: AUD | F6: 0 | G6: Bond_Interest_Receivable | H6: DailyCalculation
B7: 43292 | C7: Allocation1 | D7: EF828225 | E7: AUD | F7: 0.56 | G7: Bond_Interest_Receivable | H7: DailyCalculation
B8: 43292 | C8: Allocation1 | D8: EF828225 | E8: AUD | F8: 0 | G8: Bond_Interest_Receivable | H8: DailyCalculation
B9: 43293 | C9: Allocation1 | D9: EF828225 | E9: AUD | F9: 0.56 | G9: Bond_Interest_Receivable | H9: DailyCalculation
B10: 43293 | C10: Allocation1 | D10: EF828225 | E10: AUD | F10: 0 | G10: Bond_Interest_Receivable | H10: DailyCalculation
B11: 43294 | C11: Allocation1 | D11: EF828225 | E11: AUD | F11: 0.56 | G11: Bond_Interest_Receivable | H11: DailyCalculation
B12: 43294 | C12: Allocation1 | D12: EF828225 | E12: AUD | F12: 0.28 | G12: Bond_Interest_Receivable | H12: DailyCalculation
B13: 43290 | C13: Allocation1 | D13: EF828225 | E13: AUD | F13: 0 | G13: Bond_Interest_Receivable | H13: DailyCalculation

Sheet VerifyTradingTransaction1
B1: Data
J2: =VLOOKUP($E$3,'_MasterData'!B4:D1000,3,FALSE) -> #N/A
B3: Module | C3: GeneralLedger | D3: Step | E3: VerifyTradingTransaction | F3: Data Format | G3: Input Format
B4: =IFERROR(__xludf.DUMMYFUNCTION("IF(C3="""","""",Transpose(IMPORTRANGE('_Settings'!$B$3,C3&""!A4:A1000"")))"),"#REF!") -> #REF! | C4: EnterCashDividends | D4: EnterNonTradingTransaction | E4: VerifyCash | F4: VerifyActivity | G4: VerifyTradingTransaction | H4: VerifyRevaluationData | I4: GetTradingTransaction | J4: GetActivityData | K4: GetRevaluationData | L4: GetAccountDetails | M4: GetNonTradingTransaction | N4: GetDividendData | O4: VerifyNonTradingTransaction | P4: VerifyDividend | Q4: GetOpeningBalanceData | R4: GetAccountBalance | S4: SelectNonTradingTransaction | T4: SelectNonTradingTranItem | U4: DeleteNonTradingTransaction | V4: DeleteNonTradingTranItem | W4: AddNonTradingTransaction | X4: AddNonTradingTranItem | Y4: VerifyOpeningBalanceData | Z4: SelectOpeningBalanceTransaction | AA4: SelectOpeningBalanceTranItem | AB4: EditNonTradingTransaction | AC4: EditNonTradingTranItem | AD4: DeleteOpeningBalanceTransaction | AE4: DeleteOpeningBalanceTranItem | AF4: GetDayEndCash | AG4: VerifyDayEndCash | AH4: RunRevaluation | AI4: CalculateDayEndCash | AJ4: GetCashTransaction | AK4: SelectCashTransaction | AL4: DeleteCashTransaction | AM4: EditCashTransaction | AN4: AddCashTransaction | AO4: AddOpeningBalanceTransaction | AP4: AddOpeningBalanceTranItem | AQ4: GetDailyCalculationsData | AR4: CalculateDailyCalculations | AS4: EditOpeningBalanceTransaction | AT4: EditOpeningBalanceTranItem | AU4: VerifyDailyCalTransactions | AV4: CloseGeneralLedger | AW4: VerifyAccountDetails | AX4: SaveTransaction
A5: =IFERROR(__xludf.DUMMYFUNCTION("TRANSPOSE(IMPORTRANGE(VLOOKUP($E$3,IMPORTRANGE('_Settings'!$B$3,$C$3&""!A4:B1000""),2,FALSE),$G$3&""!A4:A1000""))"),"") | B5: =IFERROR(__xludf.DUMMYFUNCTION("""COMPUTED_VALUE"""),"Date") -> Date | C5: =IFERROR(__xludf.DUMMYFUNCTION("""COMPUTED_VALUE"""),"Modify Date") -> Modify Date | D5: =IFERROR(__xludf.DUMMYFUNCTION("""COMPUTED_VALUE"""),"Entry Date") -> Entry Date | E5: =IFERROR(__xludf.DUMMYFUNCTION("""COMPUTED_VALUE"""),"DR") -> DR | F5: =IFERROR(__xludf.DUMMYFUNCTION("""COMPUTED_VALUE"""),"CR") -> CR | G5: =IFERROR(__xludf.DUMMYFUNCTION("""COMPUTED_VALUE"""),"Fx Rate") -> Fx Rate | H5: =IFERROR(__xludf.DUMMYFUNCTION("""COMPUTED_VALUE"""),"FX Conversion Method Operator") -> FX Conversion Method Operator | I5: =IFERROR(__xludf.DUMMYFUNCTION("""COMPUTED_VALUE"""),"Account Side") -> Account Side | J5: =IFERROR(__xludf.DUMMYFUNCTION("""COMPUTED_VALUE"""),"TransactionSource") -> TransactionSource | K5: =IFERROR(__xludf.DUMMYFUNCTION("""COMPUTED_VALUE"""),"Currency") -> Currency | L5: =IFERROR(__xludf.DUMMYFUNCTION("""COMPUTED_VALUE"""),"Base Currency") -> Base Currency | M5: =IFERROR(__xludf.DUMMYFUNCTION("""COMPUTED_VALUE"""),"Symbol") -> Symbol | N5: =IFERROR(__xludf.DUMMYFUNCTION("""COMPUTED_VALUE"""),"Description") -> Description | O5: =IFERROR(__xludf.DUMMYFUNCTION("""COMPUTED_VALUE"""),"DR (Base)") -> DR (Base) | P5: =IFERROR(__xludf.DUMMYFUNCTION("""COMPUTED_VALUE"""),"CR (Base)") -> CR (Base) | Q5: =IFERROR(__xludf.DUMMYFUNCTION("""COMPUTED_VALUE"""),"Cash Sub-Account") -> Cash Sub-Account | R5: =IFERROR(__xludf.DUMMYFUNCTION("""COMPUTED_VALUE"""),"Account") -> Account | S5: =IFERROR(__xludf.DUMMYFUNCTION("""COMPUTED_VALUE"""),"TaxLotId") -> TaxLotId
